Workbook

Sheet Control
A4: Monthly F
A5: Monthly V
A6: Annual
A7: One-Time

Sheet DeleteThisPageThenSave
B2: OriginalFileName | C2: Echelon_Primary_TCO_v5_11_13_25.xlsx

Sheet Confidentiality&Non-Disclosure
B2: Confidentiality and Non-Disclosure All tools, software, documentation, processes, methodologies, and related materials provided by Arriba Advisors LLC (the “Proprietary Materials”) are proprietary and confidential. These Proprietary Materials are intended solely for the recipient’s authorized use and shall not be copied, shared, distributed, or disclosed to any third party without Arriba Advisor LLC’s prior written consent. Any unauthorized review, use, storage, reproduction, or distribution of the Tools is strictly prohibited. If you have received access to the Proprietary Materials in error or without authorization, please notify Arriba Advisor LLC immediately and delete or destroy any copies in your possession. This confidentiality obligation remains in effect even after the conclusion of the business relationship.

Sheet Line Items
O1: FIS | BB1: Jack Henry
B2: Years-> | D2: 7 | O2: CPI Bundle-> | Q2: 0.06 | BB2: Growth-> | BD2: 0 | BE2: *Variable items are minimums. No growth needs to be added.
B3: Growth-> | D3: 0.2 | O3: CPI Non-Bundle-> | Q3: 0.03 | BB3: CPI-> | BD3: 0.03 | CO3: CPI-> | CP3: 0.03
B4: Type (Monthly/Annual) | D4: Average Monthly QTY | E4: Quantity Per Year with Growth | O4: FIS | AP4: Type (Monthly/Annual) | AQ4: Average Monthly QTY | AR4: Quantity Per Year with Growth | BB4: Jack Henry | CC4: Type (Monthly/Annual) | CD4: Average Monthly QTY | CE4: Quantity Per Year with Growth | CO4: Vendor 3
C5: Proposal (11/2025) | E5: Year 1 Quantity | F5: Year 2 Quantity | G5: Year 3 Quantity | H5: Year 4 Quantity | I5: Year 5 Quantity | J5: Year 6 Quantity | K5: Year 7 Quantity | L5: Year 8 Quantity | M5: Year 9 Quantity | N5: Year 10 Quantity | O5: Solution Name/Description | P5: Category | Q5: Per Unit Rate | R5: Year 1 Monthly Cost | S5: Year 1 Cost | T5: Year 2 Cost | U5: Year 3 Cost | V5: Year 4 Cost | W5: Year 5 Cost | X5: Year 6 Cost | Y5: Year 7 Cost | Z5: Year 8 Cost | AA5: Year 9 Cost | AB5: Year 10 Cost | AC5: Year 1 CPI | AD5: Year 2 CPI | AE5: Year 3 CPI | AF5: Year 4 CPI | AG5: Year 5 CPI | AH5: Year 6 CPI | AI5: Year 7 CPI | AJ5: Year 8 CPI | AK5: Year 9 CPI | AL5: Year 10 CPI | AM5: CPI | AN5: Total Term Cost | AR5: Year 1 Quantity | AS5: Year 2 Quantity | AT5: Year 3 Quantity | AU5: Year 4 Quantity | AV5: Year 5 Quantity | AW5: Year 6 Quantity | AX5: Year 7 Quantity | AY5: Year 8 Quantity | AZ5: Year 9 Quantity | BA5: Year 10 Quantity | BB5: Solution Name/Description | BC5: Category | BD5: Per Unit Rate | BE5: Year 1 Monthly Cost | BF5: Year 1 Cost | BG5: Year 2 Cost | BH5: Year 3 Cost | BI5: Year 4 Cost | BJ5: Year 5 Cost | BK5: Year 6 Cost | BL5: Year 7 Cost | BM5: Year 8 Cost | BN5: Year 9 Cost | BO5: Year 10 Cost | BP5: Year 1 CPI | BQ5: Year 2 CPI | BR5: Year 3 CPI | BS5: Year 4 CPI | BT5: Year 5 CPI | BU5: Year 6 CPI | BV5: Year 7 CPI | BW5: Year 8 CPI | BX5: Year 9 CPI | BY5: Year 10 CPI | BZ5: CPI | CA5: Total Term Cost | CE5: Year 1 Quantity | CF5: Year 2 Quantity | CG5: Year 3 Quantity | CH5: Year 4 Quantity | CI5: Year 5 Quantity | CJ5: Year 6 Quantity | CK5: Year 7 Quantity | CL5: Year 8 Quantity | CM5: Year 9 Quantity | CN5: Year 10 Quantity | CO5: Solution Name/Description | CP5: Per Unit Rate | CQ5: Year 1 Monthly Cost | CR5: Year 1 Cost | CS5: Year 2 Cost | CT5: Year 3 Cost | CU5: Year 4 Cost | CV5: Year 5 Cost | CW5: Year 6 Cost | CX5: Year 7 Cost | CY5: Year 8 Cost | CZ5: Year 9 Cost | DA5: Year 10 Cost | DB5: Year 1 CPI | DC5: Year 2 CPI | DD5: Year 3 CPI | DE5: Year 4 CPI | DF5: Year 5 CPI | DG5: Year 6 CPI | DH5: Year 7 CPI | DI5: Year 8 CPI | DJ5: Year 9 CPI | DK5: Year 10 CPI | DL5: CPI | DM5: Total Term Cost
B6: Recurring Monthly and Annual Fees - Bundle FIS products | AP6: Recurring Monthly and Annual Fees Jack Henry Product | CC6: Recurring Monthly and Annual Fees
B7: Monthly F | C7: 1 | D7: =IFERROR(AVERAGE(C7:C7),0) -> 1 | E7: =IF($B7="Annual",1,IF($B7="Monthly F",12,IF($B7="Monthly V",D7*12,IF($B7="One-Time",1,D7*12)))) -> 12 | F7: 0 | G7: 0 | H7: 0 | I7: 0 | J7: 0 | K7: 0 | L7: 0 | M7: 0 | N7: 0 | O7: Year 1 CORE PROCESSING (Bundle) | P7: HORIZON CORE ACCOUNT PROCESSING | Q7: 15000 | R7: =S7/12 -> 15000 | S7: =IFERROR($Q7*E7,0) -> 180000 | T7: =IFERROR($Q7*F7,0) -> 0 | U7: =IFERROR($Q7*G7,0) -> 0 | V7: =IFERROR($Q7*H7,0) -> 0 | W7: =IFERROR($Q7*I7,0) -> 0 | X7: =IFERROR($Q7*J7,0) -> 0 | Y7: =IFERROR($Q7*K7,0) -> 0 | Z7: =IFERROR($Q7*L7,0) -> 0 | ... AB7: =IFERROR($Q7*N7,0) -> 0 | AD7: 0 | AE7: 0 | AF7: 0 | AG7: 0 | AH7: 0 | AI7: 0 | AJ7: 0 | AK7: 0 | AL7: 0 | AM7: =SUM(AC7:AL7) -> 0 | AN7: =SUM(AM7,S7:AB7) -> 180000 | AP7: Monthly V | AQ7: 5000 | AR7: =IF($AP7="Annual",1,IF($AP7="Monthly F",12,IF($AP7="Monthly V",AQ7*12,IF($AP7="One-Time",1,AQ7*12)))) -> 60000 | AS7: {=IFERROR(_xlfn.IFS(VALUE(MID(AS$5,6,1))>$D$2,0,$AP7="Annual",1,AR7=12,12,$AP7="Monthly V",AR7*(1+$BD$2),$AP7="Monthly F",12,$AP7="One-Time",0),AR7*(1+$BD$2))} -> 60000 | AT7: {=IFERROR(_xlfn.IFS(VALUE(MID(AT$5,6,1))>$D$2,0,$AP7="Annual",1,AS7=12,12,$AP7="Monthly V",AS7*(1+$BD$2),$AP7="Monthly F",12,$AP7="One-Time",0),AS7*(1+$BD$2))} -> 60000 | AU7: {=IFERROR(_xlfn.IFS(VALUE(MID(AU$5,6,1))>$D$2,0,$AP7="Annual",1,AT7=12,12,$AP7="Monthly V",AT7*(1+$BD$2),$AP7="Monthly F",12,$AP7="One-Time",0),AT7*(1+$BD$2))} -> 60000 | AV7: {=IFERROR(_xlfn.IFS(VALUE(MID(AV$5,6,1))>$D$2,0,$AP7="Annual",1,AU7=12,12,$AP7="Monthly V",AU7*(1+$BD$2),$AP7="Monthly F",12,$AP7="One-Time",0),AU7*(1+$BD$2))} -> 60000 | AW7: {=IFERROR(_xlfn.IFS(VALUE(MID(AW$5,6,1))>$D$2,0,$AP7="Annual",1,AV7=12,12,$AP7="Monthly V",AV7*(1+$BD$2),$AP7="Monthly F",12,$AP7="One-Time",0),AV7*(1+$BD$2))} -> 60000 | AX7: {=IFERROR(_xlfn.IFS(VALUE(MID(AX$5,6,1))>$D$2,0,$AP7="Annual",1,AW7=12,12,$AP7="Monthly V",AW7*(1+$BD$2),$AP7="Monthly F",12,$AP7="One-Time",0),AW7*(1+$BD$2))} -> 60000 | AY7: {=IFERROR(_xlfn.IFS(VALUE(MID(AY$5,6,1))>$D$2,0,$AP7="Annual",1,AX7=12,12,$AP7="Monthly V",AX7*(1+$D$3),$AP7="Monthly F",12,$AP7="One-Time",0),AX7*(1+$D$3))} -> 0 | AZ7: {=IFERROR(_xlfn.IFS(VALUE(MID(AZ$5,6,1))>$D$2,0,$AP7="Annual",1,AY7=12,12,$AP7="Monthly V",AY7*(1+$D$3),$AP7="Monthly F",12,$AP7="One-Time",0),AY7*(1+$D$3))} -> 0 | BA7: {=IFERROR(_xlfn.IFS(VALUE(MID(BA$5,6,2))>$D$2,0,$AP7="Annual",1,AZ7=12,12,$AP7="Monthly V",AZ7*(1+$D$3),$AP7="Monthly F",12,$AP7="One-Time",0),AZ7*(1+$D$3))} -> 0 | BB7: SilverLake System Bundle | BC7: SilverLake | BD7: 1.2181 | BE7: =BF7/12 -> 6090.5 | BF7: =IFERROR(AR7*$BD7,0) -> 73086 | BG7: =IFERROR(AS7*$BD7,0) -> 73086 | BH7: =IFERROR(AT7*$BD7,0) -> 73086 | BI7: =BH7*1.03 -> 75278.58 | BJ7: =BI7*1.03 -> 77536.937 | BK7: =BJ7*1.03 -> 79863.046 | BL7: =BK7*1.03 -> 82258.937 | BM7: =IFERROR(AY7*$BD7,0) -> 0 | BN7: =IFERROR(AZ7*$BD7,0) -> 0 | BO7: =IFERROR(BA7*$BD7,0) -> 0 | BQ7: =IF(VALUE(MID(BQ$5,6,1))<=$D$2,((1+$BD$3)^1-1)*BG7,0) -> 2192.58 | BR7: =IF(VALUE(MID(BR$5,6,1))<=$D$2,((1+$BD$3)^2-1)*BH7,0) -> 4450.9374 | BS7: =IF(VALUE(MID(BS$5,6,1))<=$D$2,((1+$BD$3)^3-1)*BI7,0) -> 6980.3569 | BT7: =IF(VALUE(MID(BT$5,6,1))<=$D$2,((1+$BD$3)^4-1)*BJ7,0) -> 9731.5687 | BU7: =IF(VALUE(MID(BU$5,6,1))<=$D$2,((1+$BD$3)^5-1)*BK7,0) -> 12720.113 | BV7: =IF(VALUE(MID(BV$5,6,1))<=$D$2,((1+$BD$3)^6-1)*BL7,0) -> 15962.536 | BW7: =IF(VALUE(MID(BW$5,6,1))<=$D$2,((1+$BD$3)^7-1)*BM7,0) -> 0 | BX7: =IF(VALUE(MID(BX$5,6,1))<=$D$2,((1+$BD$3)^8-1)*BN7,0) -> 0 | BY7: =IF(VALUE(MID(BY$5,6,2))<=$D$2,((1+$BD$3)^9-1)*BO7,0) -> 0 | BZ7: =SUM(BP7:BY7) -> 52038.091 | CA7: =SUM(BZ7,BF7:BO7) -> 586233.59 | CE7: =IF($CC7="Annual",1,IF($CC7="Monthly F",12,IF($CC7="Monthly V",CD7*12,IF($CC7="One-Time",1,CD7*12)))) -> 0 | CF7: {=IFERROR(_xlfn.IFS(VALUE(MID(CF$5,6,1))>$D$2,0,$CC7="Annual",1,CE7=12,12,$CC7="Monthly V",CE7*(1+$D$3),$CC7="Monthly F",12,$CC7="One-Time",0),CE7*(1+$D$3))} -> 0 | CG7: {=IFERROR(_xlfn.IFS(VALUE(MID(CG$5,6,1))>$D$2,0,$CC7="Annual",1,CF7=12,12,$CC7="Monthly V",CF7*(1+$D$3),$CC7="Monthly F",12,$CC7="One-Time",0),CF7*(1+$D$3))} -> 0 | CH7: {=IFERROR(_xlfn.IFS(VALUE(MID(CH$5,6,1))>$D$2,0,$CC7="Annual",1,CG7=12,12,$CC7="Monthly V",CG7*(1+$D$3),$CC7="Monthly F",12,$CC7="One-Time",0),CG7*(1+$D$3))} -> 0 | CI7: {=IFERROR(_xlfn.IFS(VALUE(MID(CI$5,6,1))>$D$2,0,$CC7="Annual",1,CH7=12,12,$CC7="Monthly V",CH7*(1+$D$3),$CC7="Monthly F",12,$CC7="One-Time",0),CH7*(1+$D$3))} -> 0 | CJ7: {=IFERROR(_xlfn.IFS(VALUE(MID(CJ$5,6,1))>$D$2,0,$CC7="Annual",1,CI7=12,12,$CC7="Monthly V",CI7*(1+$D$3),$CC7="Monthly F",12,$CC7="One-Time",0),CI7*(1+$D$3))} -> 0 | CK7: {=IFERROR(_xlfn.IFS(VALUE(MID(CK$5,6,1))>$D$2,0,$CC7="Annual",1,CJ7=12,12,$CC7="Monthly V",CJ7*(1+$D$3),$CC7="Monthly F",12,$CC7="One-Time",0),CJ7*(1+$D$3))} -> 0 | CL7: {=IFERROR(_xlfn.IFS(VALUE(MID(CL$5,6,1))>$D$2,0,$CC7="Annual",1,CK7=12,12,$CC7="Monthly V",CK7*(1+$D$3),$CC7="Monthly F",12,$CC7="One-Time",0),CK7*(1+$D$3))} -> 0 | CM7: {=IFERROR(_xlfn.IFS(VALUE(MID(CM$5,6,1))>$D$2,0,$CC7="Annual",1,CL7=12,12,$CC7="Monthly V",CL7*(1+$D$3),$CC7="Monthly F",12,$CC7="One-Time",0),CL7*(1+$D$3))} -> 0 | CN7: {=IFERROR(_xlfn.IFS(VALUE(MID(CN$5,6,2))>$D$2,0,$CC7="Annual",1,CM7=12,12,$CC7="Monthly V",CM7*(1+$D$3),$CC7="Monthly F",12,$CC7="One-Time",0),CM7*(1+$D$3))} -> 0 | CQ7: =CR7/12 -> 0 | CR7: =IFERROR(CE7*$CP7,0) -> 0 | CS7: =IFERROR(CF7*$CP7,0) -> 0 | CT7: =IFERROR(CG7*$CP7,0) -> 0 | CU7: =IFERROR(CH7*$CP7,0) -> 0 | CV7: =IFERROR(CI7*$CP7,0) -> 0 | CW7: =IFERROR(CJ7*$CP7,0) -> 0 | CX7: =IFERROR(CK7*$CP7,0) -> 0 | CY7: =IFERROR(CL7*$CP7,0) -> 0 | ... DA7: =IFERROR(CN7*$CP7,0) -> 0 | DC7: =IF(VALUE(MID(DC$5,6,1))<=$D$2,((1+$CP$3)^1-1)*CS7,0) -> 0 | DD7: =IF(VALUE(MID(DD$5,6,1))<=$D$2,((1+$CP$3)^2-1)*CT7,0) -> 0 | DE7: =IF(VALUE(MID(DE$5,6,1))<=$D$2,((1+$CP$3)^3-1)*CU7,0) -> 0 | DF7: =IF(VALUE(MID(DF$5,6,1))<=$D$2,((1+$CP$3)^4-1)*CV7,0) -> 0 | DG7: =IF(VALUE(MID(DG$5,6,1))<=$D$2,((1+$CP$3)^5-1)*CW7,0) -> 0 | DH7: =IF(VALUE(MID(DH$5,6,1))<=$D$2,((1+$CP$3)^6-1)*CX7,0) -> 0 | DI7: =IF(VALUE(MID(DI$5,6,1))<=$D$2,((1+$CP$3)^7-1)*CY7,0) -> 0 | DJ7: =IF(VALUE(MID(DJ$5,6,1))<=$D$2,((1+$CP$3)^8-1)*CZ7,0) -> 0 | DK7: =IF(VALUE(MID(DK$5,6,2))<=$D$2,((1+$CP$3)^9-1)*DA7,0) -> 0 | DL7: =SUM(DB7:DK7) -> 0 | DM7: =SUM(DL7,CR7:DA7) -> 0
B8: Monthly F | C8: 1 | D8: =IFERROR(AVERAGE(C8:C8),0) -> 1 | E8: 0 | F8: {=IFERROR(_xlfn.IFS(VALUE(MID(F$5,6,1))>$D$2,0,$B8="Annual",1,E8=12,12,$B8="Monthly V",E8*(1+$D$3),$B8="Monthly F",12,$B8="One-Time",0),E8*(1+$D$3))} -> 12 | G8: 0 | H8: 0 | I8: 0 | J8: 0 | K8: 0 | L8: 0 | M8: 0 | N8: 0 | O8: Year 2 CORE PROCESSING (Bundle) | P8: HORIZON CORE ACCOUNT PROCESSING | Q8: 17500 | R8: =S8/12 -> 0 | S8: =IFERROR($Q8*E8,0) -> 0 | T8: =IFERROR($Q8*F8,0) -> 210000 | U8: =IFERROR($Q8*G8,0) -> 0 | V8: =IFERROR($Q8*H8,0) -> 0 | W8: =IFERROR($Q8*I8,0) -> 0 | X8: =IFERROR($Q8*J8,0) -> 0 | Y8: =IFERROR($Q8*K8,0) -> 0 | Z8: =IFERROR($Q8*L8,0) -> 0 | ... AB8: =IFERROR($Q8*N8,0) -> 0 | AD8: 0 | AE8: 0 | AF8: 0 | AG8: 0 | AH8: 0 | AI8: 0 | AJ8: 0 | AK8: 0 | AL8: 0 | AM8: =SUM(AC8:AL8) -> 0 | AN8: =SUM(AM8,S8:AB8) -> 210000 | AP8: Monthly V | AQ8: 1 | AR8: =IF($AP8="Annual",1,IF($AP8="Monthly F",12,IF($AP8="Monthly V",AQ8*12,IF($AP8="One-Time",1,AQ8*12)))) -> 12 | AS8: {=IFERROR(_xlfn.IFS(VALUE(MID(AS$5,6,1))>$D$2,0,$AP8="Annual",1,AR8=12,12,$AP8="Monthly V",AR8*(1+$BD$2),$AP8="Monthly F",12,$AP8="One-Time",0),AR8*(1+$BD$2))} -> 12 | AT8: {=IFERROR(_xlfn.IFS(VALUE(MID(AT$5,6,1))>$D$2,0,$AP8="Annual",1,AS8=12,12,$AP8="Monthly V",AS8*(1+$BD$2),$AP8="Monthly F",12,$AP8="One-Time",0),AS8*(1+$BD$2))} -> 12 | AU8: {=IFERROR(_xlfn.IFS(VALUE(MID(AU$5,6,1))>$D$2,0,$AP8="Annual",1,AT8=12,12,$AP8="Monthly V",AT8*(1+$BD$2),$AP8="Monthly F",12,$AP8="One-Time",0),AT8*(1+$BD$2))} -> 12 | AV8: {=IFERROR(_xlfn.IFS(VALUE(MID(AV$5,6,1))>$D$2,0,$AP8="Annual",1,AU8=12,12,$AP8="Monthly V",AU8*(1+$BD$2),$AP8="Monthly F",12,$AP8="One-Time",0),AU8*(1+$BD$2))} -> 12 | AW8: {=IFERROR(_xlfn.IFS(VALUE(MID(AW$5,6,1))>$D$2,0,$AP8="Annual",1,AV8=12,12,$AP8="Monthly V",AV8*(1+$BD$2),$AP8="Monthly F",12,$AP8="One-Time",0),AV8*(1+$BD$2))} -> 12 | AX8: {=IFERROR(_xlfn.IFS(VALUE(MID(AX$5,6,1))>$D$2,0,$AP8="Annual",1,AW8=12,12,$AP8="Monthly V",AW8*(1+$BD$2),$AP8="Monthly F",12,$AP8="One-Time",0),AW8*(1+$BD$2))} -> 12 | AY8: {=IFERROR(_xlfn.IFS(VALUE(MID(AY$5,6,1))>$D$2,0,$AP8="Annual",1,AX8=12,12,$AP8="Monthly V",AX8*(1+$D$3),$AP8="Monthly F",12,$AP8="One-Time",0),AX8*(1+$D$3))} -> 0 | AZ8: {=IFERROR(_xlfn.IFS(VALUE(MID(AZ$5,6,1))>$D$2,0,$AP8="Annual",1,AY8=12,12,$AP8="Monthly V",AY8*(1+$D$3),$AP8="Monthly F",12,$AP8="One-Time",0),AY8*(1+$D$3))} -> 0 | BA8: {=IFERROR(_xlfn.IFS(VALUE(MID(BA$5,6,2))>$D$2,0,$AP8="Annual",1,AZ8=12,12,$AP8="Monthly V",AZ8*(1+$D$3),$AP8="Monthly F",12,$AP8="One-Time",0),AZ8*(1+$D$3))} -> 0 | BB8: Closed Accounts (PAP) | BC8: SilverLake | BD8: 0.25 | BE8: =BF8/12 -> 0.25 | BF8: =IFERROR(AR8*$BD8,0) -> 3 | BG8: =IFERROR(AS8*$BD8,0) -> 3 | BH8: =IFERROR(AT8*$BD8,0) -> 3 | BI8: =BH8*1.03 -> 3.09 | BJ8: =IFERROR(AV8*$BD8,0) -> 3 | BK8: =IFERROR(AW8*$BD8,0) -> 3 | BL8: =IFERROR(AX8*$BD8,0) -> 3 | BM8: =IFERROR(AY8*$BD8,0) -> 0 | BN8: =IFERROR(AZ8*$BD8,0) -> 0 | BO8: =IFERROR(BA8*$BD8,0) -> 0 | BQ8: =IF(VALUE(MID(BQ$5,6,1))<=$D$2,((1+$BD$3)^1-1)*BG8,0) -> 0.09 | BR8: =IF(VALUE(MID(BR$5,6,1))<=$D$2,((1+$BD$3)^2-1)*BH8,0) -> 0.1827 | BS8: =IF(VALUE(MID(BS$5,6,1))<=$D$2,((1+$BD$3)^3-1)*BI8,0) -> 0.28652643 | BT8: =IF(VALUE(MID(BT$5,6,1))<=$D$2,((1+$BD$3)^4-1)*BJ8,0) -> 0.37652643 | BU8: =IF(VALUE(MID(BU$5,6,1))<=$D$2,((1+$BD$3)^5-1)*BK8,0) -> 0.47782222 | BV8: =IF(VALUE(MID(BV$5,6,1))<=$D$2,((1+$BD$3)^6-1)*BL8,0) -> 0.58215689 | BW8: =IF(VALUE(MID(BW$5,6,1))<=$D$2,((1+$BD$3)^7-1)*BM8,0) -> 0 | BX8: =IF(VALUE(MID(BX$5,6,1))<=$D$2,((1+$BD$3)^8-1)*BN8,0) -> 0 | BY8: =IF(VALUE(MID(BY$5,6,2))<=$D$2,((1+$BD$3)^9-1)*BO8,0) -> 0 | BZ8: =SUM(BP8:BY8) -> 1.995732 | CA8: =SUM(BZ8,BF8:BO8) -> 23.085732 | CE8: =IF($CC8="Annual",1,IF($CC8="Monthly F",12,IF($CC8="Monthly V",CD8*12,IF($CC8="One-Time",1,CD8*12)))) -> 0 | CF8: {=IFERROR(_xlfn.IFS(VALUE(MID(CF$5,6,1))>$D$2,0,$CC8="Annual",1,CE8=12,12,$CC8="Monthly V",CE8*(1+$D$3),$CC8="Monthly F",12,$CC8="One-Time",0),CE8*(1+$D$3))} -> 0 | CG8: {=IFERROR(_xlfn.IFS(VALUE(MID(CG$5,6,1))>$D$2,0,$CC8="Annual",1,CF8=12,12,$CC8="Monthly V",CF8*(1+$D$3),$CC8="Monthly F",12,$CC8="One-Time",0),CF8*(1+$D$3))} -> 0 | CH8: {=IFERROR(_xlfn.IFS(VALUE(MID(CH$5,6,1))>$D$2,0,$CC8="Annual",1,CG8=12,12,$CC8="Monthly V",CG8*(1+$D$3),$CC8="Monthly F",12,$CC8="One-Time",0),CG8*(1+$D$3))} -> 0 | CI8: {=IFERROR(_xlfn.IFS(VALUE(MID(CI$5,6,1))>$D$2,0,$CC8="Annual",1,CH8=12,12,$CC8="Monthly V",CH8*(1+$D$3),$CC8="Monthly F",12,$CC8="One-Time",0),CH8*(1+$D$3))} -> 0 | CJ8: {=IFERROR(_xlfn.IFS(VALUE(MID(CJ$5,6,1))>$D$2,0,$CC8="Annual",1,CI8=12,12,$CC8="Monthly V",CI8*(1+$D$3),$CC8="Monthly F",12,$CC8="One-Time",0),CI8*(1+$D$3))} -> 0 | CK8: {=IFERROR(_xlfn.IFS(VALUE(MID(CK$5,6,1))>$D$2,0,$CC8="Annual",1,CJ8=12,12,$CC8="Monthly V",CJ8*(1+$D$3),$CC8="Monthly F",12,$CC8="One-Time",0),CJ8*(1+$D$3))} -> 0 | CL8: {=IFERROR(_xlfn.IFS(VALUE(MID(CL$5,6,1))>$D$2,0,$CC8="Annual",1,CK8=12,12,$CC8="Monthly V",CK8*(1+$D$3),$CC8="Monthly F",12,$CC8="One-Time",0),CK8*(1+$D$3))} -> 0 | CM8: {=IFERROR(_xlfn.IFS(VALUE(MID(CM$5,6,1))>$D$2,0,$CC8="Annual",1,CL8=12,12,$CC8="Monthly V",CL8*(1+$D$3),$CC8="Monthly F",12,$CC8="One-Time",0),CL8*(1+$D$3))} -> 0 | CN8: {=IFERROR(_xlfn.IFS(VALUE(MID(CN$5,6,2))>$D$2,0,$CC8="Annual",1,CM8=12,12,$CC8="Monthly V",CM8*(1+$D$3),$CC8="Monthly F",12,$CC8="One-Time",0),CM8*(1+$D$3))} -> 0 | CQ8: =CR8/12 -> 0 | CR8: =IFERROR(CE8*$CP8,0) -> 0 | CS8: =IFERROR(CF8*$CP8,0) -> 0 | CT8: =IFERROR(CG8*$CP8,0) -> 0 | CU8: =IFERROR(CH8*$CP8,0) -> 0 | CV8: =IFERROR(CI8*$CP8,0) -> 0 | CW8: =IFERROR(CJ8*$CP8,0) -> 0 | CX8: =IFERROR(CK8*$CP8,0) -> 0 | CY8: =IFERROR(CL8*$CP8,0) -> 0 | ... DA8: =IFERROR(CN8*$CP8,0) -> 0 | DC8: =IF(VALUE(MID(DC$5,6,1))<=$D$2,((1+$CP$3)^1-1)*CS8,0) -> 0 | DD8: =IF(VALUE(MID(DD$5,6,1))<=$D$2,((1+$CP$3)^2-1)*CT8,0) -> 0 | DE8: =IF(VALUE(MID(DE$5,6,1))<=$D$2,((1+$CP$3)^3-1)*CU8,0) -> 0 | DF8: =IF(VALUE(MID(DF$5,6,1))<=$D$2,((1+$CP$3)^4-1)*CV8,0) -> 0 | DG8: =IF(VALUE(MID(DG$5,6,1))<=$D$2,((1+$CP$3)^5-1)*CW8,0) -> 0 | DH8: =IF(VALUE(MID(DH$5,6,1))<=$D$2,((1+$CP$3)^6-1)*CX8,0) -> 0 | DI8: =IF(VALUE(MID(DI$5,6,1))<=$D$2,((1+$CP$3)^7-1)*CY8,0) -> 0 | DJ8: =IF(VALUE(MID(DJ$5,6,1))<=$D$2,((1+$CP$3)^8-1)*CZ8,0) -> 0 | DK8: =IF(VALUE(MID(DK$5,6,2))<=$D$2,((1+$CP$3)^9-1)*DA8,0) -> 0 | DL8: =SUM(DB8:DK8) -> 0 | DM8: =SUM(DL8,CR8:DA8) -> 0
B9: Monthly F | C9: 1 | D9: =IFERROR(AVERAGE(C9:C9),0) -> 1 | E9: 0 | F9: 0 | G9: {=IFERROR(_xlfn.IFS(VALUE(MID(G$5,6,1))>$D$2,0,$B9="Annual",1,F9=12,12,$B9="Monthly V",F9*(1+$D$3),$B9="Monthly F",12,$B9="One-Time",0),F9*(1+$D$3))} -> 12 | H9: 0 | I9: 0 | J9: 0 | K9: 0 | L9: 0 | M9: 0 | N9: 0 | O9: Year 3 CORE PROCESSING (Bundle) | P9: HORIZON CORE ACCOUNT PROCESSING | Q9: 22500 | R9: =S9/12 -> 0 | S9: =IFERROR($Q9*E9,0) -> 0 | T9: =IFERROR($Q9*F9,0) -> 0 | U9: =IFERROR($Q9*G9,0) -> 270000 | V9: =IFERROR($Q9*H9,0) -> 0 | W9: =IFERROR($Q9*I9,0) -> 0 | X9: =IFERROR($Q9*J9,0) -> 0 | Y9: =IFERROR($Q9*K9,0) -> 0 | Z9: =IFERROR($Q9*L9,0) -> 0 | ... AB9: =IFERROR($Q9*N9,0) -> 0 | AD9: 0 | AE9: 0 | AF9: 0 | AG9: 0 | AH9: 0 | AI9: 0 | AJ9: 0 | AK9: 0 | AL9: 0 | AM9: =SUM(AC9:AL9) -> 0 | AN9: =SUM(AM9,S9:AB9) -> 270000 | AP9: Monthly F | AQ9: 1 | AR9: =IF($AP9="Annual",1,IF($AP9="Monthly F",12,IF($AP9="Monthly V",AQ9*12,IF($AP9="One-Time",1,AQ9*12)))) -> 12 | AS9: {=IFERROR(_xlfn.IFS(VALUE(MID(AS$5,6,1))>$D$2,0,$AP9="Annual",1,AR9=12,12,$AP9="Monthly V",AR9*(1+$BD$2),$AP9="Monthly F",12,$AP9="One-Time",0),AR9*(1+$BD$2))} -> 12 | AT9: {=IFERROR(_xlfn.IFS(VALUE(MID(AT$5,6,1))>$D$2,0,$AP9="Annual",1,AS9=12,12,$AP9="Monthly V",AS9*(1+$BD$2),$AP9="Monthly F",12,$AP9="One-Time",0),AS9*(1+$BD$2))} -> 12 | AU9: {=IFERROR(_xlfn.IFS(VALUE(MID(AU$5,6,1))>$D$2,0,$AP9="Annual",1,AT9=12,12,$AP9="Monthly V",AT9*(1+$BD$2),$AP9="Monthly F",12,$AP9="One-Time",0),AT9*(1+$BD$2))} -> 12 | AV9: {=IFERROR(_xlfn.IFS(VALUE(MID(AV$5,6,1))>$D$2,0,$AP9="Annual",1,AU9=12,12,$AP9="Monthly V",AU9*(1+$BD$2),$AP9="Monthly F",12,$AP9="One-Time",0),AU9*(1+$BD$2))} -> 12 | AW9: {=IFERROR(_xlfn.IFS(VALUE(MID(AW$5,6,1))>$D$2,0,$AP9="Annual",1,AV9=12,12,$AP9="Monthly V",AV9*(1+$BD$2),$AP9="Monthly F",12,$AP9="One-Time",0),AV9*(1+$BD$2))} -> 12 | AX9: {=IFERROR(_xlfn.IFS(VALUE(MID(AX$5,6,1))>$D$2,0,$AP9="Annual",1,AW9=12,12,$AP9="Monthly V",AW9*(1+$BD$2),$AP9="Monthly F",12,$AP9="One-Time",0),AW9*(1+$BD$2))} -> 12 | AY9: {=IFERROR(_xlfn.IFS(VALUE(MID(AY$5,6,1))>$D$2,0,$AP9="Annual",1,AX9=12,12,$AP9="Monthly V",AX9*(1+$D$3),$AP9="Monthly F",12,$AP9="One-Time",0),AX9*(1+$D$3))} -> 0 | AZ9: {=IFERROR(_xlfn.IFS(VALUE(MID(AZ$5,6,1))>$D$2,0,$AP9="Annual",1,AY9=12,12,$AP9="Monthly V",AY9*(1+$D$3),$AP9="Monthly F",12,$AP9="One-Time",0),AY9*(1+$D$3))} -> 0 | BA9: {=IFERROR(_xlfn.IFS(VALUE(MID(BA$5,6,2))>$D$2,0,$AP9="Annual",1,AZ9=12,12,$AP9="Monthly V",AZ9*(1+$D$3),$AP9="Monthly F",12,$AP9="One-Time",0),AZ9*(1+$D$3))} -> 0 | BB9: Daily File Transfer Integration IntraFi | BC9: SilverLake | BD9: 225 | BE9: =BF9/12 -> 225 | BF9: =IFERROR(AR9*$BD9,0) -> 2700 | BG9: =IFERROR(AS9*$BD9,0) -> 2700 | BH9: =IFERROR(AT9*$BD9,0) -> 2700 | BI9: =BH9*1.03 -> 2781 | BJ9: =BI9*1.03 -> 2864.43 | BK9: =BJ9*1.03 -> 2950.3629 | BL9: =BK9*1.03 -> 3038.8738 | BM9: =IFERROR(AY9*$BD9,0) -> 0 | BN9: =IFERROR(AZ9*$BD9,0) -> 0 | BO9: =IFERROR(BA9*$BD9,0) -> 0 | BQ9: =IF(VALUE(MID(BQ$5,6,1))<=$D$2,((1+$BD$3)^1-1)*BG9,0) -> 81 | BR9: =IF(VALUE(MID(BR$5,6,1))<=$D$2,((1+$BD$3)^2-1)*BH9,0) -> 164.43 | BS9: =IF(VALUE(MID(BS$5,6,1))<=$D$2,((1+$BD$3)^3-1)*BI9,0) -> 257.87379 | BT9: =IF(VALUE(MID(BT$5,6,1))<=$D$2,((1+$BD$3)^4-1)*BJ9,0) -> 359.5112 | BU9: =IF(VALUE(MID(BU$5,6,1))<=$D$2,((1+$BD$3)^5-1)*BK9,0) -> 469.91632 | BV9: =IF(VALUE(MID(BV$5,6,1))<=$D$2,((1+$BD$3)^6-1)*BL9,0) -> 589.70044 | BW9: =IF(VALUE(MID(BW$5,6,1))<=$D$2,((1+$BD$3)^7-1)*BM9,0) -> 0 | BX9: =IF(VALUE(MID(BX$5,6,1))<=$D$2,((1+$BD$3)^8-1)*BN9,0) -> 0 | BY9: =IF(VALUE(MID(BY$5,6,2))<=$D$2,((1+$BD$3)^9-1)*BO9,0) -> 0 | BZ9: =SUM(BP9:BY9) -> 1922.4317 | CA9: =SUM(BZ9,BF9:BO9) -> 21657.098 | CE9: =IF($CC9="Annual",1,IF($CC9="Monthly F",12,IF($CC9="Monthly V",CD9*12,IF($CC9="One-Time",1,CD9*12)))) -> 0 | CF9: {=IFERROR(_xlfn.IFS(VALUE(MID(CF$5,6,1))>$D$2,0,$CC9="Annual",1,CE9=12,12,$CC9="Monthly V",CE9*(1+$D$3),$CC9="Monthly F",12,$CC9="One-Time",0),CE9*(1+$D$3))} -> 0 | CG9: {=IFERROR(_xlfn.IFS(VALUE(MID(CG$5,6,1))>$D$2,0,$CC9="Annual",1,CF9=12,12,$CC9="Monthly V",CF9*(1+$D$3),$CC9="Monthly F",12,$CC9="One-Time",0),CF9*(1+$D$3))} -> 0 | CH9: {=IFERROR(_xlfn.IFS(VALUE(MID(CH$5,6,1))>$D$2,0,$CC9="Annual",1,CG9=12,12,$CC9="Monthly V",CG9*(1+$D$3),$CC9="Monthly F",12,$CC9="One-Time",0),CG9*(1+$D$3))} -> 0 | CI9: {=IFERROR(_xlfn.IFS(VALUE(MID(CI$5,6,1))>$D$2,0,$CC9="Annual",1,CH9=12,12,$CC9="Monthly V",CH9*(1+$D$3),$CC9="Monthly F",12,$CC9="One-Time",0),CH9*(1+$D$3))} -> 0 | CJ9: {=IFERROR(_xlfn.IFS(VALUE(MID(CJ$5,6,1))>$D$2,0,$CC9="Annual",1,CI9=12,12,$CC9="Monthly V",CI9*(1+$D$3),$CC9="Monthly F",12,$CC9="One-Time",0),CI9*(1+$D$3))} -> 0 | CK9: {=IFERROR(_xlfn.IFS(VALUE(MID(CK$5,6,1))>$D$2,0,$CC9="Annual",1,CJ9=12,12,$CC9="Monthly V",CJ9*(1+$D$3),$CC9="Monthly F",12,$CC9="One-Time",0),CJ9*(1+$D$3))} -> 0 | CL9: {=IFERROR(_xlfn.IFS(VALUE(MID(CL$5,6,1))>$D$2,0,$CC9="Annual",1,CK9=12,12,$CC9="Monthly V",CK9*(1+$D$3),$CC9="Monthly F",12,$CC9="One-Time",0),CK9*(1+$D$3))} -> 0 | CM9: {=IFERROR(_xlfn.IFS(VALUE(MID(CM$5,6,1))>$D$2,0,$CC9="Annual",1,CL9=12,12,$CC9="Monthly V",CL9*(1+$D$3),$CC9="Monthly F",12,$CC9="One-Time",0),CL9*(1+$D$3))} -> 0 | CN9: {=IFERROR(_xlfn.IFS(VALUE(MID(CN$5,6,2))>$D$2,0,$CC9="Annual",1,CM9=12,12,$CC9="Monthly V",CM9*(1+$D$3),$CC9="Monthly F",12,$CC9="One-Time",0),CM9*(1+$D$3))} -> 0 | CQ9: =CR9/12 -> 0 | CR9: =IFERROR(CE9*$CP9,0) -> 0 | CS9: =IFERROR(CF9*$CP9,0) -> 0 | CT9: =IFERROR(CG9*$CP9,0) -> 0 | CU9: =IFERROR(CH9*$CP9,0) -> 0 | CV9: =IFERROR(CI9*$CP9,0) -> 0 | CW9: =IFERROR(CJ9*$CP9,0) -> 0 | CX9: =IFERROR(CK9*$CP9,0) -> 0 | CY9: =IFERROR(CL9*$CP9,0) -> 0 | ... DA9: =IFERROR(CN9*$CP9,0) -> 0 | DC9: =IF(VALUE(MID(DC$5,6,1))<=$D$2,((1+$CP$3)^1-1)*CS9,0) -> 0 | DD9: =IF(VALUE(MID(DD$5,6,1))<=$D$2,((1+$CP$3)^2-1)*CT9,0) -> 0 | DE9: =IF(VALUE(MID(DE$5,6,1))<=$D$2,((1+$CP$3)^3-1)*CU9,0) -> 0 | DF9: =IF(VALUE(MID(DF$5,6,1))<=$D$2,((1+$CP$3)^4-1)*CV9,0) -> 0 | DG9: =IF(VALUE(MID(DG$5,6,1))<=$D$2,((1+$CP$3)^5-1)*CW9,0) -> 0 | DH9: =IF(VALUE(MID(DH$5,6,1))<=$D$2,((1+$CP$3)^6-1)*CX9,0) -> 0 | DI9: =IF(VALUE(MID(DI$5,6,1))<=$D$2,((1+$CP$3)^7-1)*CY9,0) -> 0 | DJ9: =IF(VALUE(MID(DJ$5,6,1))<=$D$2,((1+$CP$3)^8-1)*CZ9,0) -> 0 | DK9: =IF(VALUE(MID(DK$5,6,2))<=$D$2,((1+$CP$3)^9-1)*DA9,0) -> 0 | DL9: =SUM(DB9:DK9) -> 0 | DM9: =SUM(DL9,CR9:DA9) -> 0
B10: Monthly F | C10: 1 | D10: =IFERROR(AVERAGE(C10:C10),0) -> 1 | E10: 0 | F10: 0 | G10: 0 | H10: {=IFERROR(_xlfn.IFS(VALUE(MID(H$5,6,1))>$D$2,0,$B10="Annual",1,G10=12,12,$B10="Monthly V",G10*(1+$D$3),$B10="Monthly F",12,$B10="One-Time",0),G10*(1+$D$3))} -> 12 | I10: 0 | J10: 0 | K10: 0 | L10: 0 | M10: 0 | N10: 0 | O10: Year 4 CORE PROCESSING (Bundle) | P10: HORIZON CORE ACCOUNT PROCESSING | Q10: 28000 | R10: =S10/12 -> 0 | S10: =IFERROR($Q10*E10,0) -> 0 | T10: =IFERROR($Q10*F10,0) -> 0 | U10: =IFERROR($Q10*G10,0) -> 0 | V10: =IFERROR($Q10*H10,0) -> 336000 | W10: =IFERROR($Q10*I10,0) -> 0 | X10: =IFERROR($Q10*J10,0) -> 0 | Y10: =IFERROR($Q10*K10,0) -> 0 | Z10: =IFERROR($Q10*L10,0) -> 0 | ... AB10: =IFERROR($Q10*N10,0) -> 0 | AD10: 0 | AE10: 0 | AF10: 0 | AG10: 0 | AH10: 0 | AI10: 0 | AJ10: 0 | AK10: 0 | AL10: 0 | AM10: =SUM(AC10:AL10) -> 0 | AN10: =SUM(AM10,S10:AB10) -> 336000 | AP10: Monthly V | AQ10: 5000 | AR10: =IF($AP10="Annual",1,IF($AP10="Monthly F",12,IF($AP10="Monthly V",AQ10*12,IF($AP10="One-Time",1,AQ10*12)))) -> 60000 | AS10: {=IFERROR(_xlfn.IFS(VALUE(MID(AS$5,6,1))>$D$2,0,$AP10="Annual",1,AR10=12,12,$AP10="Monthly V",AR10*(1+$BD$2),$AP10="Monthly F",12,$AP10="One-Time",0),AR10*(1+$BD$2))} -> 60000 | AT10: {=IFERROR(_xlfn.IFS(VALUE(MID(AT$5,6,1))>$D$2,0,$AP10="Annual",1,AS10=12,12,$AP10="Monthly V",AS10*(1+$BD$2),$AP10="Monthly F",12,$AP10="One-Time",0),AS10*(1+$BD$2))} -> 60000 | AU10: {=IFERROR(_xlfn.IFS(VALUE(MID(AU$5,6,1))>$D$2,0,$AP10="Annual",1,AT10=12,12,$AP10="Monthly V",AT10*(1+$BD$2),$AP10="Monthly F",12,$AP10="One-Time",0),AT10*(1+$BD$2))} -> 60000 | AV10: {=IFERROR(_xlfn.IFS(VALUE(MID(AV$5,6,1))>$D$2,0,$AP10="Annual",1,AU10=12,12,$AP10="Monthly V",AU10*(1+$BD$2),$AP10="Monthly F",12,$AP10="One-Time",0),AU10*(1+$BD$2))} -> 60000 | AW10: {=IFERROR(_xlfn.IFS(VALUE(MID(AW$5,6,1))>$D$2,0,$AP10="Annual",1,AV10=12,12,$AP10="Monthly V",AV10*(1+$BD$2),$AP10="Monthly F",12,$AP10="One-Time",0),AV10*(1+$BD$2))} -> 60000 | AX10: {=IFERROR(_xlfn.IFS(VALUE(MID(AX$5,6,1))>$D$2,0,$AP10="Annual",1,AW10=12,12,$AP10="Monthly V",AW10*(1+$BD$2),$AP10="Monthly F",12,$AP10="One-Time",0),AW10*(1+$BD$2))} -> 60000 | AY10: {=IFERROR(_xlfn.IFS(VALUE(MID(AY$5,6,1))>$D$2,0,$AP10="Annual",1,AX10=12,12,$AP10="Monthly V",AX10*(1+$D$3),$AP10="Monthly F",12,$AP10="One-Time",0),AX10*(1+$D$3))} -> 0 | AZ10: {=IFERROR(_xlfn.IFS(VALUE(MID(AZ$5,6,1))>$D$2,0,$AP10="Annual",1,AY10=12,12,$AP10="Monthly V",AY10*(1+$D$3),$AP10="Monthly F",12,$AP10="One-Time",0),AY10*(1+$D$3))} -> 0 | BA10: {=IFERROR(_xlfn.IFS(VALUE(MID(BA$5,6,2))>$D$2,0,$AP10="Annual",1,AZ10=12,12,$AP10="Monthly V",AZ10*(1+$D$3),$AP10="Monthly F",12,$AP10="One-Time",0),AZ10*(1+$D$3))} -> 0 | BB10: Hosted Xperience | BC10: Xperience | BD10: 0.0225 | BE10: =BF10/12 -> 112.5 | BF10: =IFERROR(AR10*$BD10,0) -> 1350 | BG10: =IFERROR(AS10*$BD10,0) -> 1350 | BH10: =IFERROR(AT10*$BD10,0) -> 1350 | BI10: =BH10*1.03 -> 1390.5 | BJ10: =BI10*1.03 -> 1432.215 | BK10: =BJ10*1.03 -> 1475.1815 | BL10: =BK10*1.03 -> 1519.4369 | BM10: =IFERROR(AY10*$BD10,0) -> 0 | BN10: =IFERROR(AZ10*$BD10,0) -> 0 | BO10: =IFERROR(BA10*$BD10,0) -> 0 | BQ10: =IF(VALUE(MID(BQ$5,6,1))<=$D$2,((1+$BD$3)^1-1)*BG10,0) -> 40.5 | BR10: =IF(VALUE(MID(BR$5,6,1))<=$D$2,((1+$BD$3)^2-1)*BH10,0) -> 82.215 | BS10: =IF(VALUE(MID(BS$5,6,1))<=$D$2,((1+$BD$3)^3-1)*BI10,0) -> 128.93689 | BT10: =IF(VALUE(MID(BT$5,6,1))<=$D$2,((1+$BD$3)^4-1)*BJ10,0) -> 179.7556 | BU10: =IF(VALUE(MID(BU$5,6,1))<=$D$2,((1+$BD$3)^5-1)*BK10,0) -> 234.95816 | BV10: =IF(VALUE(MID(BV$5,6,1))<=$D$2,((1+$BD$3)^6-1)*BL10,0) -> 294.85022 | BW10: =IF(VALUE(MID(BW$5,6,1))<=$D$2,((1+$BD$3)^7-1)*BM10,0) -> 0 | BX10: =IF(VALUE(MID(BX$5,6,1))<=$D$2,((1+$BD$3)^8-1)*BN10,0) -> 0 | BY10: =IF(VALUE(MID(BY$5,6,2))<=$D$2,((1+$BD$3)^9-1)*BO10,0) -> 0 | BZ10: =SUM(BP10:BY10) -> 961.21587 | CA10: =SUM(BZ10,BF10:BO10) -> 10828.549 | CE10: =IF($CC10="Annual",1,IF($CC10="Monthly F",12,IF($CC10="Monthly V",CD10*12,IF($CC10="One-Time",1,CD10*12)))) -> 0 | CF10: {=IFERROR(_xlfn.IFS(VALUE(MID(CF$5,6,1))>$D$2,0,$CC10="Annual",1,CE10=12,12,$CC10="Monthly V",CE10*(1+$D$3),$CC10="Monthly F",12,$CC10="One-Time",0),CE10*(1+$D$3))} -> 0 | CG10: {=IFERROR(_xlfn.IFS(VALUE(MID(CG$5,6,1))>$D$2,0,$CC10="Annual",1,CF10=12,12,$CC10="Monthly V",CF10*(1+$D$3),$CC10="Monthly F",12,$CC10="One-Time",0),CF10*(1+$D$3))} -> 0 | CH10: {=IFERROR(_xlfn.IFS(VALUE(MID(CH$5,6,1))>$D$2,0,$CC10="Annual",1,CG10=12,12,$CC10="Monthly V",CG10*(1+$D$3),$CC10="Monthly F",12,$CC10="One-Time",0),CG10*(1+$D$3))} -> 0 | CI10: {=IFERROR(_xlfn.IFS(VALUE(MID(CI$5,6,1))>$D$2,0,$CC10="Annual",1,CH10=12,12,$CC10="Monthly V",CH10*(1+$D$3),$CC10="Monthly F",12,$CC10="One-Time",0),CH10*(1+$D$3))} -> 0 | CJ10: {=IFERROR(_xlfn.IFS(VALUE(MID(CJ$5,6,1))>$D$2,0,$CC10="Annual",1,CI10=12,12,$CC10="Monthly V",CI10*(1+$D$3),$CC10="Monthly F",12,$CC10="One-Time",0),CI10*(1+$D$3))} -> 0 | CK10: {=IFERROR(_xlfn.IFS(VALUE(MID(CK$5,6,1))>$D$2,0,$CC10="Annual",1,CJ10=12,12,$CC10="Monthly V",CJ10*(1+$D$3),$CC10="Monthly F",12,$CC10="One-Time",0),CJ10*(1+$D$3))} -> 0 | CL10: {=IFERROR(_xlfn.IFS(VALUE(MID(CL$5,6,1))>$D$2,0,$CC10="Annual",1,CK10=12,12,$CC10="Monthly V",CK10*(1+$D$3),$CC10="Monthly F",12,$CC10="One-Time",0),CK10*(1+$D$3))} -> 0 | CM10: {=IFERROR(_xlfn.IFS(VALUE(MID(CM$5,6,1))>$D$2,0,$CC10="Annual",1,CL10=12,12,$CC10="Monthly V",CL10*(1+$D$3),$CC10="Monthly F",12,$CC10="One-Time",0),CL10*(1+$D$3))} -> 0 | CN10: {=IFERROR(_xlfn.IFS(VALUE(MID(CN$5,6,2))>$D$2,0,$CC10="Annual",1,CM10=12,12,$CC10="Monthly V",CM10*(1+$D$3),$CC10="Monthly F",12,$CC10="One-Time",0),CM10*(1+$D$3))} -> 0 | CQ10: =CR10/12 -> 0 | CR10: =IFERROR(CE10*$CP10,0) -> 0 | CS10: =IFERROR(CF10*$CP10,0) -> 0 | CT10: =IFERROR(CG10*$CP10,0) -> 0 | CU10: =IFERROR(CH10*$CP10,0) -> 0 | CV10: =IFERROR(CI10*$CP10,0) -> 0 | CW10: =IFERROR(CJ10*$CP10,0) -> 0 | CX10: =IFERROR(CK10*$CP10,0) -> 0 | CY10: =IFERROR(CL10*$CP10,0) -> 0 | ... DA10: =IFERROR(CN10*$CP10,0) -> 0 | DC10: =IF(VALUE(MID(DC$5,6,1))<=$D$2,((1+$CP$3)^1-1)*CS10,0) -> 0 | DD10: =IF(VALUE(MID(DD$5,6,1))<=$D$2,((1+$CP$3)^2-1)*CT10,0) -> 0 | DE10: =IF(VALUE(MID(DE$5,6,1))<=$D$2,((1+$CP$3)^3-1)*CU10,0) -> 0 | DF10: =IF(VALUE(MID(DF$5,6,1))<=$D$2,((1+$CP$3)^4-1)*CV10,0) -> 0 | DG10: =IF(VALUE(MID(DG$5,6,1))<=$D$2,((1+$CP$3)^5-1)*CW10,0) -> 0 | DH10: =IF(VALUE(MID(DH$5,6,1))<=$D$2,((1+$CP$3)^6-1)*CX10,0) -> 0 | DI10: =IF(VALUE(MID(DI$5,6,1))<=$D$2,((1+$CP$3)^7-1)*CY10,0) -> 0 | DJ10: =IF(VALUE(MID(DJ$5,6,1))<=$D$2,((1+$CP$3)^8-1)*CZ10,0) -> 0 | DK10: =IF(VALUE(MID(DK$5,6,2))<=$D$2,((1+$CP$3)^9-1)*DA10,0) -> 0 | DL10: =SUM(DB10:DK10) -> 0 | DM10: =SUM(DL10,CR10:DA10) -> 0
B11: Monthly F | C11: 1 | D11: =IFERROR(AVERAGE(C11:C11),0) -> 1 | E11: 0 | F11: 0 | G11: 0 | H11: 0 | I11: {=IFERROR(_xlfn.IFS(VALUE(MID(I$5,6,1))>$D$2,0,$B11="Annual",1,H11=12,12,$B11="Monthly V",H11*(1+$D$3),$B11="Monthly F",12,$B11="One-Time",0),H11*(1+$D$3))} -> 12 | J11: 0 | K11: 0 | L11: 0 | M11: 0 | N11: 0 | O11: Year 5 CORE PROCESSING (Bundle) | P11: HORIZON CORE ACCOUNT PROCESSING | Q11: 35000 | R11: =S11/12 -> 0 | S11: =IFERROR($Q11*E11,0) -> 0 | T11: =IFERROR($Q11*F11,0) -> 0 | U11: =IFERROR($Q11*G11,0) -> 0 | V11: =IFERROR($Q11*H11,0) -> 0 | W11: =IFERROR($Q11*I11,0) -> 420000 | X11: =IFERROR($Q11*J11,0) -> 0 | Y11: =IFERROR($Q11*K11,0) -> 0 | Z11: =IFERROR($Q11*L11,0) -> 0 | ... AB11: =IFERROR($Q11*N11,0) -> 0 | AD11: 0 | AE11: 0 | AF11: 0 | AG11: 0 | AH11: 0 | AI11: 0 | AJ11: 0 | AK11: 0 | AL11: 0 | AM11: =SUM(AC11:AL11) -> 0 | AN11: =SUM(AM11,S11:AB11) -> 420000 | AP11: Monthly V | AQ11: 5000 | AR11: =IF($AP11="Annual",1,IF($AP11="Monthly F",12,IF($AP11="Monthly V",AQ11*12,IF($AP11="One-Time",1,AQ11*12)))) -> 60000 | AS11: {=IFERROR(_xlfn.IFS(VALUE(MID(AS$5,6,1))>$D$2,0,$AP11="Annual",1,AR11=12,12,$AP11="Monthly V",AR11*(1+$BD$2),$AP11="Monthly F",12,$AP11="One-Time",0),AR11*(1+$BD$2))} -> 60000 | AT11: {=IFERROR(_xlfn.IFS(VALUE(MID(AT$5,6,1))>$D$2,0,$AP11="Annual",1,AS11=12,12,$AP11="Monthly V",AS11*(1+$BD$2),$AP11="Monthly F",12,$AP11="One-Time",0),AS11*(1+$BD$2))} -> 60000 | AU11: {=IFERROR(_xlfn.IFS(VALUE(MID(AU$5,6,1))>$D$2,0,$AP11="Annual",1,AT11=12,12,$AP11="Monthly V",AT11*(1+$BD$2),$AP11="Monthly F",12,$AP11="One-Time",0),AT11*(1+$BD$2))} -> 60000 | AV11: {=IFERROR(_xlfn.IFS(VALUE(MID(AV$5,6,1))>$D$2,0,$AP11="Annual",1,AU11=12,12,$AP11="Monthly V",AU11*(1+$BD$2),$AP11="Monthly F",12,$AP11="One-Time",0),AU11*(1+$BD$2))} -> 60000 | AW11: {=IFERROR(_xlfn.IFS(VALUE(MID(AW$5,6,1))>$D$2,0,$AP11="Annual",1,AV11=12,12,$AP11="Monthly V",AV11*(1+$BD$2),$AP11="Monthly F",12,$AP11="One-Time",0),AV11*(1+$BD$2))} -> 60000 | AX11: {=IFERROR(_xlfn.IFS(VALUE(MID(AX$5,6,1))>$D$2,0,$AP11="Annual",1,AW11=12,12,$AP11="Monthly V",AW11*(1+$BD$2),$AP11="Monthly F",12,$AP11="One-Time",0),AW11*(1+$BD$2))} -> 60000 | AY11: {=IFERROR(_xlfn.IFS(VALUE(MID(AY$5,6,1))>$D$2,0,$AP11="Annual",1,AX11=12,12,$AP11="Monthly V",AX11*(1+$D$3),$AP11="Monthly F",12,$AP11="One-Time",0),AX11*(1+$D$3))} -> 0 | AZ11: {=IFERROR(_xlfn.IFS(VALUE(MID(AZ$5,6,1))>$D$2,0,$AP11="Annual",1,AY11=12,12,$AP11="Monthly V",AY11*(1+$D$3),$AP11="Monthly F",12,$AP11="One-Time",0),AY11*(1+$D$3))} -> 0 | BA11: {=IFERROR(_xlfn.IFS(VALUE(MID(BA$5,6,2))>$D$2,0,$AP11="Annual",1,AZ11=12,12,$AP11="Monthly V",AZ11*(1+$D$3),$AP11="Monthly F",12,$AP11="One-Time",0),AZ11*(1+$D$3))} -> 0 | BB11: OnBoard Deposits | BC11: OnBoard | BD11: 0.1703 | BE11: =BF11/12 -> 851.5 | BF11: =IFERROR(AR11*$BD11,0) -> 10218 | BG11: =IFERROR(AS11*$BD11,0) -> 10218 | BH11: =IFERROR(AT11*$BD11,0) -> 10218 | BI11: =BH11*1.03 -> 10524.54 | BJ11: =BI11*1.03 -> 10840.276 | BK11: =BJ11*1.03 -> 11165.484 | BL11: =BK11*1.03 -> 11500.449 | BM11: =IFERROR(AY11*$BD11,0) -> 0 | BN11: =IFERROR(AZ11*$BD11,0) -> 0 | BO11: =IFERROR(BA11*$BD11,0) -> 0 | BQ11: =IF(VALUE(MID(BQ$5,6,1))<=$D$2,((1+$BD$3)^1-1)*BG11,0) -> 306.54 | BR11: =IF(VALUE(MID(BR$5,6,1))<=$D$2,((1+$BD$3)^2-1)*BH11,0) -> 622.2762 | BS11: =IF(VALUE(MID(BS$5,6,1))<=$D$2,((1+$BD$3)^3-1)*BI11,0) -> 975.90902 | BT11: =IF(VALUE(MID(BT$5,6,1))<=$D$2,((1+$BD$3)^4-1)*BJ11,0) -> 1360.5502 | BU11: =IF(VALUE(MID(BU$5,6,1))<=$D$2,((1+$BD$3)^5-1)*BK11,0) -> 1778.3722 | BV11: =IF(VALUE(MID(BV$5,6,1))<=$D$2,((1+$BD$3)^6-1)*BL11,0) -> 2231.6885 | BW11: =IF(VALUE(MID(BW$5,6,1))<=$D$2,((1+$BD$3)^7-1)*BM11,0) -> 0 | BX11: =IF(VALUE(MID(BX$5,6,1))<=$D$2,((1+$BD$3)^8-1)*BN11,0) -> 0 | BY11: =IF(VALUE(MID(BY$5,6,2))<=$D$2,((1+$BD$3)^9-1)*BO11,0) -> 0 | BZ11: =SUM(BP11:BY11) -> 7275.3361 | CA11: =SUM(BZ11,BF11:BO11) -> 81960.086 | CE11: =IF($CC11="Annual",1,IF($CC11="Monthly F",12,IF($CC11="Monthly V",CD11*12,IF($CC11="One-Time",1,CD11*12)))) -> 0 | CF11: {=IFERROR(_xlfn.IFS(VALUE(MID(CF$5,6,1))>$D$2,0,$CC11="Annual",1,CE11=12,12,$CC11="Monthly V",CE11*(1+$D$3),$CC11="Monthly F",12,$CC11="One-Time",0),CE11*(1+$D$3))} -> 0 | CG11: {=IFERROR(_xlfn.IFS(VALUE(MID(CG$5,6,1))>$D$2,0,$CC11="Annual",1,CF11=12,12,$CC11="Monthly V",CF11*(1+$D$3),$CC11="Monthly F",12,$CC11="One-Time",0),CF11*(1+$D$3))} -> 0 | CH11: {=IFERROR(_xlfn.IFS(VALUE(MID(CH$5,6,1))>$D$2,0,$CC11="Annual",1,CG11=12,12,$CC11="Monthly V",CG11*(1+$D$3),$CC11="Monthly F",12,$CC11="One-Time",0),CG11*(1+$D$3))} -> 0 | CI11: {=IFERROR(_xlfn.IFS(VALUE(MID(CI$5,6,1))>$D$2,0,$CC11="Annual",1,CH11=12,12,$CC11="Monthly V",CH11*(1+$D$3),$CC11="Monthly F",12,$CC11="One-Time",0),CH11*(1+$D$3))} -> 0 | CJ11: {=IFERROR(_xlfn.IFS(VALUE(MID(CJ$5,6,1))>$D$2,0,$CC11="Annual",1,CI11=12,12,$CC11="Monthly V",CI11*(1+$D$3),$CC11="Monthly F",12,$CC11="One-Time",0),CI11*(1+$D$3))} -> 0 | CK11: {=IFERROR(_xlfn.IFS(VALUE(MID(CK$5,6,1))>$D$2,0,$CC11="Annual",1,CJ11=12,12,$CC11="Monthly V",CJ11*(1+$D$3),$CC11="Monthly F",12,$CC11="One-Time",0),CJ11*(1+$D$3))} -> 0 | CL11: {=IFERROR(_xlfn.IFS(VALUE(MID(CL$5,6,1))>$D$2,0,$CC11="Annual",1,CK11=12,12,$CC11="Monthly V",CK11*(1+$D$3),$CC11="Monthly F",12,$CC11="One-Time",0),CK11*(1+$D$3))} -> 0 | CM11: {=IFERROR(_xlfn.IFS(VALUE(MID(CM$5,6,1))>$D$2,0,$CC11="Annual",1,CL11=12,12,$CC11="Monthly V",CL11*(1+$D$3),$CC11="Monthly F",12,$CC11="One-Time",0),CL11*(1+$D$3))} -> 0 | CN11: {=IFERROR(_xlfn.IFS(VALUE(MID(CN$5,6,2))>$D$2,0,$CC11="Annual",1,CM11=12,12,$CC11="Monthly V",CM11*(1+$D$3),$CC11="Monthly F",12,$CC11="One-Time",0),CM11*(1+$D$3))} -> 0 | CQ11: =CR11/12 -> 0 | CR11: =IFERROR(CE11*$CP11,0) -> 0 | CS11: =IFERROR(CF11*$CP11,0) -> 0 | CT11: =IFERROR(CG11*$CP11,0) -> 0 | CU11: =IFERROR(CH11*$CP11,0) -> 0 | CV11: =IFERROR(CI11*$CP11,0) -> 0 | CW11: =IFERROR(CJ11*$CP11,0) -> 0 | CX11: =IFERROR(CK11*$CP11,0) -> 0 | CY11: =IFERROR(CL11*$CP11,0) -> 0 | ... DA11: =IFERROR(CN11*$CP11,0) -> 0 | DC11: =IF(VALUE(MID(DC$5,6,1))<=$D$2,((1+$CP$3)^1-1)*CS11,0) -> 0 | DD11: =IF(VALUE(MID(DD$5,6,1))<=$D$2,((1+$CP$3)^2-1)*CT11,0) -> 0 | DE11: =IF(VALUE(MID(DE$5,6,1))<=$D$2,((1+$CP$3)^3-1)*CU11,0) -> 0 | DF11: =IF(VALUE(MID(DF$5,6,1))<=$D$2,((1+$CP$3)^4-1)*CV11,0) -> 0 | DG11: =IF(VALUE(MID(DG$5,6,1))<=$D$2,((1+$CP$3)^5-1)*CW11,0) -> 0 | DH11: =IF(VALUE(MID(DH$5,6,1))<=$D$2,((1+$CP$3)^6-1)*CX11,0) -> 0 | DI11: =IF(VALUE(MID(DI$5,6,1))<=$D$2,((1+$CP$3)^7-1)*CY11,0) -> 0 | DJ11: =IF(VALUE(MID(DJ$5,6,1))<=$D$2,((1+$CP$3)^8-1)*CZ11,0) -> 0 | DK11: =IF(VALUE(MID(DK$5,6,2))<=$D$2,((1+$CP$3)^9-1)*DA11,0) -> 0 | DL11: =SUM(DB11:DK11) -> 0 | DM11: =SUM(DL11,CR11:DA11) -> 0
B12: Monthly F | C12: 1 | D12: =IFERROR(AVERAGE(C12:C12),0) -> 1 | E12: 0 | F12: 0 | G12: 0 | H12: 0 | I12: 0 | J12: {=IFERROR(_xlfn.IFS(VALUE(MID(J$5,6,1))>$D$2,0,$B12="Annual",1,I12=12,12,$B12="Monthly V",I12*(1+$D$3),$B12="Monthly F",12,$B12="One-Time",0),I12*(1+$D$3))} -> 12 | K12: 0 | L12: 0 | M12: 0 | N12: 0 | O12: Year 6 CORE PROCESSING (Bundle) - CPI Increase Begins | P12: HORIZON CORE ACCOUNT PROCESSING | Q12: 35000 | R12: =S12/12 -> 0 | S12: =IFERROR($Q12*E12,0) -> 0 | T12: =IFERROR($Q12*F12,0) -> 0 | U12: =IFERROR($Q12*G12,0) -> 0 | V12: =IFERROR($Q12*H12,0) -> 0 | W12: =IFERROR($Q12*I12,0) -> 0 | X12: =IFERROR($Q12*J12,0) -> 420000 | Y12: =IFERROR($Q12*K12,0) -> 0 | Z12: =IFERROR($Q12*L12,0) -> 0 | ... AB12: =IFERROR($Q12*N12,0) -> 0 | AD12: =IF(VALUE(MID(AD$5,6,1))<=$D$2,((1+$Q$3)^1-1)*T12,0) -> 0 | AE12: =IF(VALUE(MID(AE$5,6,1))<=$D$2,((1+$Q$3)^2-1)*U12,0) -> 0 | AF12: =IF(VALUE(MID(AF$5,6,1))<=$D$2,((1+$Q$3)^3-1)*V12,0) -> 0 | AG12: =IF(VALUE(MID(AG$5,6,1))<=$D$2,((1+$Q$3)^4-1)*W12,0) -> 0 | AH12: =IF(VALUE(MID(AH$5,6,1))<=$D$2,((1+$Q$2)^1-1)*X12,0) -> 25200 | AI12: =IF(VALUE(MID(AI$5,6,1))<=$D$2,((1+$Q$3)^6-1)*Y12,0) -> 0 | AJ12: =IF(VALUE(MID(AJ$5,6,1))<=$D$2,((1+$Q$3)^7-1)*Z12,0) -> 0 | AK12: =IF(VALUE(MID(AK$5,6,1))<=$D$2,((1+$Q$3)^8-1)*AA12,0) -> 0 | AL12: =IF(VALUE(MID(AL$5,6,2))<=$D$2,((1+$Q$3)^9-1)*AB12,0) -> 0 | AM12: =SUM(AC12:AL12) -> 25200 | AN12: =SUM(AM12,S12:AB12) -> 445200 | AP12: Monthly V | AQ12: 5000 | AR12: =IF($AP12="Annual",1,IF($AP12="Monthly F",12,IF($AP12="Monthly V",AQ12*12,IF($AP12="One-Time",1,AQ12*12)))) -> 60000 | AS12: {=IFERROR(_xlfn.IFS(VALUE(MID(AS$5,6,1))>$D$2,0,$AP12="Annual",1,AR12=12,12,$AP12="Monthly V",AR12*(1+$BD$2),$AP12="Monthly F",12,$AP12="One-Time",0),AR12*(1+$BD$2))} -> 60000 | AT12: {=IFERROR(_xlfn.IFS(VALUE(MID(AT$5,6,1))>$D$2,0,$AP12="Annual",1,AS12=12,12,$AP12="Monthly V",AS12*(1+$BD$2),$AP12="Monthly F",12,$AP12="One-Time",0),AS12*(1+$BD$2))} -> 60000 | AU12: {=IFERROR(_xlfn.IFS(VALUE(MID(AU$5,6,1))>$D$2,0,$AP12="Annual",1,AT12=12,12,$AP12="Monthly V",AT12*(1+$BD$2),$AP12="Monthly F",12,$AP12="One-Time",0),AT12*(1+$BD$2))} -> 60000 | AV12: {=IFERROR(_xlfn.IFS(VALUE(MID(AV$5,6,1))>$D$2,0,$AP12="Annual",1,AU12=12,12,$AP12="Monthly V",AU12*(1+$BD$2),$AP12="Monthly F",12,$AP12="One-Time",0),AU12*(1+$BD$2))} -> 60000 | AW12: {=IFERROR(_xlfn.IFS(VALUE(MID(AW$5,6,1))>$D$2,0,$AP12="Annual",1,AV12=12,12,$AP12="Monthly V",AV12*(1+$BD$2),$AP12="Monthly F",12,$AP12="One-Time",0),AV12*(1+$BD$2))} -> 60000 | AX12: {=IFERROR(_xlfn.IFS(VALUE(MID(AX$5,6,1))>$D$2,0,$AP12="Annual",1,AW12=12,12,$AP12="Monthly V",AW12*(1+$BD$2),$AP12="Monthly F",12,$AP12="One-Time",0),AW12*(1+$BD$2))} -> 60000 | AY12: {=IFERROR(_xlfn.IFS(VALUE(MID(AY$5,6,1))>$D$2,0,$AP12="Annual",1,AX12=12,12,$AP12="Monthly V",AX12*(1+$D$3),$AP12="Monthly F",12,$AP12="One-Time",0),AX12*(1+$D$3))} -> 0 | AZ12: {=IFERROR(_xlfn.IFS(VALUE(MID(AZ$5,6,1))>$D$2,0,$AP12="Annual",1,AY12=12,12,$AP12="Monthly V",AY12*(1+$D$3),$AP12="Monthly F",12,$AP12="One-Time",0),AY12*(1+$D$3))} -> 0 | BA12: {=IFERROR(_xlfn.IFS(VALUE(MID(BA$5,6,2))>$D$2,0,$AP12="Annual",1,AZ12=12,12,$AP12="Monthly V",AZ12*(1+$D$3),$AP12="Monthly F",12,$AP12="One-Time",0),AZ12*(1+$D$3))} -> 0 | BB12: Teller Cash Recycler | BC12: Teller | BD12: 0.03 | BE12: =BF12/12 -> 150 | BF12: =IFERROR(AR12*$BD12,0) -> 1800 | BG12: =IFERROR(AS12*$BD12,0) -> 1800 | BH12: =IFERROR(AT12*$BD12,0) -> 1800 | BI12: =BH12*1.03 -> 1854 | BJ12: =BI12*1.03 -> 1909.62 | BK12: =BJ12*1.03 -> 1966.9086 | BL12: =BK12*1.03 -> 2025.9159 | BM12: =IFERROR(AY12*$BD12,0) -> 0 | BN12: =IFERROR(AZ12*$BD12,0) -> 0 | BO12: =IFERROR(BA12*$BD12,0) -> 0 | BQ12: =IF(VALUE(MID(BQ$5,6,1))<=$D$2,((1+$BD$3)^1-1)*BG12,0) -> 54 | BR12: =IF(VALUE(MID(BR$5,6,1))<=$D$2,((1+$BD$3)^2-1)*BH12,0) -> 109.62 | BS12: =IF(VALUE(MID(BS$5,6,1))<=$D$2,((1+$BD$3)^3-1)*BI12,0) -> 171.91586 | BT12: =IF(VALUE(MID(BT$5,6,1))<=$D$2,((1+$BD$3)^4-1)*BJ12,0) -> 239.67413 | BU12: =IF(VALUE(MID(BU$5,6,1))<=$D$2,((1+$BD$3)^5-1)*BK12,0) -> 313.27755 | BV12: =IF(VALUE(MID(BV$5,6,1))<=$D$2,((1+$BD$3)^6-1)*BL12,0) -> 393.13362 | BW12: =IF(VALUE(MID(BW$5,6,1))<=$D$2,((1+$BD$3)^7-1)*BM12,0) -> 0 | BX12: =IF(VALUE(MID(BX$5,6,1))<=$D$2,((1+$BD$3)^8-1)*BN12,0) -> 0 | BY12: =IF(VALUE(MID(BY$5,6,2))<=$D$2,((1+$BD$3)^9-1)*BO12,0) -> 0 | BZ12: =SUM(BP12:BY12) -> 1281.6212 | CA12: =SUM(BZ12,BF12:BO12) -> 14438.066 | CE12: =IF($CC12="Annual",1,IF($CC12="Monthly F",12,IF($CC12="Monthly V",CD12*12,IF($CC12="One-Time",1,CD12*12)))) -> 0 | CF12: {=IFERROR(_xlfn.IFS(VALUE(MID(CF$5,6,1))>$D$2,0,$CC12="Annual",1,CE12=12,12,$CC12="Monthly V",CE12*(1+$D$3),$CC12="Monthly F",12,$CC12="One-Time",0),CE12*(1+$D$3))} -> 0 | CG12: {=IFERROR(_xlfn.IFS(VALUE(MID(CG$5,6,1))>$D$2,0,$CC12="Annual",1,CF12=12,12,$CC12="Monthly V",CF12*(1+$D$3),$CC12="Monthly F",12,$CC12="One-Time",0),CF12*(1+$D$3))} -> 0 | CH12: {=IFERROR(_xlfn.IFS(VALUE(MID(CH$5,6,1))>$D$2,0,$CC12="Annual",1,CG12=12,12,$CC12="Monthly V",CG12*(1+$D$3),$CC12="Monthly F",12,$CC12="One-Time",0),CG12*(1+$D$3))} -> 0 | CI12: {=IFERROR(_xlfn.IFS(VALUE(MID(CI$5,6,1))>$D$2,0,$CC12="Annual",1,CH12=12,12,$CC12="Monthly V",CH12*(1+$D$3),$CC12="Monthly F",12,$CC12="One-Time",0),CH12*(1+$D$3))} -> 0 | CJ12: {=IFERROR(_xlfn.IFS(VALUE(MID(CJ$5,6,1))>$D$2,0,$CC12="Annual",1,CI12=12,12,$CC12="Monthly V",CI12*(1+$D$3),$CC12="Monthly F",12,$CC12="One-Time",0),CI12*(1+$D$3))} -> 0 | CK12: {=IFERROR(_xlfn.IFS(VALUE(MID(CK$5,6,1))>$D$2,0,$CC12="Annual",1,CJ12=12,12,$CC12="Monthly V",CJ12*(1+$D$3),$CC12="Monthly F",12,$CC12="One-Time",0),CJ12*(1+$D$3))} -> 0 | CL12: {=IFERROR(_xlfn.IFS(VALUE(MID(CL$5,6,1))>$D$2,0,$CC12="Annual",1,CK12=12,12,$CC12="Monthly V",CK12*(1+$D$3),$CC12="Monthly F",12,$CC12="One-Time",0),CK12*(1+$D$3))} -> 0 | CM12: {=IFERROR(_xlfn.IFS(VALUE(MID(CM$5,6,1))>$D$2,0,$CC12="Annual",1,CL12=12,12,$CC12="Monthly V",CL12*(1+$D$3),$CC12="Monthly F",12,$CC12="One-Time",0),CL12*(1+$D$3))} -> 0 | CN12: {=IFERROR(_xlfn.IFS(VALUE(MID(CN$5,6,2))>$D$2,0,$CC12="Annual",1,CM12=12,12,$CC12="Monthly V",CM12*(1+$D$3),$CC12="Monthly F",12,$CC12="One-Time",0),CM12*(1+$D$3))} -> 0 | CQ12: =CR12/12 -> 0 | CR12: =IFERROR(CE12*$CP12,0) -> 0 | CS12: =IFERROR(CF12*$CP12,0) -> 0 | CT12: =IFERROR(CG12*$CP12,0) -> 0 | CU12: =IFERROR(CH12*$CP12,0) -> 0 | CV12: =IFERROR(CI12*$CP12,0) -> 0 | CW12: =IFERROR(CJ12*$CP12,0) -> 0 | CX12: =IFERROR(CK12*$CP12,0) -> 0 | CY12: =IFERROR(CL12*$CP12,0) -> 0 | ... DA12: =IFERROR(CN12*$CP12,0) -> 0 | DC12: =IF(VALUE(MID(DC$5,6,1))<=$D$2,((1+$CP$3)^1-1)*CS12,0) -> 0 | DD12: =IF(VALUE(MID(DD$5,6,1))<=$D$2,((1+$CP$3)^2-1)*CT12,0) -> 0 | DE12: =IF(VALUE(MID(DE$5,6,1))<=$D$2,((1+$CP$3)^3-1)*CU12,0) -> 0 | DF12: =IF(VALUE(MID(DF$5,6,1))<=$D$2,((1+$CP$3)^4-1)*CV12,0) -> 0 | DG12: =IF(VALUE(MID(DG$5,6,1))<=$D$2,((1+$CP$3)^5-1)*CW12,0) -> 0 | DH12: =IF(VALUE(MID(DH$5,6,1))<=$D$2,((1+$CP$3)^6-1)*CX12,0) -> 0 | DI12: =IF(VALUE(MID(DI$5,6,1))<=$D$2,((1+$CP$3)^7-1)*CY12,0) -> 0 | DJ12: =IF(VALUE(MID(DJ$5,6,1))<=$D$2,((1+$CP$3)^8-1)*CZ12,0) -> 0 | DK12: =IF(VALUE(MID(DK$5,6,2))<=$D$2,((1+$CP$3)^9-1)*DA12,0) -> 0 | DL12: =SUM(DB12:DK12) -> 0 | DM12: =SUM(DL12,CR12:DA12) -> 0
B13: Monthly F | C13: 1 | D13: =IFERROR(AVERAGE(C13:C13),0) -> 1 | E13: 0 | F13: 0 | G13: 0 | H13: 0 | I13: 0 | J13: 0 | K13: {=IFERROR(_xlfn.IFS(VALUE(MID(K$5,6,1))>$D$2,0,$B13="Annual",1,J13=12,12,$B13="Monthly V",J13*(1+$D$3),$B13="Monthly F",12,$B13="One-Time",0),J13*(1+$D$3))} -> 12 | L13: 0 | M13: 0 | N13: 0 | O13: Year 7 CORE PROCESSING (Bundle) - CPI Increase | P13: HORIZON CORE ACCOUNT PROCESSING | Q13: =AN12/12 -> 37100 | R13: =S13/12 -> 0 | S13: =IFERROR($Q13*E13,0) -> 0 | T13: =IFERROR($Q13*F13,0) -> 0 | U13: =IFERROR($Q13*G13,0) -> 0 | V13: =IFERROR($Q13*H13,0) -> 0 | W13: =IFERROR($Q13*I13,0) -> 0 | X13: =IFERROR($Q13*J13,0) -> 0 | Y13: =IFERROR($Q13*K13,0) -> 445200 | Z13: =IFERROR($Q13*L13,0) -> 0 | ... AB13: =IFERROR($Q13*N13,0) -> 0 | AD13: =IF(VALUE(MID(AD$5,6,1))<=$D$2,((1+$Q$3)^1-1)*T13,0) -> 0 | AE13: =IF(VALUE(MID(AE$5,6,1))<=$D$2,((1+$Q$3)^2-1)*U13,0) -> 0 | AF13: =IF(VALUE(MID(AF$5,6,1))<=$D$2,((1+$Q$3)^3-1)*V13,0) -> 0 | AG13: =IF(VALUE(MID(AG$5,6,1))<=$D$2,((1+$Q$3)^4-1)*W13,0) -> 0 | AH13: =IF(VALUE(MID(AH$5,6,1))<=$D$2,((1+$Q$2)^1-1)*X13,0) -> 0 | AI13: =IF(VALUE(MID(AI$5,6,1))<=$D$2,((1+$Q$2)^1-1)*Y13,0) -> 26712 | AJ13: =IF(VALUE(MID(AJ$5,6,1))<=$D$2,((1+$Q$3)^7-1)*Z13,0) -> 0 | AK13: =IF(VALUE(MID(AK$5,6,1))<=$D$2,((1+$Q$3)^8-1)*AA13,0) -> 0 | AL13: =IF(VALUE(MID(AL$5,6,2))<=$D$2,((1+$Q$3)^9-1)*AB13,0) -> 0 | AM13: =SUM(AC13:AL13) -> 26712 | AN13: =SUM(AM13,S13:AB13) -> 471912 | AP13: Monthly V | AQ13: 5000 | AR13: =IF($AP13="Annual",1,IF($AP13="Monthly F",12,IF($AP13="Monthly V",AQ13*12,IF($AP13="One-Time",1,AQ13*12)))) -> 60000 | AS13: {=IFERROR(_xlfn.IFS(VALUE(MID(AS$5,6,1))>$D$2,0,$AP13="Annual",1,AR13=12,12,$AP13="Monthly V",AR13*(1+$BD$2),$AP13="Monthly F",12,$AP13="One-Time",0),AR13*(1+$BD$2))} -> 60000 | AT13: {=IFERROR(_xlfn.IFS(VALUE(MID(AT$5,6,1))>$D$2,0,$AP13="Annual",1,AS13=12,12,$AP13="Monthly V",AS13*(1+$BD$2),$AP13="Monthly F",12,$AP13="One-Time",0),AS13*(1+$BD$2))} -> 60000 | AU13: {=IFERROR(_xlfn.IFS(VALUE(MID(AU$5,6,1))>$D$2,0,$AP13="Annual",1,AT13=12,12,$AP13="Monthly V",AT13*(1+$BD$2),$AP13="Monthly F",12,$AP13="One-Time",0),AT13*(1+$BD$2))} -> 60000 | AV13: {=IFERROR(_xlfn.IFS(VALUE(MID(AV$5,6,1))>$D$2,0,$AP13="Annual",1,AU13=12,12,$AP13="Monthly V",AU13*(1+$BD$2),$AP13="Monthly F",12,$AP13="One-Time",0),AU13*(1+$BD$2))} -> 60000 | AW13: {=IFERROR(_xlfn.IFS(VALUE(MID(AW$5,6,1))>$D$2,0,$AP13="Annual",1,AV13=12,12,$AP13="Monthly V",AV13*(1+$BD$2),$AP13="Monthly F",12,$AP13="One-Time",0),AV13*(1+$BD$2))} -> 60000 | AX13: {=IFERROR(_xlfn.IFS(VALUE(MID(AX$5,6,1))>$D$2,0,$AP13="Annual",1,AW13=12,12,$AP13="Monthly V",AW13*(1+$BD$2),$AP13="Monthly F",12,$AP13="One-Time",0),AW13*(1+$BD$2))} -> 60000 | AY13: {=IFERROR(_xlfn.IFS(VALUE(MID(AY$5,6,1))>$D$2,0,$AP13="Annual",1,AX13=12,12,$AP13="Monthly V",AX13*(1+$D$3),$AP13="Monthly F",12,$AP13="One-Time",0),AX13*(1+$D$3))} -> 0 | AZ13: {=IFERROR(_xlfn.IFS(VALUE(MID(AZ$5,6,1))>$D$2,0,$AP13="Annual",1,AY13=12,12,$AP13="Monthly V",AY13*(1+$D$3),$AP13="Monthly F",12,$AP13="One-Time",0),AY13*(1+$D$3))} -> 0 | BA13: {=IFERROR(_xlfn.IFS(VALUE(MID(BA$5,6,2))>$D$2,0,$AP13="Annual",1,AZ13=12,12,$AP13="Monthly V",AZ13*(1+$D$3),$AP13="Monthly F",12,$AP13="One-Time",0),AZ13*(1+$D$3))} -> 0 | BB13: Teller CheckMaster Plus | BC13: Teller | BD13: 0.0135 | BE13: =BF13/12 -> 67.5 | BF13: =IFERROR(AR13*$BD13,0) -> 810 | BG13: =IFERROR(AS13*$BD13,0) -> 810 | BH13: =IFERROR(AT13*$BD13,0) -> 810 | BI13: =BH13*1.03 -> 834.3 | BJ13: =BI13*1.03 -> 859.329 | BK13: =BJ13*1.03 -> 885.10887 | BL13: =BK13*1.03 -> 911.66214 | BM13: =IFERROR(AY13*$BD13,0) -> 0 | BN13: =IFERROR(AZ13*$BD13,0) -> 0 | BO13: =IFERROR(BA13*$BD13,0) -> 0 | BQ13: =IF(VALUE(MID(BQ$5,6,1))<=$D$2,((1+$BD$3)^1-1)*BG13,0) -> 24.3 | BR13: =IF(VALUE(MID(BR$5,6,1))<=$D$2,((1+$BD$3)^2-1)*BH13,0) -> 49.329 | BS13: =IF(VALUE(MID(BS$5,6,1))<=$D$2,((1+$BD$3)^3-1)*BI13,0) -> 77.362136 | BT13: =IF(VALUE(MID(BT$5,6,1))<=$D$2,((1+$BD$3)^4-1)*BJ13,0) -> 107.85336 | BU13: =IF(VALUE(MID(BU$5,6,1))<=$D$2,((1+$BD$3)^5-1)*BK13,0) -> 140.9749 | BV13: =IF(VALUE(MID(BV$5,6,1))<=$D$2,((1+$BD$3)^6-1)*BL13,0) -> 176.91013 | BW13: =IF(VALUE(MID(BW$5,6,1))<=$D$2,((1+$BD$3)^7-1)*BM13,0) -> 0 | BX13: =IF(VALUE(MID(BX$5,6,1))<=$D$2,((1+$BD$3)^8-1)*BN13,0) -> 0 | BY13: =IF(VALUE(MID(BY$5,6,2))<=$D$2,((1+$BD$3)^9-1)*BO13,0) -> 0 | BZ13: =SUM(BP13:BY13) -> 576.72952 | CA13: =SUM(BZ13,BF13:BO13) -> 6497.1295 | CE13: =IF($CC13="Annual",1,IF($CC13="Monthly F",12,IF($CC13="Monthly V",CD13*12,IF($CC13="One-Time",1,CD13*12)))) -> 0 | CF13: {=IFERROR(_xlfn.IFS(VALUE(MID(CF$5,6,1))>$D$2,0,$CC13="Annual",1,CE13=12,12,$CC13="Monthly V",CE13*(1+$D$3),$CC13="Monthly F",12,$CC13="One-Time",0),CE13*(1+$D$3))} -> 0 | CG13: {=IFERROR(_xlfn.IFS(VALUE(MID(CG$5,6,1))>$D$2,0,$CC13="Annual",1,CF13=12,12,$CC13="Monthly V",CF13*(1+$D$3),$CC13="Monthly F",12,$CC13="One-Time",0),CF13*(1+$D$3))} -> 0 | CH13: {=IFERROR(_xlfn.IFS(VALUE(MID(CH$5,6,1))>$D$2,0,$CC13="Annual",1,CG13=12,12,$CC13="Monthly V",CG13*(1+$D$3),$CC13="Monthly F",12,$CC13="One-Time",0),CG13*(1+$D$3))} -> 0 | CI13: {=IFERROR(_xlfn.IFS(VALUE(MID(CI$5,6,1))>$D$2,0,$CC13="Annual",1,CH13=12,12,$CC13="Monthly V",CH13*(1+$D$3),$CC13="Monthly F",12,$CC13="One-Time",0),CH13*(1+$D$3))} -> 0 | CJ13: {=IFERROR(_xlfn.IFS(VALUE(MID(CJ$5,6,1))>$D$2,0,$CC13="Annual",1,CI13=12,12,$CC13="Monthly V",CI13*(1+$D$3),$CC13="Monthly F",12,$CC13="One-Time",0),CI13*(1+$D$3))} -> 0 | CK13: {=IFERROR(_xlfn.IFS(VALUE(MID(CK$5,6,1))>$D$2,0,$CC13="Annual",1,CJ13=12,12,$CC13="Monthly V",CJ13*(1+$D$3),$CC13="Monthly F",12,$CC13="One-Time",0),CJ13*(1+$D$3))} -> 0 | CL13: {=IFERROR(_xlfn.IFS(VALUE(MID(CL$5,6,1))>$D$2,0,$CC13="Annual",1,CK13=12,12,$CC13="Monthly V",CK13*(1+$D$3),$CC13="Monthly F",12,$CC13="One-Time",0),CK13*(1+$D$3))} -> 0 | CM13: {=IFERROR(_xlfn.IFS(VALUE(MID(CM$5,6,1))>$D$2,0,$CC13="Annual",1,CL13=12,12,$CC13="Monthly V",CL13*(1+$D$3),$CC13="Monthly F",12,$CC13="One-Time",0),CL13*(1+$D$3))} -> 0 | CN13: {=IFERROR(_xlfn.IFS(VALUE(MID(CN$5,6,2))>$D$2,0,$CC13="Annual",1,CM13=12,12,$CC13="Monthly V",CM13*(1+$D$3),$CC13="Monthly F",12,$CC13="One-Time",0),CM13*(1+$D$3))} -> 0 | CQ13: =CR13/12 -> 0 | CR13: =IFERROR(CE13*$CP13,0) -> 0 | CS13: =IFERROR(CF13*$CP13,0) -> 0 | CT13: =IFERROR(CG13*$CP13,0) -> 0 | CU13: =IFERROR(CH13*$CP13,0) -> 0 | CV13: =IFERROR(CI13*$CP13,0) -> 0 | CW13: =IFERROR(CJ13*$CP13,0) -> 0 | CX13: =IFERROR(CK13*$CP13,0) -> 0 | CY13: =IFERROR(CL13*$CP13,0) -> 0 | ... DA13: =IFERROR(CN13*$CP13,0) -> 0 | DC13: =IF(VALUE(MID(DC$5,6,1))<=$D$2,((1+$CP$3)^1-1)*CS13,0) -> 0 | DD13: =IF(VALUE(MID(DD$5,6,1))<=$D$2,((1+$CP$3)^2-1)*CT13,0) -> 0 | DE13: =IF(VALUE(MID(DE$5,6,1))<=$D$2,((1+$CP$3)^3-1)*CU13,0) -> 0 | DF13: =IF(VALUE(MID(DF$5,6,1))<=$D$2,((1+$CP$3)^4-1)*CV13,0) -> 0 | DG13: =IF(VALUE(MID(DG$5,6,1))<=$D$2,((1+$CP$3)^5-1)*CW13,0) -> 0 | DH13: =IF(VALUE(MID(DH$5,6,1))<=$D$2,((1+$CP$3)^6-1)*CX13,0) -> 0 | DI13: =IF(VALUE(MID(DI$5,6,1))<=$D$2,((1+$CP$3)^7-1)*CY13,0) -> 0 | DJ13: =IF(VALUE(MID(DJ$5,6,1))<=$D$2,((1+$CP$3)^8-1)*CZ13,0) -> 0 | DK13: =IF(VALUE(MID(DK$5,6,2))<=$D$2,((1+$CP$3)^9-1)*DA13,0) -> 0 | DL13: =SUM(DB13:DK13) -> 0 | DM13: =SUM(DL13,CR13:DA13) -> 0
D14: =IFERROR(AVERAGE(C14:C14),0) -> 0 | E14: =IF($B14="Annual",1,IF($B14="Monthly F",12,IF($B14="Monthly V",D14*12,IF($B14="One-Time",1,D14*12)))) -> 0 | F14: {=IFERROR(_xlfn.IFS(VALUE(MID(F$5,6,1))>$D$2,0,$B14="Annual",1,E14=12,12,$B14="Monthly V",E14*(1+$D$3),$B14="Monthly F",12,$B14="One-Time",0),E14*(1+$D$3))} -> 0 | G14: {=IFERROR(_xlfn.IFS(VALUE(MID(G$5,6,1))>$D$2,0,$B14="Annual",1,F14=12,12,$B14="Monthly V",F14*(1+$D$3),$B14="Monthly F",12,$B14="One-Time",0),F14*(1+$D$3))} -> 0 | H14: {=IFERROR(_xlfn.IFS(VALUE(MID(H$5,6,1))>$D$2,0,$B14="Annual",1,G14=12,12,$B14="Monthly V",G14*(1+$D$3),$B14="Monthly F",12,$B14="One-Time",0),G14*(1+$D$3))} -> 0 | I14: {=IFERROR(_xlfn.IFS(VALUE(MID(I$5,6,1))>$D$2,0,$B14="Annual",1,H14=12,12,$B14="Monthly V",H14*(1+$D$3),$B14="Monthly F",12,$B14="One-Time",0),H14*(1+$D$3))} -> 0 | J14: {=IFERROR(_xlfn.IFS(VALUE(MID(J$5,6,1))>$D$2,0,$B14="Annual",1,I14=12,12,$B14="Monthly V",I14*(1+$D$3),$B14="Monthly F",12,$B14="One-Time",0),I14*(1+$D$3))} -> 0 | K14: {=IFERROR(_xlfn.IFS(VALUE(MID(K$5,6,1))>$D$2,0,$B14="Annual",1,J14=12,12,$B14="Monthly V",J14*(1+$D$3),$B14="Monthly F",12,$B14="One-Time",0),J14*(1+$D$3))} -> 0 | L14: {=IFERROR(_xlfn.IFS(VALUE(MID(L$5,6,1))>$D$2,0,$B14="Annual",1,K14=12,12,$B14="Monthly V",K14*(1+$D$3),$B14="Monthly F",12,$B14="One-Time",0),K14*(1+$D$3))} -> 0 | M14: {=IFERROR(_xlfn.IFS(VALUE(MID(M$5,6,1))>$D$2,0,$B14="Annual",1,L14=12,12,$B14="Monthly V",L14*(1+$D$3),$B14="Monthly F",12,$B14="One-Time",0),L14*(1+$D$3))} -> 0 | N14: {=IFERROR(_xlfn.IFS(VALUE(MID(N$5,6,2))>$D$2,0,$B14="Annual",1,M14=12,12,$B14="Monthly V",M14*(1+$D$3),$B14="Monthly F",12,$B14="One-Time",0),M14*(1+$D$3))} -> 0 | R14: =S14/12 -> 0 | S14: =IFERROR($Q14*E14,0) -> 0 | T14: =IFERROR($Q14*F14,0) -> 0 | U14: =IFERROR($Q14*G14,0) -> 0 | V14: =IFERROR($Q14*H14,0) -> 0 | W14: =IFERROR($Q14*I14,0) -> 0 | X14: =IFERROR($Q14*J14,0) -> 0 | Y14: =IFERROR($Q14*K14,0) -> 0 | Z14: =IFERROR($Q14*L14,0) -> 0 | ... AB14: =IFERROR($Q14*N14,0) -> 0 | AD14: =IF(VALUE(MID(AD$5,6,1))<=$D$2,((1+$Q$3)^1-1)*T14,0) -> 0 | AE14: =IF(VALUE(MID(AE$5,6,1))<=$D$2,((1+$Q$3)^2-1)*U14,0) -> 0 | AF14: =IF(VALUE(MID(AF$5,6,1))<=$D$2,((1+$Q$3)^3-1)*V14,0) -> 0 | AG14: =IF(VALUE(MID(AG$5,6,1))<=$D$2,((1+$Q$3)^4-1)*W14,0) -> 0 | AH14: =IF(VALUE(MID(AH$5,6,1))<=$D$2,((1+$Q$3)^5-1)*X14,0) -> 0 | AI14: =IF(VALUE(MID(AI$5,6,1))<=$D$2,((1+$Q$3)^6-1)*Y14,0) -> 0 | AJ14: =IF(VALUE(MID(AJ$5,6,1))<=$D$2,((1+$Q$3)^7-1)*Z14,0) -> 0 | AK14: =IF(VALUE(MID(AK$5,6,1))<=$D$2,((1+$Q$3)^8-1)*AA14,0) -> 0 | AL14: =IF(VALUE(MID(AL$5,6,2))<=$D$2,((1+$Q$3)^9-1)*AB14,0) -> 0 | AM14: =SUM(AC14:AL14) -> 0 | AN14: =SUM(AM14,S14:AB14) -> 0 | AP14: Monthly V | AQ14: 5000 | AR14: =IF($AP14="Annual",1,IF($AP14="Monthly F",12,IF($AP14="Monthly V",AQ14*12,IF($AP14="One-Time",1,AQ14*12)))) -> 60000 | AS14: {=IFERROR(_xlfn.IFS(VALUE(MID(AS$5,6,1))>$D$2,0,$AP14="Annual",1,AR14=12,12,$AP14="Monthly V",AR14*(1+$BD$2),$AP14="Monthly F",12,$AP14="One-Time",0),AR14*(1+$BD$2))} -> 60000 | AT14: {=IFERROR(_xlfn.IFS(VALUE(MID(AT$5,6,1))>$D$2,0,$AP14="Annual",1,AS14=12,12,$AP14="Monthly V",AS14*(1+$BD$2),$AP14="Monthly F",12,$AP14="One-Time",0),AS14*(1+$BD$2))} -> 60000 | AU14: {=IFERROR(_xlfn.IFS(VALUE(MID(AU$5,6,1))>$D$2,0,$AP14="Annual",1,AT14=12,12,$AP14="Monthly V",AT14*(1+$BD$2),$AP14="Monthly F",12,$AP14="One-Time",0),AT14*(1+$BD$2))} -> 60000 | AV14: {=IFERROR(_xlfn.IFS(VALUE(MID(AV$5,6,1))>$D$2,0,$AP14="Annual",1,AU14=12,12,$AP14="Monthly V",AU14*(1+$BD$2),$AP14="Monthly F",12,$AP14="One-Time",0),AU14*(1+$BD$2))} -> 60000 | AW14: {=IFERROR(_xlfn.IFS(VALUE(MID(AW$5,6,1))>$D$2,0,$AP14="Annual",1,AV14=12,12,$AP14="Monthly V",AV14*(1+$BD$2),$AP14="Monthly F",12,$AP14="One-Time",0),AV14*(1+$BD$2))} -> 60000 | AX14: {=IFERROR(_xlfn.IFS(VALUE(MID(AX$5,6,1))>$D$2,0,$AP14="Annual",1,AW14=12,12,$AP14="Monthly V",AW14*(1+$BD$2),$AP14="Monthly F",12,$AP14="One-Time",0),AW14*(1+$BD$2))} -> 60000 | AY14: {=IFERROR(_xlfn.IFS(VALUE(MID(AY$5,6,1))>$D$2,0,$AP14="Annual",1,AX14=12,12,$AP14="Monthly V",AX14*(1+$D$3),$AP14="Monthly F",12,$AP14="One-Time",0),AX14*(1+$D$3))} -> 0 | AZ14: {=IFERROR(_xlfn.IFS(VALUE(MID(AZ$5,6,1))>$D$2,0,$AP14="Annual",1,AY14=12,12,$AP14="Monthly V",AY14*(1+$D$3),$AP14="Monthly F",12,$AP14="One-Time",0),AY14*(1+$D$3))} -> 0 | BA14: {=IFERROR(_xlfn.IFS(VALUE(MID(BA$5,6,2))>$D$2,0,$AP14="Annual",1,AZ14=12,12,$AP14="Monthly V",AZ14*(1+$D$3),$AP14="Monthly F",12,$AP14="One-Time",0),AZ14*(1+$D$3))} -> 0 | BB14: Synapsys CRM | BC14: Synapsys | BD14: 0.1643 | BE14: =BF14/12 -> 821.5 | BF14: =IFERROR(AR14*$BD14,0) -> 9858 | BG14: =IFERROR(AS14*$BD14,0) -> 9858 | BH14: =IFERROR(AT14*$BD14,0) -> 9858 | BI14: =BH14*1.03 -> 10153.74 | BJ14: =BI14*1.03 -> 10458.352 | BK14: =BJ14*1.03 -> 10772.103 | BL14: =BK14*1.03 -> 11095.266 | BM14: =IFERROR(AY14*$BD14,0) -> 0 | BN14: =IFERROR(AZ14*$BD14,0) -> 0 | BO14: =IFERROR(BA14*$BD14,0) -> 0 | BQ14: =IF(VALUE(MID(BQ$5,6,1))<=$D$2,((1+$BD$3)^1-1)*BG14,0) -> 295.74 | BR14: =IF(VALUE(MID(BR$5,6,1))<=$D$2,((1+$BD$3)^2-1)*BH14,0) -> 600.3522 | BS14: =IF(VALUE(MID(BS$5,6,1))<=$D$2,((1+$BD$3)^3-1)*BI14,0) -> 941.52585 | BT14: =IF(VALUE(MID(BT$5,6,1))<=$D$2,((1+$BD$3)^4-1)*BJ14,0) -> 1312.6153 | BU14: =IF(VALUE(MID(BU$5,6,1))<=$D$2,((1+$BD$3)^5-1)*BK14,0) -> 1715.7167 | BV14: =IF(VALUE(MID(BV$5,6,1))<=$D$2,((1+$BD$3)^6-1)*BL14,0) -> 2153.0618 | BW14: =IF(VALUE(MID(BW$5,6,1))<=$D$2,((1+$BD$3)^7-1)*BM14,0) -> 0 | BX14: =IF(VALUE(MID(BX$5,6,1))<=$D$2,((1+$BD$3)^8-1)*BN14,0) -> 0 | BY14: =IF(VALUE(MID(BY$5,6,2))<=$D$2,((1+$BD$3)^9-1)*BO14,0) -> 0 | BZ14: =SUM(BP14:BY14) -> 7019.0119 | CA14: =SUM(BZ14,BF14:BO14) -> 79072.473 | CE14: =IF($CC14="Annual",1,IF($CC14="Monthly F",12,IF($CC14="Monthly V",CD14*12,IF($CC14="One-Time",1,CD14*12)))) -> 0 | CF14: {=IFERROR(_xlfn.IFS(VALUE(MID(CF$5,6,1))>$D$2,0,$CC14="Annual",1,CE14=12,12,$CC14="Monthly V",CE14*(1+$D$3),$CC14="Monthly F",12,$CC14="One-Time",0),CE14*(1+$D$3))} -> 0 | CG14: {=IFERROR(_xlfn.IFS(VALUE(MID(CG$5,6,1))>$D$2,0,$CC14="Annual",1,CF14=12,12,$CC14="Monthly V",CF14*(1+$D$3),$CC14="Monthly F",12,$CC14="One-Time",0),CF14*(1+$D$3))} -> 0 | CH14: {=IFERROR(_xlfn.IFS(VALUE(MID(CH$5,6,1))>$D$2,0,$CC14="Annual",1,CG14=12,12,$CC14="Monthly V",CG14*(1+$D$3),$CC14="Monthly F",12,$CC14="One-Time",0),CG14*(1+$D$3))} -> 0 | CI14: {=IFERROR(_xlfn.IFS(VALUE(MID(CI$5,6,1))>$D$2,0,$CC14="Annual",1,CH14=12,12,$CC14="Monthly V",CH14*(1+$D$3),$CC14="Monthly F",12,$CC14="One-Time",0),CH14*(1+$D$3))} -> 0 | CJ14: {=IFERROR(_xlfn.IFS(VALUE(MID(CJ$5,6,1))>$D$2,0,$CC14="Annual",1,CI14=12,12,$CC14="Monthly V",CI14*(1+$D$3),$CC14="Monthly F",12,$CC14="One-Time",0),CI14*(1+$D$3))} -> 0 | CK14: {=IFERROR(_xlfn.IFS(VALUE(MID(CK$5,6,1))>$D$2,0,$CC14="Annual",1,CJ14=12,12,$CC14="Monthly V",CJ14*(1+$D$3),$CC14="Monthly F",12,$CC14="One-Time",0),CJ14*(1+$D$3))} -> 0 | CL14: {=IFERROR(_xlfn.IFS(VALUE(MID(CL$5,6,1))>$D$2,0,$CC14="Annual",1,CK14=12,12,$CC14="Monthly V",CK14*(1+$D$3),$CC14="Monthly F",12,$CC14="One-Time",0),CK14*(1+$D$3))} -> 0 | CM14: {=IFERROR(_xlfn.IFS(VALUE(MID(CM$5,6,1))>$D$2,0,$CC14="Annual",1,CL14=12,12,$CC14="Monthly V",CL14*(1+$D$3),$CC14="Monthly F",12,$CC14="One-Time",0),CL14*(1+$D$3))} -> 0 | CN14: {=IFERROR(_xlfn.IFS(VALUE(MID(CN$5,6,2))>$D$2,0,$CC14="Annual",1,CM14=12,12,$CC14="Monthly V",CM14*(1+$D$3),$CC14="Monthly F",12,$CC14="One-Time",0),CM14*(1+$D$3))} -> 0 | CQ14: =CR14/12 -> 0 | CR14: =IFERROR(CE14*$CP14,0) -> 0 | CS14: =IFERROR(CF14*$CP14,0) -> 0 | CT14: =IFERROR(CG14*$CP14,0) -> 0 | CU14: =IFERROR(CH14*$CP14,0) -> 0 | CV14: =IFERROR(CI14*$CP14,0) -> 0 | CW14: =IFERROR(CJ14*$CP14,0) -> 0 | CX14: =IFERROR(CK14*$CP14,0) -> 0 | CY14: =IFERROR(CL14*$CP14,0) -> 0 | ... DA14: =IFERROR(CN14*$CP14,0) -> 0 | DC14: =IF(VALUE(MID(DC$5,6,1))<=$D$2,((1+$CP$3)^1-1)*CS14,0) -> 0 | DD14: =IF(VALUE(MID(DD$5,6,1))<=$D$2,((1+$CP$3)^2-1)*CT14,0) -> 0 | DE14: =IF(VALUE(MID(DE$5,6,1))<=$D$2,((1+$CP$3)^3-1)*CU14,0) -> 0 | DF14: =IF(VALUE(MID(DF$5,6,1))<=$D$2,((1+$CP$3)^4-1)*CV14,0) -> 0 | DG14: =IF(VALUE(MID(DG$5,6,1))<=$D$2,((1+$CP$3)^5-1)*CW14,0) -> 0 | DH14: =IF(VALUE(MID(DH$5,6,1))<=$D$2,((1+$CP$3)^6-1)*CX14,0) -> 0 | DI14: =IF(VALUE(MID(DI$5,6,1))<=$D$2,((1+$CP$3)^7-1)*CY14,0) -> 0 | DJ14: =IF(VALUE(MID(DJ$5,6,1))<=$D$2,((1+$CP$3)^8-1)*CZ14,0) -> 0 | DK14: =IF(VALUE(MID(DK$5,6,2))<=$D$2,((1+$CP$3)^9-1)*DA14,0) -> 0 | DL14: =SUM(DB14:DK14) -> 0 | DM14: =SUM(DL14,CR14:DA14) -> 0
