Workbook
Name ChgType: SF_Output!$L1048566:$L988
Name Delivery: SF_Output!$O1048566:$O988
Name Description: SF_Output!$M1048566:$M988
Name Disc: SF_Output!$T1048566:$T988
Name extid: SF_Output!$J1048566:$J988
Name Freq: SF_Output!$Q1048566:$Q988
Name List: SF_Output!$S1048566:$S988
Name OType: SF_Output!$N1048566:$N988

Sheet SF_Output
A1: Agreement: Last Activity Date | B1: Account | C1: Based On Assets | D1: Agreement: Owner Name | E1: Sales Support Owner | F1: PAP Val | G1: Optional PAP Val | H1: Agreement: Agreement Name | I1: Master Category Text | J1: Product External ID | K1: Product Family | L1: Charge Type | M1: Line Description | N1: Order Type | O1: Delivery | P1: Optional Product | Q1: Pricing Frequency | R1: Quantity | S1: Deal Sheet Base price for Override | T1: Deal Sheet Discount Amount | U1: JH Company ID | V1: Base Price (Override) | W1: Base Price | X1: PLI APTS ID | Y1: Based on Number of Open Accounts | Z1: Calculated List PAP | AA1: Sort1 | AB1: Sort2
A2: 45895 | B2: Echelon Bank (InOrg) | C2: 0 | D2: Christopher Darty | E2: Diane Jackson | F2: 0 | G2: 0 | H2: Clearwater, FL - Echelon Bank (InOrg) - New Core SilverLake OL PAP | I2: IS and Risk | J2: CTBK00039 | K2: Centurion | L2: Professional Service | M2: Centurion Remote Data Entry | N2: New | O2: Hosted by JHA | P2: 0 | Q2: Yearly | R2: 1 | S2: 1880 | T2: 0 | U2: 116592 | W2: 1880 | X2: a4p0R0000002bLDQAY | Y2: 5000 | Z2: =ROUND(IF((F2+G2)=0,0,S2/Y2),4) -> 0 | AA2: {=IFERROR(INDEX(H_Tables!E:E,MATCH(INDIRECT("I"&ROW()),H_Tables!F:F,0)),"")} -> 7 | AB2: {=IFERROR(INDEX(H_Tables!H:H,MATCH(INDIRECT("k"&ROW()),H_Tables!I:I,0)),"")} -> 1 | AC2: =_xlfn.TEXTJOIN(",",TRUE,M2:P2) -> Centurion Remote Data Entry,New,Hosted by JHA,0 | AD2: 1
A3: 45895 | B3: Echelon Bank (InOrg) | C3: 0 | D3: Christopher Darty | E3: Diane Jackson | F3: 0 | G3: 0 | H3: Clearwater, FL - Echelon Bank (InOrg) - New Core SilverLake OL PAP | I3: IS and Risk | J3: CTCT00101 | K3: Centurion | L3: Professional Service | M3: Centurion Connectivity for Jack Henry Hosted Services | N3: New | O3: Hosted by JHA | P3: 0 | Q3: Monthly | R3: 1 | S3: 200 | T3: 0 | U3: 116592 | W3: 200 | X3: a4pWB0000000DmrYAE | Y3: 5000 | Z3: =ROUND(IF((F3+G3)=0,0,S3/Y3),4) -> 0 | AA3: {=IFERROR(INDEX(H_Tables!E:E,MATCH(INDIRECT("I"&ROW()),H_Tables!F:F,0)),"")} -> 7 | AB3: {=IFERROR(INDEX(H_Tables!H:H,MATCH(INDIRECT("k"&ROW()),H_Tables!I:I,0)),"")} -> 1 | AC3: =_xlfn.TEXTJOIN(",",TRUE,M3:P3) -> Centurion Connectivity for Jack Henry Hosted Services,New,Hosted by JHA,0 | AD3: 2
A4: 45895 | B4: Echelon Bank (InOrg) | C4: 0 | D4: Christopher Darty | E4: Diane Jackson | F4: 0 | G4: 0 | H4: Clearwater, FL - Echelon Bank (InOrg) - New Core SilverLake OL PAP | I4: Payments | J4: IPNA00416 | K4: iPay | L4: Processing Service | M4: iPay Business BillPay Banno | N4: New | O4: Hosted by JHA | P4: 0 | Q4: Monthly | R4: 1 | S4: 400 | T4: 0 | U4: 116592 | W4: 400 | X4: a4g2a000000HBB5AAO | Y4: 5000 | Z4: =ROUND(IF((F4+G4)=0,0,S4/Y4),4) -> 0 | AA4: {=IFERROR(INDEX(H_Tables!E:E,MATCH(INDIRECT("I"&ROW()),H_Tables!F:F,0)),"")} -> 6 | AB4: {=IFERROR(INDEX(H_Tables!H:H,MATCH(INDIRECT("k"&ROW()),H_Tables!I:I,0)),"")} -> 3 | AC4: =_xlfn.TEXTJOIN(",",TRUE,M4:P4) -> iPay Business BillPay Banno,New,Hosted by JHA,0 | AD4: 3
A5: 45895 | B5: Echelon Bank (InOrg) | C5: 0 | D5: Christopher Darty | E5: Diane Jackson | F5: 0 | G5: 0 | H5: Clearwater, FL - Echelon Bank (InOrg) - New Core SilverLake OL PAP | I5: Payments | J5: IPNA00416 | K5: iPay | L5: Professional Service | M5: iPay Business BillPay Banno | N5: New | O5: Hosted by JHA | P5: 0 | Q5: One Time | R5: 1 | S5: 2500 | T5: -2500 | U5: 116592 | W5: 2500 | X5: a4g2a000000HA36AAG | Y5: 5000 | Z5: =ROUND(IF((F5+G5)=0,0,S5/Y5),4) -> 0 | AA5: {=IFERROR(INDEX(H_Tables!E:E,MATCH(INDIRECT("I"&ROW()),H_Tables!F:F,0)),"")} -> 6 | AB5: {=IFERROR(INDEX(H_Tables!H:H,MATCH(INDIRECT("k"&ROW()),H_Tables!I:I,0)),"")} -> 3 | AC5: =_xlfn.TEXTJOIN(",",TRUE,M5:P5) -> iPay Business BillPay Banno,New,Hosted by JHA,0 | AD5: 4
A6: 45895 | B6: Echelon Bank (InOrg) | C6: 0 | D6: Christopher Darty | E6: Diane Jackson | F6: 0 | G6: 0 | H6: Clearwater, FL - Echelon Bank (InOrg) - New Core SilverLake OL PAP | I6: Payments | J6: IPNA00415 | K6: iPay | L6: Processing Service | M6: iPay Electronic Bill Payment Annual Compliance Package Banno | N6: New | O6: Hosted by JHA | P6: 0 | Q6: Yearly | R6: 1 | S6: 630 | T6: 0 | U6: 116592 | V6: 630 | W6: 595 | X6: a4g2a000000HAPvAAO | Y6: 5000 | Z6: =ROUND(IF((F6+G6)=0,0,S6/Y6),4) -> 0 | AA6: {=IFERROR(INDEX(H_Tables!E:E,MATCH(INDIRECT("I"&ROW()),H_Tables!F:F,0)),"")} -> 6 | AB6: {=IFERROR(INDEX(H_Tables!H:H,MATCH(INDIRECT("k"&ROW()),H_Tables!I:I,0)),"")} -> 3 | AC6: =_xlfn.TEXTJOIN(",",TRUE,M6:P6) -> iPay Electronic Bill Payment Annual Compliance Package Banno,New,Hosted by JHA,0 | AD6: 5
A7: 45895 | B7: Echelon Bank (InOrg) | C7: 0 | D7: Christopher Darty | E7: Diane Jackson | F7: 0 | G7: 0 | H7: Clearwater, FL - Echelon Bank (InOrg) - New Core SilverLake OL PAP | I7: Payments | J7: IPNA00414 | K7: iPay | L7: Processing Service | M7: iPay eBill Detail | N7: New | O7: Hosted by JHA | P7: 0 | Q7: Monthly | R7: 1 | S7: 0 | T7: 0 | U7: 116592 | W7: 0 | X7: a4p3J0000013SezQAE | Y7: 5000 | Z7: =ROUND(IF((F7+G7)=0,0,S7/Y7),4) -> 0 | AA7: {=IFERROR(INDEX(H_Tables!E:E,MATCH(INDIRECT("I"&ROW()),H_Tables!F:F,0)),"")} -> 6 | AB7: {=IFERROR(INDEX(H_Tables!H:H,MATCH(INDIRECT("k"&ROW()),H_Tables!I:I,0)),"")} -> 3 | AC7: =_xlfn.TEXTJOIN(",",TRUE,M7:P7) -> iPay eBill Detail,New,Hosted by JHA,0 | AD7: 6
A8: 45895 | B8: Echelon Bank (InOrg) | C8: 0 | D8: Christopher Darty | E8: Diane Jackson | F8: 0 | G8: 0 | H8: Clearwater, FL - Echelon Bank (InOrg) - New Core SilverLake OL PAP | I8: Payments | J8: PYRZ00102 | K8: iPay | L8: Professional Service | M8: Payrailz/iPay Integration | N8: New | O8: Hosted by JHA | P8: 0 | Q8: One Time | R8: 1 | S8: 5000 | T8: -5000 | U8: 116592 | W8: 5000 | X8: a4p04000000DiGjAAK | Y8: 5000 | Z8: =ROUND(IF((F8+G8)=0,0,S8/Y8),4) -> 0 | AA8: {=IFERROR(INDEX(H_Tables!E:E,MATCH(INDIRECT("I"&ROW()),H_Tables!F:F,0)),"")} -> 6 | AB8: {=IFERROR(INDEX(H_Tables!H:H,MATCH(INDIRECT("k"&ROW()),H_Tables!I:I,0)),"")} -> 3 | AC8: =_xlfn.TEXTJOIN(",",TRUE,M8:P8) -> Payrailz/iPay Integration,New,Hosted by JHA,0 | AD8: 7
A9: 45895 | B9: Echelon Bank (InOrg) | C9: 0 | D9: Christopher Darty | E9: Diane Jackson | F9: 1.2181 | G9: 0 | H9: Clearwater, FL - Echelon Bank (InOrg) - New Core SilverLake OL PAP | I9: Core | J9: SLAKE00199 | K9: SilverLake | L9: Processing Service | M9: SilverLake System Bundle | N9: New | O9: Hosted by JHA | P9: 0 | Q9: Monthly | R9: 5000 | S9: 6921.15 | T9: -830.54 | U9: 116592 | W9: 1.38423 | X9: a4pWB0000008VmcYAE | Y9: 5000 | Z9: =ROUND(IF((F9+G9)=0,0,S9/Y9),4) -> 1.3842 | AA9: {=IFERROR(INDEX(H_Tables!E:E,MATCH(INDIRECT("I"&ROW()),H_Tables!F:F,0)),"")} -> 1 | AB9: {=IFERROR(INDEX(H_Tables!H:H,MATCH(INDIRECT("k"&ROW()),H_Tables!I:I,0)),"")} -> 1 | AC9: =_xlfn.TEXTJOIN(",",TRUE,M9:P9) -> SilverLake System Bundle,New,Hosted by JHA,0 | AD9: 8
A10: 45895 | B10: Echelon Bank (InOrg) | C10: 0 | D10: Christopher Darty | E10: Diane Jackson | F10: 0 | G10: 0 | H10: Clearwater, FL - Echelon Bank (InOrg) - New Core SilverLake OL PAP | I10: Core | J10: SLAKE00199 | K10: SilverLake | L10: Professional Service | M10: SilverLake System Bundle | N10: New | O10: Hosted by JHA | P10: 0 | Q10: One Time | R10: 1 | S10: 78700 | T10: -78700 | U10: 116592 | W10: 78700 | X10: a4pWB0000008VmbYAE | Y10: 5000 | Z10: =ROUND(IF((F10+G10)=0,0,S10/Y10),4) -> 0 | AA10: {=IFERROR(INDEX(H_Tables!E:E,MATCH(INDIRECT("I"&ROW()),H_Tables!F:F,0)),"")} -> 1 | AB10: {=IFERROR(INDEX(H_Tables!H:H,MATCH(INDIRECT("k"&ROW()),H_Tables!I:I,0)),"")} -> 1 | AC10: =_xlfn.TEXTJOIN(",",TRUE,M10:P10) -> SilverLake System Bundle,New,Hosted by JHA,0 | AD10: 9
A11: 45895 | B11: Echelon Bank (InOrg) | C11: 0 | D11: Christopher Darty | E11: Diane Jackson | F11: 0 | G11: 0 | H11: Clearwater, FL - Echelon Bank (InOrg) - New Core SilverLake OL PAP | I11: Core | J11: SLTC00100 | K11: SilverLake | L11: Professional Service | M11: SilverLake Technical Conversion/Installation | N11: New | O11: Hosted by JHA | P11: 0 | Q11: One Time | R11: 1 | S11: 125405 | T11: -125405 | U11: 116592 | W11: 125405 | X11: a4pWB000000CHWXYA4 | Y11: 5000 | Z11: =ROUND(IF((F11+G11)=0,0,S11/Y11),4) -> 0 | AA11: {=IFERROR(INDEX(H_Tables!E:E,MATCH(INDIRECT("I"&ROW()),H_Tables!F:F,0)),"")} -> 1 | AB11: {=IFERROR(INDEX(H_Tables!H:H,MATCH(INDIRECT("k"&ROW()),H_Tables!I:I,0)),"")} -> 1 | AC11: =_xlfn.TEXTJOIN(",",TRUE,M11:P11) -> SilverLake Technical Conversion/Installation,New,Hosted by JHA,0 | AD11: 10
A12: 45895 | B12: Echelon Bank (InOrg) | C12: 0 | D12: Christopher Darty | E12: Diane Jackson | F12: 0 | G12: 0 | H12: Clearwater, FL - Echelon Bank (InOrg) - New Core SilverLake OL PAP | I12: Training | J12: OLTF000117 | K12: SilverLake | L12: Professional Service | M12: Core Implementation Training | N12: New | O12: Hosted by JHA | P12: 0 | Q12: One Time | R12: 1 | S12: 30000 | T12: 0 | U12: 116592 | W12: 30000 | X12: a4p18000000GqnfAAC | Y12: 5000 | Z12: =ROUND(IF((F12+G12)=0,0,S12/Y12),4) -> 0 | AA12: {=IFERROR(INDEX(H_Tables!E:E,MATCH(INDIRECT("I"&ROW()),H_Tables!F:F,0)),"")} -> 9 | AB12: {=IFERROR(INDEX(H_Tables!H:H,MATCH(INDIRECT("k"&ROW()),H_Tables!I:I,0)),"")} -> 1 | AC12: =_xlfn.TEXTJOIN(",",TRUE,M12:P12) -> Core Implementation Training,New,Hosted by JHA,0 | AD12: 11
A13: 45895 | B13: Echelon Bank (InOrg) | C13: 0 | D13: Christopher Darty | E13: Diane Jackson | F13: 0 | G13: 0 | H13: Clearwater, FL - Echelon Bank (InOrg) - New Core SilverLake OL PAP | I13: Core | J13: CCORE00109 | K13: SilverLake | L13: Processing Service | M13: Closed Accounts (PAP) | N13: New | O13: Hosted by JHA | P13: 0 | Q13: Monthly | R13: 1 | S13: 0.25 | T13: 0 | U13: 116592 | W13: 0.25 | X13: a4p7h000000QZkzAAG | Y13: 5000 | Z13: =ROUND(IF((F13+G13)=0,0,S13/Y13),4) -> 0 | AA13: {=IFERROR(INDEX(H_Tables!E:E,MATCH(INDIRECT("I"&ROW()),H_Tables!F:F,0)),"")} -> 1 | AB13: {=IFERROR(INDEX(H_Tables!H:H,MATCH(INDIRECT("k"&ROW()),H_Tables!I:I,0)),"")} -> 1 | AC13: =_xlfn.TEXTJOIN(",",TRUE,M13:P13) -> Closed Accounts (PAP),New,Hosted by JHA,0 | AD13: 12
A14: 45895 | B14: Echelon Bank (InOrg) | C14: 0 | D14: Christopher Darty | E14: Diane Jackson | F14: 0 | G14: 0 | H14: Clearwater, FL - Echelon Bank (InOrg) - New Core SilverLake OL PAP | I14: Training | J14: OLTF000102 | K14: SilverLake | L14: Professional Service | M14: User and Device Administration Training | N14: New | O14: Hosted by JHA | P14: 0 | Q14: One Time | R14: 1 | S14: 5000 | T14: 0 | U14: 116592 | W14: 5000 | X14: a4p18000000GqlhAAC | Y14: 5000 | Z14: =ROUND(IF((F14+G14)=0,0,S14/Y14),4) -> 0 | AA14: {=IFERROR(INDEX(H_Tables!E:E,MATCH(INDIRECT("I"&ROW()),H_Tables!F:F,0)),"")} -> 9 | AB14: {=IFERROR(INDEX(H_Tables!H:H,MATCH(INDIRECT("k"&ROW()),H_Tables!I:I,0)),"")} -> 1 | AC14: =_xlfn.TEXTJOIN(",",TRUE,M14:P14) -> User and Device Administration Training,New,Hosted by JHA,0 | AD14: 13
A15: 45895 | B15: Echelon Bank (InOrg) | C15: 0 | D15: Christopher Darty | E15: Diane Jackson | F15: 0 | G15: 0 | H15: Clearwater, FL - Echelon Bank (InOrg) - New Core SilverLake OL PAP | I15: Core | J15: SLAKE000102 | K15: SilverLake | L15: Processing Service | M15: SilverLake Static Training Bank | N15: New | O15: Hosted by JHA | P15: 1 | Q15: Monthly | R15: 1 | S15: 530 | T15: -132.5 | U15: 116592 | W15: 530 | X15: a4p18000000GqkKAAS | Y15: 5000 | Z15: =ROUND(IF((F15+G15)=0,0,S15/Y15),4) -> 0 | AA15: {=IFERROR(INDEX(H_Tables!E:E,MATCH(INDIRECT("I"&ROW()),H_Tables!F:F,0)),"")} -> 1 | AB15: {=IFERROR(INDEX(H_Tables!H:H,MATCH(INDIRECT("k"&ROW()),H_Tables!I:I,0)),"")} -> 1 | AC15: =_xlfn.TEXTJOIN(",",TRUE,M15:P15) -> SilverLake Static Training Bank,New,Hosted by JHA,1 | AD15: 14
A16: 45895 | B16: Echelon Bank (InOrg) | C16: 0 | D16: Christopher Darty | E16: Diane Jackson | F16: 0 | G16: 0 | H16: Clearwater, FL - Echelon Bank (InOrg) - New Core SilverLake OL PAP | I16: Core | J16: SLAKE000102 | K16: SilverLake | L16: Professional Service | M16: SilverLake Static Training Bank | N16: New | O16: Hosted by JHA | P16: 1 | Q16: One Time | R16: 1 | S16: 6000 | T16: -6000 | U16: 116592 | W16: 6000 | X16: a4p18000000GqkPAAS | Y16: 5000 | Z16: =ROUND(IF((F16+G16)=0,0,S16/Y16),4) -> 0 | AA16: {=IFERROR(INDEX(H_Tables!E:E,MATCH(INDIRECT("I"&ROW()),H_Tables!F:F,0)),"")} -> 1 | AB16: {=IFERROR(INDEX(H_Tables!H:H,MATCH(INDIRECT("k"&ROW()),H_Tables!I:I,0)),"")} -> 1 | AC16: =_xlfn.TEXTJOIN(",",TRUE,M16:P16) -> SilverLake Static Training Bank,New,Hosted by JHA,1 | AD16: 15
A17: 45895 | B17: Echelon Bank (InOrg) | C17: 0 | D17: Christopher Darty | E17: Diane Jackson | F17: 0 | G17: 0 | H17: Clearwater, FL - Echelon Bank (InOrg) - New Core SilverLake OL PAP | I17: Retail | J17: STCT1001 | K17: SilverLake | L17: Processing Service | M17: Platform Static Training Bank | N17: New | O17: Hosted by JHA | P17: 1 | Q17: Monthly | R17: 1 | S17: 110 | T17: -27.5 | U17: 116592 | W17: 110 | X17: a4p0R000000AhCgQAK | Y17: 5000 | Z17: =ROUND(IF((F17+G17)=0,0,S17/Y17),4) -> 0 | AA17: {=IFERROR(INDEX(H_Tables!E:E,MATCH(INDIRECT("I"&ROW()),H_Tables!F:F,0)),"")} -> 2 | AB17: {=IFERROR(INDEX(H_Tables!H:H,MATCH(INDIRECT("k"&ROW()),H_Tables!I:I,0)),"")} -> 1 | AC17: =_xlfn.TEXTJOIN(",",TRUE,M17:P17) -> Platform Static Training Bank,New,Hosted by JHA,1 | AD17: 16
A18: 45895 | B18: Echelon Bank (InOrg) | C18: 0 | D18: Christopher Darty | E18: Diane Jackson | F18: 0 | G18: 0 | H18: Clearwater, FL - Echelon Bank (InOrg) - New Core SilverLake OL PAP | I18: Retail | J18: STCT1001 | K18: SilverLake | L18: Professional Service | M18: Platform Static Training Bank | N18: New | O18: Hosted by JHA | P18: 1 | Q18: One Time | R18: 1 | S18: 2500 | T18: -2500 | U18: 116592 | W18: 2500 | X18: a4p0R000000AhCbQAK | Y18: 5000 | Z18: =ROUND(IF((F18+G18)=0,0,S18/Y18),4) -> 0 | AA18: {=IFERROR(INDEX(H_Tables!E:E,MATCH(INDIRECT("I"&ROW()),H_Tables!F:F,0)),"")} -> 2 | AB18: {=IFERROR(INDEX(H_Tables!H:H,MATCH(INDIRECT("k"&ROW()),H_Tables!I:I,0)),"")} -> 1 | AC18: =_xlfn.TEXTJOIN(",",TRUE,M18:P18) -> Platform Static Training Bank,New,Hosted by JHA,1 | AD18: 17
... A163: 45895 | B163: Echelon Bank (InOrg) | C163: 0 | D163: Christopher Darty | E163: Diane Jackson | F163: 0 | G163: 0 | H163: Clearwater, FL - Echelon Bank (InOrg) - New Core SilverLake OL PAP | I163: Payments | J163: CPS000101 | K163: Card Processing Solutions (CPS) | L163: Professional Service | M163: JHA Debit Processing | N163: New | O163: Hosted by 3rd Party | P163: 0 | Q163: One Time | R163: 1 | S163: 12500 | T163: -12500 | U163: 116592 | W163: 12500 | X163: a4p18000000GxnuAAC | Y163: 5000 | Z163: =ROUND(IF((F163+G163)=0,0,S163/Y163),4) -> 0 | AA163: {=IFERROR(INDEX(H_Tables!E:E,MATCH(INDIRECT("I"&ROW()),H_Tables!F:F,0)),"")} -> 6 | AB163: {=IFERROR(INDEX(H_Tables!H:H,MATCH(INDIRECT("k"&ROW()),H_Tables!I:I,0)),"")} -> 1 | AC163: =_xlfn.TEXTJOIN(",",TRUE,M163:P163) -> JHA Debit Processing,New,Hosted by 3rd Party,0 | AD163: 160
A164: 45895 | B164: Echelon Bank (InOrg) | C164: 0 | D164: Christopher Darty | E164: Diane Jackson | F164: 0 | G164: 0 | H164: Clearwater, FL - Echelon Bank (InOrg) - New Core SilverLake OL PAP | I164: Payments | J164: CPS000104 | K164: Card Processing Solutions (CPS) | L164: Processing Service | M164: Debit Card Authorization subject to {$}250 minimum monthly | N164: New | O164: Hosted by 3rd Party | P164: 0 | Q164: Monthly | R164: 1 | S164: 250 | T164: 0 | U164: 116592 | V164: 250 | W164: 500 | X164: a3g4a000000WCwzAAG | Y164: 5000 | Z164: =ROUND(IF((F164+G164)=0,0,S164/Y164),4) -> 0 | AA164: {=IFERROR(INDEX(H_Tables!E:E,MATCH(INDIRECT("I"&ROW()),H_Tables!F:F,0)),"")} -> 6 | AB164: {=IFERROR(INDEX(H_Tables!H:H,MATCH(INDIRECT("k"&ROW()),H_Tables!I:I,0)),"")} -> 1 | AC164: =_xlfn.TEXTJOIN(",",TRUE,M164:P164) -> Debit Card Authorization subject to {$}250 minimum monthly,New,Hosted by 3rd Party,0 | AD164: 161
A165: 45895 | B165: Echelon Bank (InOrg) | C165: 0 | D165: Christopher Darty | E165: Diane Jackson | F165: 0 | G165: 0 | H165: Clearwater, FL - Echelon Bank (InOrg) - New Core SilverLake OL PAP | I165: Payments | J165: CPS000105 | K165: Card Processing Solutions (CPS) | L165: Processing Service | M165: Debit Card Settlement | N165: New | O165: Hosted by 3rd Party | P165: 0 | Q165: Monthly | R165: 0 | S165: 0 | T165: 0 | U165: 116592 | W165: 0.02 | X165: a4p18000000GxoiAAC | Y165: 5000 | Z165: =ROUND(IF((F165+G165)=0,0,S165/Y165),4) -> 0 | AA165: {=IFERROR(INDEX(H_Tables!E:E,MATCH(INDIRECT("I"&ROW()),H_Tables!F:F,0)),"")} -> 6 | AB165: {=IFERROR(INDEX(H_Tables!H:H,MATCH(INDIRECT("k"&ROW()),H_Tables!I:I,0)),"")} -> 1 | AC165: =_xlfn.TEXTJOIN(",",TRUE,M165:P165) -> Debit Card Settlement,New,Hosted by 3rd Party,0 | AD165: 162
A166: 45895 | B166: Echelon Bank (InOrg) | C166: 0 | D166: Christopher Darty | E166: Diane Jackson | F166: 0 | G166: 0 | H166: Clearwater, FL - Echelon Bank (InOrg) - New Core SilverLake OL PAP | I166: Payments | J166: CPS000106 | K166: Card Processing Solutions (CPS) | L166: Processing Service | M166: ATM/Debit Cards | N166: New | O166: Hosted by 3rd Party | P166: 0 | Q166: Monthly | R166: 0 | S166: 0 | T166: 0 | U166: 116592 | W166: 0.025 | X166: a4p18000000GxosAAC | Y166: 5000 | Z166: =ROUND(IF((F166+G166)=0,0,S166/Y166),4) -> 0 | AA166: {=IFERROR(INDEX(H_Tables!E:E,MATCH(INDIRECT("I"&ROW()),H_Tables!F:F,0)),"")} -> 6 | AB166: {=IFERROR(INDEX(H_Tables!H:H,MATCH(INDIRECT("k"&ROW()),H_Tables!I:I,0)),"")} -> 1 | AC166: =_xlfn.TEXTJOIN(",",TRUE,M166:P166) -> ATM/Debit Cards,New,Hosted by 3rd Party,0 | AD166: 163
A167: 45895 | B167: Echelon Bank (InOrg) | C167: 0 | D167: Christopher Darty | E167: Diane Jackson | F167: 0 | G167: 0 | H167: Clearwater, FL - Echelon Bank (InOrg) - New Core SilverLake OL PAP | I167: Payments | J167: CPS000200 | K167: Card Processing Solutions (CPS) | L167: Processing Service | M167: Administrative Fee | N167: New | O167: Hosted by 3rd Party | P167: 0 | Q167: Monthly | R167: 0 | S167: 0 | T167: 0 | U167: 116592 | W167: 0.015 | X167: a4p0R0000002bOqQAI | Y167: 5000 | Z167: =ROUND(IF((F167+G167)=0,0,S167/Y167),4) -> 0 | AA167: {=IFERROR(INDEX(H_Tables!E:E,MATCH(INDIRECT("I"&ROW()),H_Tables!F:F,0)),"")} -> 6 | AB167: {=IFERROR(INDEX(H_Tables!H:H,MATCH(INDIRECT("k"&ROW()),H_Tables!I:I,0)),"")} -> 1 | AC167: =_xlfn.TEXTJOIN(",",TRUE,M167:P167) -> Administrative Fee,New,Hosted by 3rd Party,0 | AD167: 164
A168: 45895 | B168: Echelon Bank (InOrg) | C168: 0 | D168: Christopher Darty | E168: Diane Jackson | F168: 0 | G168: 0 | H168: Clearwater, FL - Echelon Bank (InOrg) - New Core SilverLake OL PAP | I168: Payments | J168: CPS000109 | K168: Card Processing Solutions (CPS) | L168: Processing Service | M168: EMV Chip Card Authorization | N168: New | O168: Hosted by 3rd Party | P168: 0 | Q168: Monthly | R168: 0 | S168: 0 | T168: 0 | U168: 116592 | W168: 0.0075 | X168: a4p18000000GxpCAAS | Y168: 5000 | Z168: =ROUND(IF((F168+G168)=0,0,S168/Y168),4) -> 0 | AA168: {=IFERROR(INDEX(H_Tables!E:E,MATCH(INDIRECT("I"&ROW()),H_Tables!F:F,0)),"")} -> 6 | AB168: {=IFERROR(INDEX(H_Tables!H:H,MATCH(INDIRECT("k"&ROW()),H_Tables!I:I,0)),"")} -> 1 | AC168: =_xlfn.TEXTJOIN(",",TRUE,M168:P168) -> EMV Chip Card Authorization,New,Hosted by 3rd Party,0 | AD168: 165
A169: 45895 | B169: Echelon Bank (InOrg) | C169: 0 | D169: Christopher Darty | E169: Diane Jackson | F169: 0 | G169: 0 | H169: Clearwater, FL - Echelon Bank (InOrg) - New Core SilverLake OL PAP | I169: Payments | J169: CPS000930 | K169: Card Processing Solutions (CPS) | L169: Processing Service | M169: Authorization Track One Name Edit | N169: New | O169: Hosted by 3rd Party | P169: 0 | Q169: Monthly | R169: 0 | S169: 0 | T169: 0 | U169: 116592 | W169: 0.004 | X169: a4p2F0000006TvBQAU | Y169: 5000 | Z169: =ROUND(IF((F169+G169)=0,0,S169/Y169),4) -> 0 | AA169: {=IFERROR(INDEX(H_Tables!E:E,MATCH(INDIRECT("I"&ROW()),H_Tables!F:F,0)),"")} -> 6 | AB169: {=IFERROR(INDEX(H_Tables!H:H,MATCH(INDIRECT("k"&ROW()),H_Tables!I:I,0)),"")} -> 1 | AC169: =_xlfn.TEXTJOIN(",",TRUE,M169:P169) -> Authorization Track One Name Edit,New,Hosted by 3rd Party,0 | AD169: 166
A170: 45895 | B170: Echelon Bank (InOrg) | C170: 0 | D170: Christopher Darty | E170: Diane Jackson | F170: 0 | G170: 0 | H170: Clearwater, FL - Echelon Bank (InOrg) - New Core SilverLake OL PAP | I170: Payments | J170: CPS000190 | K170: Card Processing Solutions (CPS) | L170: Processing Service | M170: JHA ATM/POS Processing | N170: New | O170: Hosted by 3rd Party | P170: 0 | Q170: Monthly | R170: 1 | S170: 500 | T170: 0 | U170: 116592 | W170: 500 | X170: a4p0R0000002bP0QAI | Y170: 5000 | Z170: =ROUND(IF((F170+G170)=0,0,S170/Y170),4) -> 0 | AA170: {=IFERROR(INDEX(H_Tables!E:E,MATCH(INDIRECT("I"&ROW()),H_Tables!F:F,0)),"")} -> 6 | AB170: {=IFERROR(INDEX(H_Tables!H:H,MATCH(INDIRECT("k"&ROW()),H_Tables!I:I,0)),"")} -> 1 | AC170: =_xlfn.TEXTJOIN(",",TRUE,M170:P170) -> JHA ATM/POS Processing,New,Hosted by 3rd Party,0 | AD170: 167
A171: 45895 | B171: Echelon Bank (InOrg) | C171: 0 | D171: Christopher Darty | E171: Diane Jackson | F171: 0 | G171: 0 | H171: Clearwater, FL - Echelon Bank (InOrg) - New Core SilverLake OL PAP | I171: Payments | J171: CPS000190 | K171: Card Processing Solutions (CPS) | L171: Professional Service | M171: JHA ATM/POS Processing | N171: New | O171: Hosted by 3rd Party | P171: 0 | Q171: One Time | R171: 1 | S171: 3000 | T171: -3000 | U171: 116592 | W171: 3000 | X171: a4p0R0000002bOvQAI | Y171: 5000 | Z171: =ROUND(IF((F171+G171)=0,0,S171/Y171),4) -> 0 | AA171: {=IFERROR(INDEX(H_Tables!E:E,MATCH(INDIRECT("I"&ROW()),H_Tables!F:F,0)),"")} -> 6 | AB171: {=IFERROR(INDEX(H_Tables!H:H,MATCH(INDIRECT("k"&ROW()),H_Tables!I:I,0)),"")} -> 1 | AC171: =_xlfn.TEXTJOIN(",",TRUE,M171:P171) -> JHA ATM/POS Processing,New,Hosted by 3rd Party,0 | AD171: 168
A172: 45895 | B172: Echelon Bank (InOrg) | C172: 0 | D172: Christopher Darty | E172: Diane Jackson | F172: 0 | G172: 0 | H172: Clearwater, FL - Echelon Bank (InOrg) - New Core SilverLake OL PAP | I172: Payments | J172: CPS000103 | K172: Card Processing Solutions (CPS) | L172: Processing Service | M172: ATM/POS Transactions subject to {$}250 minimum monthly | N172: New | O172: Hosted by 3rd Party | P172: 0 | Q172: Monthly | R172: 1 | S172: 250 | T172: 0 | U172: 116592 | V172: 250 | W172: 500 | X172: a3g4a000000TCwzAAG | Y172: 5000 | Z172: =ROUND(IF((F172+G172)=0,0,S172/Y172),4) -> 0 | AA172: {=IFERROR(INDEX(H_Tables!E:E,MATCH(INDIRECT("I"&ROW()),H_Tables!F:F,0)),"")} -> 6 | AB172: {=IFERROR(INDEX(H_Tables!H:H,MATCH(INDIRECT("k"&ROW()),H_Tables!I:I,0)),"")} -> 1 | AC172: =_xlfn.TEXTJOIN(",",TRUE,M172:P172) -> ATM/POS Transactions subject to {$}250 minimum monthly,New,Hosted by 3rd Party,0 | AD172: 169
A173: 45895 | B173: Echelon Bank (InOrg) | C173: 0 | D173: Christopher Darty | E173: Diane Jackson | F173: 0 | G173: 0 | H173: Clearwater, FL - Echelon Bank (InOrg) - New Core SilverLake OL PAP | I173: Payments | J173: CPS000110 | K173: Card Processing Solutions (CPS) | L173: Processing Service | M173: ATM Transactions (on-us at-us) | N173: New | O173: Hosted by 3rd Party | P173: 0 | Q173: Monthly | R173: 0 | S173: 0 | T173: 0 | U173: 116592 | W173: 0.02 | X173: a4p18000000GxpWAAS | Y173: 5000 | Z173: =ROUND(IF((F173+G173)=0,0,S173/Y173),4) -> 0 | AA173: {=IFERROR(INDEX(H_Tables!E:E,MATCH(INDIRECT("I"&ROW()),H_Tables!F:F,0)),"")} -> 6 | AB173: {=IFERROR(INDEX(H_Tables!H:H,MATCH(INDIRECT("k"&ROW()),H_Tables!I:I,0)),"")} -> 1 | AC173: =_xlfn.TEXTJOIN(",",TRUE,M173:P173) -> ATM Transactions (on-us at-us),New,Hosted by 3rd Party,0 | AD173: 170
A174: 45895 | B174: Echelon Bank (InOrg) | C174: 0 | D174: Christopher Darty | E174: Diane Jackson | F174: 0 | G174: 0 | H174: Clearwater, FL - Echelon Bank (InOrg) - New Core SilverLake OL PAP | I174: Payments | J174: CPS000115 | K174: Card Processing Solutions (CPS) | L174: Professional Service | M174: ATM Setup | N174: New | O174: Hosted by 3rd Party | P174: 0 | Q174: One Time | R174: 1 | S174: 145 | T174: -145 | U174: 116592 | W174: 145 | X174: a4p18000000GxqFAAS | Y174: 5000 | Z174: =ROUND(IF((F174+G174)=0,0,S174/Y174),4) -> 0 | AA174: {=IFERROR(INDEX(H_Tables!E:E,MATCH(INDIRECT("I"&ROW()),H_Tables!F:F,0)),"")} -> 6 | AB174: {=IFERROR(INDEX(H_Tables!H:H,MATCH(INDIRECT("k"&ROW()),H_Tables!I:I,0)),"")} -> 1 | AC174: =_xlfn.TEXTJOIN(",",TRUE,M174:P174) -> ATM Setup,New,Hosted by 3rd Party,0 | AD174: 171
A175: 45895 | B175: Echelon Bank (InOrg) | C175: 0 | D175: Christopher Darty | E175: Diane Jackson | F175: 0 | G175: 0 | H175: Clearwater, FL - Echelon Bank (InOrg) - New Core SilverLake OL PAP | I175: Payments | J175: CPS000114 | K175: Card Processing Solutions (CPS) | L175: Processing Service | M175: ATM Driving VPN | N175: New | O175: Hosted by 3rd Party | P175: 0 | Q175: Monthly | R175: 1 | S175: 100 | T175: 0 | U175: 116592 | W175: 100 | X175: a4p18000000Gxq5AAC | Y175: 5000 | Z175: =ROUND(IF((F175+G175)=0,0,S175/Y175),4) -> 0 | AA175: {=IFERROR(INDEX(H_Tables!E:E,MATCH(INDIRECT("I"&ROW()),H_Tables!F:F,0)),"")} -> 6 | AB175: {=IFERROR(INDEX(H_Tables!H:H,MATCH(INDIRECT("k"&ROW()),H_Tables!I:I,0)),"")} -> 1 | AC175: =_xlfn.TEXTJOIN(",",TRUE,M175:P175) -> ATM Driving VPN,New,Hosted by 3rd Party,0 | AD175: 172
A176: 45895 | B176: Echelon Bank (InOrg) | C176: 0 | D176: Christopher Darty | E176: Diane Jackson | F176: 0 | G176: 0 | H176: Clearwater, FL - Echelon Bank (InOrg) - New Core SilverLake OL PAP | I176: Payments | J176: CPS000270 | K176: Card Processing Solutions (CPS) | L176: Processing Service | M176: Regional ATM/Debit Network | N176: New | O176: Hosted by 3rd Party | P176: 0 | Q176: Monthly | R176: 1 | S176: 75 | T176: 0 | U176: 116592 | W176: 75 | X176: a4p0R000000Cxg3QAC | Y176: 5000 | Z176: =ROUND(IF((F176+G176)=0,0,S176/Y176),4) -> 0 | AA176: {=IFERROR(INDEX(H_Tables!E:E,MATCH(INDIRECT("I"&ROW()),H_Tables!F:F,0)),"")} -> 6 | AB176: {=IFERROR(INDEX(H_Tables!H:H,MATCH(INDIRECT("k"&ROW()),H_Tables!I:I,0)),"")} -> 1 | AC176: =_xlfn.TEXTJOIN(",",TRUE,M176:P176) -> Regional ATM/Debit Network,New,Hosted by 3rd Party,0 | AD176: 173
A177: 45895 | B177: Echelon Bank (InOrg) | C177: 0 | D177: Christopher Darty | E177: Diane Jackson | F177: 0 | G177: 0 | H177: Clearwater, FL - Echelon Bank (InOrg) - New Core SilverLake OL PAP | I177: Payments | J177: CPS000270 | K177: Card Processing Solutions (CPS) | L177: Professional Service | M177: Regional ATM/Debit Network | N177: New | O177: Hosted by 3rd Party | P177: 0 | Q177: One Time | R177: 1 | S177: 500 | T177: -500 | U177: 116592 | W177: 500 | X177: a4p0R000000CxfyQAC | Y177: 5000 | Z177: =ROUND(IF((F177+G177)=0,0,S177/Y177),4) -> 0 | AA177: {=IFERROR(INDEX(H_Tables!E:E,MATCH(INDIRECT("I"&ROW()),H_Tables!F:F,0)),"")} -> 6 | AB177: {=IFERROR(INDEX(H_Tables!H:H,MATCH(INDIRECT("k"&ROW()),H_Tables!I:I,0)),"")} -> 1 | AC177: =_xlfn.TEXTJOIN(",",TRUE,M177:P177) -> Regional ATM/Debit Network,New,Hosted by 3rd Party,0 | AD177: 174
A178: 45895 | B178: Echelon Bank (InOrg) | C178: 0 | D178: Christopher Darty | E178: Diane Jackson | F178: 0 | G178: 0 | H178: Clearwater, FL - Echelon Bank (InOrg) - New Core SilverLake OL PAP | I178: Payments | J178: CPS000280 | K178: Card Processing Solutions (CPS) | L178: Processing Service | M178: National ATM/Debit Network | N178: New | O178: Hosted by 3rd Party | P178: 0 | Q178: Monthly | R178: 3 | S178: 225 | T178: 0 | U178: 116592 | W178: 75 | X178: a4p0R000000CxgDQAS | Y178: 5000 | Z178: =ROUND(IF((F178+G178)=0,0,S178/Y178),4) -> 0 | AA178: {=IFERROR(INDEX(H_Tables!E:E,MATCH(INDIRECT("I"&ROW()),H_Tables!F:F,0)),"")} -> 6 | AB178: {=IFERROR(INDEX(H_Tables!H:H,MATCH(INDIRECT("k"&ROW()),H_Tables!I:I,0)),"")} -> 1 | AC178: =_xlfn.TEXTJOIN(",",TRUE,M178:P178) -> National ATM/Debit Network,New,Hosted by 3rd Party,0 | AD178: 175
A179: 45895 | B179: Echelon Bank (InOrg) | C179: 0 | D179: Christopher Darty | E179: Diane Jackson | F179: 0 | G179: 0 | H179: Clearwater, FL - Echelon Bank (InOrg) - New Core SilverLake OL PAP | I179: Payments | J179: CPS000280 | K179: Card Processing Solutions (CPS) | L179: Professional Service | M179: National ATM/Debit Network | N179: New | O179: Hosted by 3rd Party | P179: 0 | Q179: One Time | R179: 3 | S179: 1500 | T179: -1500 | U179: 116592 | W179: 500 | X179: a4p0R000000Cxg8QAC | Y179: 5000 | Z179: =ROUND(IF((F179+G179)=0,0,S179/Y179),4) -> 0 | AA179: {=IFERROR(INDEX(H_Tables!E:E,MATCH(INDIRECT("I"&ROW()),H_Tables!F:F,0)),"")} -> 6 | AB179: {=IFERROR(INDEX(H_Tables!H:H,MATCH(INDIRECT("k"&ROW()),H_Tables!I:I,0)),"")} -> 1 | AC179: =_xlfn.TEXTJOIN(",",TRUE,M179:P179) -> National ATM/Debit Network,New,Hosted by 3rd Party,0 | AD179: 176
A180: 45895 | B180: Echelon Bank (InOrg) | C180: 0 | D180: Christopher Darty | E180: Diane Jackson | F180: 0 | G180: 0 | H180: Clearwater, FL - Echelon Bank (InOrg) - New Core SilverLake OL PAP | I180: Payments | J180: CPS000550 | K180: Card Processing Solutions (CPS) | L180: Processing Service | M180: VISA/MasterCard Account Update (Items Needing Review) | N180: New | O180: Hosted by 3rd Party | P180: 0 | Q180: Monthly | R180: 0 | S180: 0 | T180: 0 | U180: 116592 | W180: 0.0008 | X180: a4p0R000000AqN1QAK | Y180: 5000 | Z180: =ROUND(IF((F180+G180)=0,0,S180/Y180),4) -> 0 | AA180: {=IFERROR(INDEX(H_Tables!E:E,MATCH(INDIRECT("I"&ROW()),H_Tables!F:F,0)),"")} -> 6 | AB180: {=IFERROR(INDEX(H_Tables!H:H,MATCH(INDIRECT("k"&ROW()),H_Tables!I:I,0)),"")} -> 1 | AC180: =_xlfn.TEXTJOIN(",",TRUE,M180:P180) -> VISA/MasterCard Account Update (Items Needing Review),New,Hosted by 3rd Party,0 | AD180: 177
A181: 45895 | B181: Echelon Bank (InOrg) | C181: 0 | D181: Christopher Darty | E181: Diane Jackson | F181: 0 | G181: 0 | H181: Clearwater, FL - Echelon Bank (InOrg) - New Core SilverLake OL PAP | I181: Payments | J181: CPS000550 | K181: Card Processing Solutions (CPS) | L181: Professional Service | M181: VISA/MasterCard Account Update (Items Needing Review) | N181: New | O181: Hosted by 3rd Party | P181: 0 | Q181: One Time | R181: 0 | S181: 200 | T181: -200 | U181: 116592 | W181: 200 | X181: a4p0R000000AqMwQAK | Y181: 5000 | Z181: =ROUND(IF((F181+G181)=0,0,S181/Y181),4) -> 0 | AA181: {=IFERROR(INDEX(H_Tables!E:E,MATCH(INDIRECT("I"&ROW()),H_Tables!F:F,0)),"")} -> 6 | AB181: {=IFERROR(INDEX(H_Tables!H:H,MATCH(INDIRECT("k"&ROW()),H_Tables!I:I,0)),"")} -> 1 | AC181: =_xlfn.TEXTJOIN(",",TRUE,M181:P181) -> VISA/MasterCard Account Update (Items Needing Review),New,Hosted by 3rd Party,0 | AD181: 178
A182: 45895 | B182: Echelon Bank (InOrg) | C182: 0 | D182: Christopher Darty | E182: Diane Jackson | F182: 0 | G182: 0 | H182: Clearwater, FL - Echelon Bank (InOrg) - New Core SilverLake OL PAP | I182: Payments | J182: CPS000552 | K182: Card Processing Solutions (CPS) | L182: Processing Service | M182: VISA/MasterCard Add/Change/Delete | N182: New | O182: Hosted by 3rd Party | P182: 0 | Q182: Monthly | R182: 0 | S182: 0 | T182: 0 | U182: 116592 | W182: 0.04 | X182: 112020a2PLI000020 | Y182: 5000 | Z182: =ROUND(IF((F182+G182)=0,0,S182/Y182),4) -> 0 | AA182: {=IFERROR(INDEX(H_Tables!E:E,MATCH(INDIRECT("I"&ROW()),H_Tables!F:F,0)),"")} -> 6 | AB182: {=IFERROR(INDEX(H_Tables!H:H,MATCH(INDIRECT("k"&ROW()),H_Tables!I:I,0)),"")} -> 1 | AC182: =_xlfn.TEXTJOIN(",",TRUE,M182:P182) -> VISA/MasterCard Add/Change/Delete,New,Hosted by 3rd Party,0 | AD182: 179
A183: 45895 | B183: Echelon Bank (InOrg) | C183: 0 | D183: Christopher Darty | E183: Diane Jackson | F183: 0 | G183: 0 | H183: Clearwater, FL - Echelon Bank (InOrg) - New Core SilverLake OL PAP | I183: Payments | J183: CPS000121 | K183: Card Processing Solutions (CPS) | L183: Professional Service | M183: JHA Tokenization (Digital Wallet) JHA Debit Processing | N183: New | O183: Hosted by 3rd Party | P183: 0 | Q183: One Time | R183: 1 | S183: 4000 | T183: -4000 | U183: 116592 | W183: 4000 | X183: a4p18000000GxrSAAS | Y183: 5000 | Z183: =ROUND(IF((F183+G183)=0,0,S183/Y183),4) -> 0 | AA183: {=IFERROR(INDEX(H_Tables!E:E,MATCH(INDIRECT("I"&ROW()),H_Tables!F:F,0)),"")} -> 6 | AB183: {=IFERROR(INDEX(H_Tables!H:H,MATCH(INDIRECT("k"&ROW()),H_Tables!I:I,0)),"")} -> 1 | AC183: =_xlfn.TEXTJOIN(",",TRUE,M183:P183) -> JHA Tokenization (Digital Wallet) JHA Debit Processing,New,Hosted by 3rd Party,0 | AD183: 180
A184: 45895 | B184: Echelon Bank (InOrg) | C184: 0 | D184: Christopher Darty | E184: Diane Jackson | F184: 0 | G184: 0 | H184: Clearwater, FL - Echelon Bank (InOrg) - New Core SilverLake OL PAP | I184: Payments | J184: CPS01001 | K184: Card Processing Solutions (CPS) | L184: Professional Service | M184: JHA Tokenization (Digital Wallet) Additional Instance JHA Debit Processing | N184: New | O184: Hosted by 3rd Party | P184: 0 | Q184: One Time | R184: 1 | S184: 2000 | T184: -2000 | U184: 116592 | W184: 2000 | X184: a4p180000001AoSAAU | Y184: 5000 | Z184: =ROUND(IF((F184+G184)=0,0,S184/Y184),4) -> 0 | AA184: {=IFERROR(INDEX(H_Tables!E:E,MATCH(INDIRECT("I"&ROW()),H_Tables!F:F,0)),"")} -> 6 | AB184: {=IFERROR(INDEX(H_Tables!H:H,MATCH(INDIRECT("k"&ROW()),H_Tables!I:I,0)),"")} -> 1 | AC184: =_xlfn.TEXTJOIN(",",TRUE,M184:P184) -> JHA Tokenization (Digital Wallet) Additional Instance JHA Debit Processing,New,Hosted by 3rd Party,0 | AD184: 181
...

Sheet Balancing
B2: Product | D2: New License | E2: New Install | F2: New Annual | G2: New Monthly | I2: Old License | J2: Old Install | K2: Old Annual | L2: Old Monthly | N2: License Delta | O2: Install Delta | P2: Annual Delta | Q2: Monthly Delta | S2: BAF License | T2: BAF Install | U2: BAF Annual | V2: BAF Monthly
B3: SilverLake System Bundle,New,Hosted by JHA,0 | D3: 0 | E3: 0 | F3: 0 | G3: 6090.5 | I3: 0 | J3: 0 | K3: 0 | L3: 6090.5 | N3: 0 | O3: 0 | P3: 0 | Q3: 0
B4: SilverLake Technical Conversion/Installation,New,Hosted by JHA,0 | D4: 0 | E4: 0 | F4: 0 | G4: 0 | I4: 0 | J4: 0 | K4: 0 | L4: 0 | N4: 0 | O4: 0 | P4: 0 | Q4: 0
B5: Closed Accounts (PAP),New,Hosted by JHA,0 | D5: 0 | E5: 0 | F5: 0 | G5: 0.25 | I5: 0 | J5: 0 | K5: 0 | L5: 0.25 | N5: 0 | O5: 0 | P5: 0 | Q5: 0
B6: SilverLake Static Training Bank,New,Hosted by JHA,1 | D6: 0 | E6: 0 | F6: 0 | G6: 397.5 | I6: 0 | J6: 0 | K6: 0 | L6: 397.5 | N6: 0 | O6: 0 | P6: 0 | Q6: 0
B7: SilverLake Teller Static Training Bank,New,Hosted by JHA,1 | D7: 0 | E7: 0 | F7: 0 | G7: 165 | I7: 0 | J7: 0 | K7: 0 | L7: 165 | N7: 0 | O7: 0 | P7: 0 | Q7: 0
B8: JH Technology Architecture Services,New,Hosted by JHA,0 | D8: 0 | E8: 0 | F8: 0 | G8: 0 | I8: 0 | J8: 0 | K8: 0 | L8: 0 | N8: 0 | O8: 0 | P8: 0 | Q8: 0
B9: JHMenu Express,New,On Premise License,0 | D9: 9000 | E9: 0 | F9: 0 | G9: 0 | I9: 9000 | J9: 0 | K9: 0 | L9: 0 | N9: 0 | O9: 0 | P9: 0 | Q9: 0
B10: Daily File Transfer Integration IntraFi,New,Hosted by JHA,0 | D10: 0 | E10: 0 | F10: 0 | G10: 225 | I10: 0 | J10: 0 | K10: 0 | L10: 225 | N10: 0 | O10: 0 | P10: 0 | Q10: 0
B11: Hosted Xperience,New,Hosted by JHA,0 | D11: 0 | E11: 0 | F11: 0 | G11: 112.5 | I11: 0 | J11: 0 | K11: 0 | L11: 112.5 | N11: 0 | O11: 0 | P11: 0 | Q11: 0
B12: Platform Static Training Bank,New,Hosted by JHA,1 | D12: 0 | E12: 0 | F12: 0 | G12: 165 | I12: 0 | J12: 0 | K12: 0 | L12: 165 | N12: 0 | O12: 0 | P12: 0 | Q12: 0
B13: OnBoard Deposits,New,Hosted by JHA,0 | D13: 0 | E13: 0 | F13: 0 | G13: 851.5 | I13: 0 | J13: 0 | K13: 0 | L13: 851.5 | N13: 0 | O13: 0 | P13: 0 | Q13: 0
B14: OnBoard Lending,New,Hosted by JHA,1 | D14: 0 | E14: 0 | F14: 0 | G14: 1136.5 | I14: 0 | J14: 0 | K14: 0 | L14: 1136.5 | N14: 0 | O14: 0 | P14: 0 | Q14: 0
... B166: Know-It-All Now eLearning,New,Hosted by JHA,0 | D166: 0 | E166: 0 | F166: 3500 | G166: 0 | I166: 0 | J166: 0 | K166: 3500 | L166: 0 | N166: 0 | O166: 0 | P166: 0 | Q166: 0

Sheet DeleteThisPageThenSave
B2: OriginalFileName | C2: Updated_With_all_products__Deal_Sheet_Clearwater__FL_-_Echelon_Bank__InOrg__-_New_Core_SilverLake_OL_PAP_08_27_25

Sheet Proposal_1
H1: {=MID(CELL("filename",A1),FIND("]",CELL("filename",A1))+1,255)} -> Proposal_1
J2: License List | K2: Discount | L2: License Net | N2: Install List | O2: Discount | P2: Install Net | R2: Maintenance List | S2: Discount | T2: Maintenance Net | V2: New Monthly List | W2: Discount | X2: New Monthly Net | Z2: Current Monthly List | AA2: Discount | AB2: Current Monthly Net
B3: Date: | C3: 45896 | I3: Included Software | J3: =SUMIFS(J$14:J$350,$F$14:$F$350,"Included")+SUMIFS(J$14:J$350,$F$14:$F$350,"Add")-J6 -> 16545 | K3: =L3-J3 -> 0 | L3: =SUMIFS(L$14:L$350,$F$14:$F$350,"Included")+SUMIFS(L$14:L$350,$F$14:$F$350,"Add")-L6 -> 16545 | N3: =SUMIFS(N$14:N$350,$F$14:$F$350,"Included")+SUMIFS(N$14:N$350,$F$14:$F$350,"Add") -> 840215 | O3: =P3-N3 -> -589322.5 | P3: =SUMIFS(P$14:P$350,$F$14:$F$350,"Included")+SUMIFS(P$14:P$350,$F$14:$F$350,"Add") -> 250892.5 | R3: =SUMIFS(R$14:R$350,$F$14:$F$350,"Included")+SUMIFS(R$14:R$350,$F$14:$F$350,"Add") -> 34899 | S3: =T3-R3 -> 0 | T3: =SUMIFS(T$14:T$350,$F$14:$F$350,"Included")+SUMIFS(T$14:T$350,$F$14:$F$350,"Add") -> 34899 | V3: =SUMIFS(V$14:V$350,$F$14:$F$350,"Included")+SUMIFS(V$14:V$350,$F$14:$F$350,"Add") -> 44605.4 | W3: =X3-V3 -> -5529.9 | X3: =SUMIFS(X$14:X$350,$F$14:$F$350,"Included")+SUMIFS(X$14:X$350,$F$14:$F$350,"Add") -> 39075.5 | Z3: =SUMIFS(Z$14:Z$350,$F$14:$F$350,"Included")+SUMIFS(Z$14:Z$350,$F$14:$F$350,"Add") -> 0 | AA3: =AB3-Z3 -> 0 | AB3: =SUMIFS(AB$14:AB$350,$F$14:$F$350,"Included")+SUMIFS(AB$14:AB$350,$F$14:$F$350,"Add") -> 0
B4: Prepared for: | C4: Echelon Bank (InOrg) | I4: Optional Software | J4: =SUMIFS(J$14:J$350,$F$14:$F$350,"Optional")-J7 -> 0 | K4: =L4-J4 -> 0 | L4: =SUMIFS(L$14:L$350,$F$14:$F$350,"Optional")-L7 -> 0 | N4: =SUMIFS(N$14:N$350,$F$14:$F$350,"Optional") -> 279595 | O4: =P4-N4 -> -190745 | P4: =SUMIFS(P$14:P$350,$F$14:$F$350,"Optional") -> 88850 | R4: =SUMIFS(R$14:R$350,$F$14:$F$350,"Optional") -> 14095.7 | S4: =T4-R4 -> 0 | T4: =SUMIFS(T$14:T$350,$F$14:$F$350,"Optional") -> 14095.7 | V4: =SUMIFS(V$14:V$350,$F$14:$F$350,"Optional") -> 11380 | W4: =X4-V4 -> -1155.5 | X4: =SUMIFS(X$14:X$350,$F$14:$F$350,"Optional") -> 10224.5 | Z4: =SUMIFS(Z$14:Z$350,$F$14:$F$350,"Optional") -> 0 | AA4: =AB4-Z4 -> 0 | AB4: =SUMIFS(AB$14:AB$350,$F$14:$F$350,"Optional") -> 0
C5: Clearwater, FL - Echelon Bank (InOrg) - New Core SilverLake OL PAP | I5: Replaced Software | J5: =SUMIFS(J$14:J$350,$F$14:$F$350,"Replaced") -> 0 | K5: =L5-J5 -> 0 | L5: =SUMIFS(L$14:L$350,$F$14:$F$350,"Replaced") -> 0 | N5: =SUMIFS(N$14:N$350,$F$14:$F$350,"Replaced") -> 0 | O5: =P5-N5 -> 0 | P5: =SUMIFS(P$14:P$350,$F$14:$F$350,"Replaced") -> 0 | R5: =SUMIFS(R$14:R$350,$F$14:$F$350,"Replaced") -> 0 | S5: =T5-R5 -> 0 | T5: =SUMIFS(T$14:T$350,$F$14:$F$350,"Replaced") -> 0 | V5: =SUMIFS(V$14:V$350,$F$14:$F$350,"Replaced") -> 0 | W5: =X5-V5 -> 0 | X5: =SUMIFS(X$14:X$350,$F$14:$F$350,"Replaced") -> 0 | Z5: =SUMIFS(Z$14:Z$350,$F$14:$F$350,"Replaced") -> 0 | AA5: =AB5-Z5 -> 0 | AB5: =SUMIFS(AB$14:AB$350,$F$14:$F$350,"Replaced") -> 0
I6: Included Hardware | J6: =SUMIFS($J$14:$J$350,$C$14:$C$350,"",$F$14:$F$350,"Included") -> 0 | K6: =L6-J6 -> 0 | L6: =SUMIFS($L$14:$L$350,$C$14:$C$350,"",$F$14:$F$350,"Included") -> 0
B7: JHA Company ID | C7: 116592 | I7: Optional Hardware | J7: =SUMIFS($J$14:$J$350,$C$14:$C$350,"",$F$14:$F$350,"Optional") -> 0 | K7: =L7-J7 -> 0 | L7: =SUMIFS($L$14:$L$350,$C$14:$C$350,"",$F$14:$F$350,"Optional") -> 0 | V7: =IF(SUM(SF_Output!F:F)>0,"PAP Discount (%)","") -> PAP Discount (%) | W7: 0
B8: Asset Size: | C8: 0
B9: AE: | C9: Christopher Darty | J9: Global Discount | K9: 0 | N9: Global Discount | O9: 0 | R9: Global Discount | S9: 0 | V9: =IF(SUM(SF_Output!F:F)>0,"","Global Discount") | W9: 0
B10: PA: | C10: Diane Jackson
B11: Term in Months | C11: TBD | K11: License | O11: Install | S11: Maintenance | W11: New Monthly | AA11: Current Monthly
C12: 5000
B13: Product Description | C13: Order Type | D13: Delivery | E13: Optional from sf | F13: Category | G13: Product Family | H13: Quantity | I13: Avg Unit $ | J13: =J2 -> License List | K13: Discount | L13: =L2 -> License Net | N13: =N2 -> Install List | O13: Discount | P13: =P2 -> Install Net | R13: =R2 -> Maintenance List | S13: Discount | T13: =T2 -> Maintenance Net | V13: =V2 -> New Monthly List | W13: Discount | X13: =X2 -> New Monthly Net | Z13: Current Monthly List | AA13: Discount | AB13: Current Monthly Net | AD13: Difference | AF13: Exclusion | AH13: Freeform Comments to PA | AI13: AutoGenerated Comments to PA | AJ13: PA Sort | AK13: PAP
B14: SilverLake System Bundle | C14: New | D14: Hosted by JHA | E14: 0 | F14: =IF(B14="","",IF(E14*1=0,"Included","Optional")) -> Included | G14: =IF(B14="","",INDEX(SF_Output!$K$1:$K$400,MATCH(B14,SF_Output!$M$1:$M$400,0))) -> SilverLake | H14: {=_xlfn.IFS(B14="","",(SUMIFS(SF_Output!$F$1:$F$400,SF_Output!$AC$1:$AC$400,_xlfn.TEXTJOIN(",",TRUE,B14:E14))+SUMIFS(SF_Output!$G$1:$G$400,SF_Output!$AC$1:$AC$400,_xlfn.TEXTJOIN(",",TRUE,B14:E14)))<>0,SF_Output!$Y$2,INDEX(SF_Output!$F$1:$F$400,MATCH(_xlfn.TEXTJOIN(",",TRUE,B14:E14),SF_Output!$AC$1:$AC$400,0))=0,INDEX(SF_Output!$R$1:$R$400,MATCH(_xlfn.TEXTJOIN(",",TRUE,B14:E14),SF_Output!$AC$1:$AC$400,0)))} -> 5000 | I14: =IFERROR(IF(AND(H14>1,H14<>""),ROUND(SUMIFS(SF_Output!$S$1:$S$400,SF_Output!$AC$1:$AC$400,_xlfn.TEXTJOIN(",",TRUE,B14:E14),SF_Output!$Q$1:$Q$400,"monthly")*(1-W14)/H14,4),""),"") -> 1.2181 | J14: =IF(B14="","",SUMIFS(SF_Output!$S$1:$S$400,SF_Output!$AC$1:$AC$400,_xlfn.TEXTJOIN(",",TRUE,B14:E14),SF_Output!$Q$1:$Q$400,"One Time",SF_Output!$L$1:$L$400,"license fee")+SUMIFS(SF_Output!$S$1:$S$400,SF_Output!$AC$1:$AC$400,_xlfn.TEXTJOIN(",",TRUE,B14:E14),SF_Output!$Q$1:$Q$400,"One Time",SF_Output!$L$1:$L$400,"software license")+SUMIFS(SF_Output!$S$1:$S$400,SF_Output!$AC$1:$AC$400,_xlfn.TEXTJOIN(",",TRUE,B14:E14),SF_Output!$Q$1:$Q$400,"One Time",SF_Output!$L$1:$L$400,"hardware")) -> 0 | K14: =IF(OR(B14=0,B14="",G14="hardware",J14=0),"",IF(AF14<>"exclusion",MAX(K$9,-((SUMIFS(SF_Output!$T$1:$T$400,SF_Output!$AC$1:$AC$400,_xlfn.TEXTJOIN(",",TRUE,$B14:$E14),SF_Output!$Q$1:$Q$400,"One Time",SF_Output!$L$1:$L$400,"license fee")+SUMIFS(SF_Output!$T$1:$T$400,SF_Output!$AC$1:$AC$400,_xlfn.TEXTJOIN(",",TRUE,$B14:$E14),SF_Output!$Q$1:$Q$400,"One Time",SF_Output!$L$1:$L$400,"software license"))/J14)),-((SUMIFS(SF_Output!$T$1:$T$400,SF_Output!$AC$1:$AC$400,_xlfn.TEXTJOIN(",",TRUE,$B14:$E14),SF_Output!$Q$1:$Q$400,"One Time",SF_Output!$L$1:$L$400,"license fee")+SUMIFS(SF_Output!$T$1:$T$400,SF_Output!$AC$1:$AC$400,_xlfn.TEXTJOIN(",",TRUE,$B14:$E14),SF_Output!$Q$1:$Q$400,"One Time",SF_Output!$L$1:$L$400,"software license"))/J14))) | L14: =IF(K14="",J14,J14*(1-K14)) -> 0 | N14: =IF(B14="","",SUMIFS(SF_Output!$S$1:$S$400,SF_Output!$AC$1:$AC$400,_xlfn.TEXTJOIN(",",TRUE,B14:E14),SF_Output!$Q$1:$Q$400,"One Time",SF_Output!$L$1:$L$400,"professional service")) -> 78700 | O14: =IF(OR(B14=0,B14="",N14=0),"",IF(AF14<>"exclusion",MAX(O$9,-(SUMIFS(SF_Output!$T$1:$T$400,SF_Output!$AC$1:$AC$400,_xlfn.TEXTJOIN(",",TRUE,$B14:$E14),SF_Output!$Q$1:$Q$400,"One Time",SF_Output!$L$1:$L$400,"professional service"))/N14),-((SUMIFS(SF_Output!$T$1:$T$400,SF_Output!$AC$1:$AC$400,_xlfn.TEXTJOIN(",",TRUE,$B14:$E14),SF_Output!$Q$1:$Q$400,"One Time",SF_Output!$L$1:$L$400,"professional service")/N14)))) -> 1 | P14: =IF(O14="",N14,N14*(1-O14)) -> 0 | R14: =IF(B14="","",SUMIFS(SF_Output!$S$1:$S$400,SF_Output!$AC$1:$AC$400,_xlfn.TEXTJOIN(",",TRUE,B14:E14),SF_Output!$Q$1:$Q$400,"yearly")+SUMIFS(SF_Output!$S$1:$S$400,SF_Output!$AC$1:$AC$400,_xlfn.TEXTJOIN(",",TRUE,B14:E14),SF_Output!$Q$1:$Q$400,"quarterly")*4) -> 0 | S14: =IF(OR(B14=0,B14="",G14="hardware",R14=0),"",IF(AF14<>"exclusion",MAX(S$9,-(SUMIFS(SF_Output!$T$1:$T$400,SF_Output!$AC$1:$AC$400,_xlfn.TEXTJOIN(",",TRUE,$B14:$E14),SF_Output!$Q$1:$Q$400,"yearly"))/R14),-((SUMIFS(SF_Output!$T$1:$T$400,SF_Output!$AC$1:$AC$400,_xlfn.TEXTJOIN(",",TRUE,$B14:$E14),SF_Output!$Q$1:$Q$400,"yearly")/R14)))) | T14: =IF(S14="",R14,R14*(1-S14)) -> 0 | V14: {=_xlfn.IFS(B14="","",AND(B14<>"",H14=SF_Output!$Y$2,SUMIFS(SF_Output!$T$1:$T$400,SF_Output!$AC$1:$AC$400,_xlfn.TEXTJOIN(",",TRUE,B14:E14),SF_Output!$Q$1:$Q$400,"monthly")=0),(SUMIFS(SF_Output!$F$1:$F$400,SF_Output!$AC$1:$AC$400,_xlfn.TEXTJOIN(",",TRUE,B14:E14),SF_Output!$Q$1:$Q$400,"monthly")+SUMIFS(SF_Output!$G$1:$G$400,SF_Output!$AC$1:$AC$400,_xlfn.TEXTJOIN(",",TRUE,B14:E14),SF_Output!$Q$1:$Q$400,"monthly"))*H14,AND(B14<>"",H14=SF_Output!$Y$2,SUMIFS(SF_Output!$T$1:$T$400,SF_Output!$AC$1:$AC$400,_xlfn.TEXTJOIN(",",TRUE,B14:E14),SF_Output!$Q$1:$Q$400,"monthly")<>0),SUMIFS(SF_Output!$S$1:$S$400,SF_Output!$AC$1:$AC$400,_xlfn.TEXTJOIN(",",TRUE,B14:E14),SF_Output!$Q$1:$Q$400,"monthly"),AND(B14<>"",H14<>SF_Output!$Y$2),SUMIFS(SF_Output!$S$1:$S$400,SF_Output!$AC$1:$AC$400,_xlfn.TEXTJOIN(",",TRUE,B14:E14),SF_Output!$Q$1:$Q$400,"monthly"))} -> 6921.15 | W14: {=_xlfn.IFS(OR(B14=0,B14="",V14=0),"",AF14<>"exclusion",MAX($W$9,$W$7,(-(SUMIFS(SF_Output!$T$1:$T$400,SF_Output!$AC$1:$AC$400,_xlfn.TEXTJOIN(",",TRUE,$B14:$E14),SF_Output!$Q$1:$Q$400,"monthly"))/V14)),AF14="exclusion",-(SUMIFS(SF_Output!$T$1:$T$400,SF_Output!$AC$1:$AC$400,_xlfn.TEXTJOIN(",",TRUE,$B14:$E14),SF_Output!$Q$1:$Q$400,"monthly"))/V14)} -> 0.12000029 | X14: {=IFERROR(_xlfn.IFS(V14=0,0,V14="","",W14=0,V14,OR(V14<>0,V14<>""),H14*I14),V14*(1-W14))} -> 6090.5 | Z14: =IFERROR(IF(B14="","",SUMIFS(Billing_Fallout!H:H,Billing_Fallout!N:N,B14)),0) -> 0 | AA14: =IF(Z14="","",AB14-Z14) -> 0 | AB14: =IFERROR(IF(B14="","",SUMIFS(Billing_Fallout!J:J,Billing_Fallout!N:N,B14)),0) -> 0 | AD14: =IFERROR(X14-AB14,"") -> 6090.5 | AF14: =IFERROR(INDEX(H_Tables!$B$1:$B$1500,MATCH(INDEX(SF_Output!$J$1:$J$400,MATCH(B14,SF_Output!$M$1:$M$400,0)),H_Tables!$A$1:$A$1500,0)),"") -> Exclusion | AI14: =IF(B14="","",IF(F14="remove","Remove Product",IF(F14="add","Add Product",_xlfn.TEXTJOIN(", ",TRUE,AQ14,AR14,AS14,AT14,AU14,AV14,AW14,AX14,AY14,AZ14,BA14,BB14,BC14)))) | AJ14: =IFERROR(INDEX(SF_Output!AD:AD,MATCH(_xlfn.TEXTJOIN(",",TRUE,B14:E14),SF_Output!AC1:AC400,0)),0.05) -> 8 | AK14: =IF(SUMIFS(SF_Output!$F$1:$F$400,SF_Output!$AC$1:$AC$400,_xlfn.TEXTJOIN(",",TRUE,B14:E14))+SUMIFS(SF_Output!$G$1:$G$400,SF_Output!$AC$1:$AC$400,_xlfn.TEXTJOIN(",",TRUE,B14:E14))=0,"","PAP") -> PAP | AL14: =LEFT(_xlfn.TEXTJOIN(",",TRUE,B14:E14),80) -> SilverLake System Bundle,New,Hosted by JHA,0 | AR14: {=IFERROR(_xlfn.IFS(AND(E14*1=1,F14="Included"),"Change to Included",AND(E14*1=0,F14="Optional"),"Change to Optional",OR(B14="",F14="replaced"),""),"")} | AS14: =IF((OR(NOT(_xlfn.ISFORMULA(J14)),NOT(_xlfn.ISFORMULA(L14)))),"Check License Price Override","") | AT14: =IF(OR(AND(K14=$K$9,K14<>0),NOT(_xlfn.ISFORMULA(K14))),"License Discount "&K14*100&"%","") | AU14: =IF((OR(NOT(_xlfn.ISFORMULA(N14)),NOT(_xlfn.ISFORMULA(P14)))),"Check Install Price Override","") | AV14: =IF(OR(AND(O14=$O$9,O14<>0),NOT(_xlfn.ISFORMULA(O14))),"Install Discount "&O14*100&"%","") | AW14: =IF((OR(NOT(_xlfn.ISFORMULA(R14)),NOT(_xlfn.ISFORMULA(T14)))),"Check Maintenance Price Override","") | AX14: =IF(OR(AND(S14=$S$9,S14<>0),NOT(_xlfn.ISFORMULA(S14))),"Maintenance Discount "&S14*100&"%","") | AY14: =IF((OR(NOT(_xlfn.ISFORMULA(V14)),NOT(_xlfn.ISFORMULA(X14)))),"Check Monthly Price Override","") | AZ14: =IF(OR((AND(W14=$W$9,W14<>0)),(AND(W14=$W$7,W14<>0)),(NOT(_xlfn.ISFORMULA(W14))),AND($W$7+0.2=W14,$W$7<>0)),"Monthly Discount "&W14*100&"%","") | BA14: =IF(NOT(_xlfn.ISFORMULA(H14)),"Check Quantity","") | BB14: =IF(NOT(_xlfn.ISFORMULA(I14)),"Check Unit Price Override","") | BE14: =INDEX(SF_Output!$AA$2:$AA$400,MATCH($B14,SF_Output!$M$2:$M$400,0)) -> 1 | BF14: =INDEX(SF_Output!$AB$2:$AB$400,MATCH($B14,SF_Output!$M$2:$M$400,0)) -> 1
B15: SilverLake Technical Conversion/Installation | C15: New | D15: Hosted by JHA | E15: 0 | F15: =IF(B15="","",IF(E15*1=0,"Included","Optional")) -> Included | G15: =IF(B15="","",INDEX(SF_Output!$K$1:$K$400,MATCH(B15,SF_Output!$M$1:$M$400,0))) -> SilverLake | H15: {=_xlfn.IFS(B15="","",(SUMIFS(SF_Output!$F$1:$F$400,SF_Output!$AC$1:$AC$400,_xlfn.TEXTJOIN(",",TRUE,B15:E15))+SUMIFS(SF_Output!$G$1:$G$400,SF_Output!$AC$1:$AC$400,_xlfn.TEXTJOIN(",",TRUE,B15:E15)))<>0,SF_Output!$Y$2,INDEX(SF_Output!$F$1:$F$400,MATCH(_xlfn.TEXTJOIN(",",TRUE,B15:E15),SF_Output!$AC$1:$AC$400,0))=0,INDEX(SF_Output!$R$1:$R$400,MATCH(_xlfn.TEXTJOIN(",",TRUE,B15:E15),SF_Output!$AC$1:$AC$400,0)))} -> 1 | I15: =IFERROR(IF(AND(H15>1,H15<>""),ROUND(SUMIFS(SF_Output!$S$1:$S$400,SF_Output!$AC$1:$AC$400,_xlfn.TEXTJOIN(",",TRUE,B15:E15),SF_Output!$Q$1:$Q$400,"monthly")*(1-W15)/H15,4),""),"") | J15: =IF(B15="","",SUMIFS(SF_Output!$S$1:$S$400,SF_Output!$AC$1:$AC$400,_xlfn.TEXTJOIN(",",TRUE,B15:E15),SF_Output!$Q$1:$Q$400,"One Time",SF_Output!$L$1:$L$400,"license fee")+SUMIFS(SF_Output!$S$1:$S$400,SF_Output!$AC$1:$AC$400,_xlfn.TEXTJOIN(",",TRUE,B15:E15),SF_Output!$Q$1:$Q$400,"One Time",SF_Output!$L$1:$L$400,"software license")+SUMIFS(SF_Output!$S$1:$S$400,SF_Output!$AC$1:$AC$400,_xlfn.TEXTJOIN(",",TRUE,B15:E15),SF_Output!$Q$1:$Q$400,"One Time",SF_Output!$L$1:$L$400,"hardware")) -> 0 | K15: =IF(OR(B15=0,B15="",G15="hardware",J15=0),"",IF(AF15<>"exclusion",MAX(K$9,-((SUMIFS(SF_Output!$T$1:$T$400,SF_Output!$AC$1:$AC$400,_xlfn.TEXTJOIN(",",TRUE,$B15:$E15),SF_Output!$Q$1:$Q$400,"One Time",SF_Output!$L$1:$L$400,"license fee")+SUMIFS(SF_Output!$T$1:$T$400,SF_Output!$AC$1:$AC$400,_xlfn.TEXTJOIN(",",TRUE,$B15:$E15),SF_Output!$Q$1:$Q$400,"One Time",SF_Output!$L$1:$L$400,"software license"))/J15)),-((SUMIFS(SF_Output!$T$1:$T$400,SF_Output!$AC$1:$AC$400,_xlfn.TEXTJOIN(",",TRUE,$B15:$E15),SF_Output!$Q$1:$Q$400,"One Time",SF_Output!$L$1:$L$400,"license fee")+SUMIFS(SF_Output!$T$1:$T$400,SF_Output!$AC$1:$AC$400,_xlfn.TEXTJOIN(",",TRUE,$B15:$E15),SF_Output!$Q$1:$Q$400,"One Time",SF_Output!$L$1:$L$400,"software license"))/J15))) | L15: =IF(K15="",J15,J15*(1-K15)) -> 0 | N15: =IF(B15="","",SUMIFS(SF_Output!$S$1:$S$400,SF_Output!$AC$1:$AC$400,_xlfn.TEXTJOIN(",",TRUE,B15:E15),SF_Output!$Q$1:$Q$400,"One Time",SF_Output!$L$1:$L$400,"professional service")) -> 125405 | O15: =IF(OR(B15=0,B15="",N15=0),"",IF(AF15<>"exclusion",MAX(O$9,-(SUMIFS(SF_Output!$T$1:$T$400,SF_Output!$AC$1:$AC$400,_xlfn.TEXTJOIN(",",TRUE,$B15:$E15),SF_Output!$Q$1:$Q$400,"One Time",SF_Output!$L$1:$L$400,"professional service"))/N15),-((SUMIFS(SF_Output!$T$1:$T$400,SF_Output!$AC$1:$AC$400,_xlfn.TEXTJOIN(",",TRUE,$B15:$E15),SF_Output!$Q$1:$Q$400,"One Time",SF_Output!$L$1:$L$400,"professional service")/N15)))) -> 1 | P15: =IF(O15="",N15,N15*(1-O15)) -> 0 | R15: =IF(B15="","",SUMIFS(SF_Output!$S$1:$S$400,SF_Output!$AC$1:$AC$400,_xlfn.TEXTJOIN(",",TRUE,B15:E15),SF_Output!$Q$1:$Q$400,"yearly")+SUMIFS(SF_Output!$S$1:$S$400,SF_Output!$AC$1:$AC$400,_xlfn.TEXTJOIN(",",TRUE,B15:E15),SF_Output!$Q$1:$Q$400,"quarterly")*4) -> 0 | S15: =IF(OR(B15=0,B15="",G15="hardware",R15=0),"",IF(AF15<>"exclusion",MAX(S$9,-(SUMIFS(SF_Output!$T$1:$T$400,SF_Output!$AC$1:$AC$400,_xlfn.TEXTJOIN(",",TRUE,$B15:$E15),SF_Output!$Q$1:$Q$400,"yearly"))/R15),-((SUMIFS(SF_Output!$T$1:$T$400,SF_Output!$AC$1:$AC$400,_xlfn.TEXTJOIN(",",TRUE,$B15:$E15),SF_Output!$Q$1:$Q$400,"yearly")/R15)))) | T15: =IF(S15="",R15,R15*(1-S15)) -> 0 | V15: {=_xlfn.IFS(B15="","",AND(B15<>"",H15=SF_Output!$Y$2,SUMIFS(SF_Output!$T$1:$T$400,SF_Output!$AC$1:$AC$400,_xlfn.TEXTJOIN(",",TRUE,B15:E15),SF_Output!$Q$1:$Q$400,"monthly")=0),(SUMIFS(SF_Output!$F$1:$F$400,SF_Output!$AC$1:$AC$400,_xlfn.TEXTJOIN(",",TRUE,B15:E15),SF_Output!$Q$1:$Q$400,"monthly")+SUMIFS(SF_Output!$G$1:$G$400,SF_Output!$AC$1:$AC$400,_xlfn.TEXTJOIN(",",TRUE,B15:E15),SF_Output!$Q$1:$Q$400,"monthly"))*H15,AND(B15<>"",H15=SF_Output!$Y$2,SUMIFS(SF_Output!$T$1:$T$400,SF_Output!$AC$1:$AC$400,_xlfn.TEXTJOIN(",",TRUE,B15:E15),SF_Output!$Q$1:$Q$400,"monthly")<>0),SUMIFS(SF_Output!$S$1:$S$400,SF_Output!$AC$1:$AC$400,_xlfn.TEXTJOIN(",",TRUE,B15:E15),SF_Output!$Q$1:$Q$400,"monthly"),AND(B15<>"",H15<>SF_Output!$Y$2),SUMIFS(SF_Output!$S$1:$S$400,SF_Output!$AC$1:$AC$400,_xlfn.TEXTJOIN(",",TRUE,B15:E15),SF_Output!$Q$1:$Q$400,"monthly"))} -> 0 | W15: {=_xlfn.IFS(OR(B15=0,B15="",V15=0),"",AF15<>"exclusion",MAX($W$9,$W$7,(-(SUMIFS(SF_Output!$T$1:$T$400,SF_Output!$AC$1:$AC$400,_xlfn.TEXTJOIN(",",TRUE,$B15:$E15),SF_Output!$Q$1:$Q$400,"monthly"))/V15)),AF15="exclusion",-(SUMIFS(SF_Output!$T$1:$T$400,SF_Output!$AC$1:$AC$400,_xlfn.TEXTJOIN(",",TRUE,$B15:$E15),SF_Output!$Q$1:$Q$400,"monthly"))/V15)} | X15: {=IFERROR(_xlfn.IFS(V15=0,0,V15="","",W15=0,V15,OR(V15<>0,V15<>""),H15*I15),V15*(1-W15))} -> 0 | Z15: =IFERROR(IF(B15="","",SUMIFS(Billing_Fallout!H:H,Billing_Fallout!N:N,B15)),0) -> 0 | AA15: =IF(Z15="","",AB15-Z15) -> 0 | AB15: =IFERROR(IF(B15="","",SUMIFS(Billing_Fallout!J:J,Billing_Fallout!N:N,B15)),0) -> 0 | AD15: =IFERROR(X15-AB15,"") -> 0 | AF15: =IFERROR(INDEX(H_Tables!$B$1:$B$1500,MATCH(INDEX(SF_Output!$J$1:$J$400,MATCH(B15,SF_Output!$M$1:$M$400,0)),H_Tables!$A$1:$A$1500,0)),"") | AI15: =IF(B15="","",IF(F15="remove","Remove Product",IF(F15="add","Add Product",_xlfn.TEXTJOIN(", ",TRUE,AQ15,AR15,AS15,AT15,AU15,AV15,AW15,AX15,AY15,AZ15,BA15,BB15,BC15)))) | AJ15: =IFERROR(INDEX(SF_Output!AD:AD,MATCH(_xlfn.TEXTJOIN(",",TRUE,B15:E15),SF_Output!AC1:AC400,0)),0.05) -> 10 | AK15: =IF(SUMIFS(SF_Output!$F$1:$F$400,SF_Output!$AC$1:$AC$400,_xlfn.TEXTJOIN(",",TRUE,B15:E15))+SUMIFS(SF_Output!$G$1:$G$400,SF_Output!$AC$1:$AC$400,_xlfn.TEXTJOIN(",",TRUE,B15:E15))=0,"","PAP") | AL15: =LEFT(_xlfn.TEXTJOIN(",",TRUE,B15:E15),80) -> SilverLake Technical Conversion/Installation,New,Hosted by JHA,0 | AR15: {=IFERROR(_xlfn.IFS(AND(E15*1=1,F15="Included"),"Change to Included",AND(E15*1=0,F15="Optional"),"Change to Optional",OR(B15="",F15="replaced"),""),"")} | AS15: =IF((OR(NOT(_xlfn.ISFORMULA(J15)),NOT(_xlfn.ISFORMULA(L15)))),"Check License Price Override","") | AT15: =IF(OR(AND(K15=$K$9,K15<>0),NOT(_xlfn.ISFORMULA(K15))),"License Discount "&K15*100&"%","") | AU15: =IF((OR(NOT(_xlfn.ISFORMULA(N15)),NOT(_xlfn.ISFORMULA(P15)))),"Check Install Price Override","") | AV15: =IF(OR(AND(O15=$O$9,O15<>0),NOT(_xlfn.ISFORMULA(O15))),"Install Discount "&O15*100&"%","") | AW15: =IF((OR(NOT(_xlfn.ISFORMULA(R15)),NOT(_xlfn.ISFORMULA(T15)))),"Check Maintenance Price Override","") | AX15: =IF(OR(AND(S15=$S$9,S15<>0),NOT(_xlfn.ISFORMULA(S15))),"Maintenance Discount "&S15*100&"%","") | AY15: =IF((OR(NOT(_xlfn.ISFORMULA(V15)),NOT(_xlfn.ISFORMULA(X15)))),"Check Monthly Price Override","") | AZ15: =IF(OR((AND(W15=$W$9,W15<>0)),(AND(W15=$W$7,W15<>0)),(NOT(_xlfn.ISFORMULA(W15))),AND($W$7+0.2=W15,$W$7<>0)),"Monthly Discount "&W15*100&"%","") | BA15: =IF(NOT(_xlfn.ISFORMULA(H15)),"Check Quantity","") | BB15: =IF(NOT(_xlfn.ISFORMULA(I15)),"Check Unit Price Override","") | BE15: =INDEX(SF_Output!$AA$2:$AA$400,MATCH($B15,SF_Output!$M$2:$M$400,0)) -> 1 | BF15: =INDEX(SF_Output!$AB$2:$AB$400,MATCH($B15,SF_Output!$M$2:$M$400,0)) -> 1
