Workbook

Sheet Line Items
A1: Row ID | B1: Fee Type | C1: Solution Name | D1: Category | E1: Third Party | F1: Optional | G1: Per Unit Rate | H1: Unit Description | I1: Avg Monthly Qty | J1: Year 1 Monthly | K1: Year 1 Annual | L1: Year 2 | M1: Year 3 | N1: Year 4 | O1: Year 5 | P1: Year 6 | Q1: Year 7 | R1: Total 7-Year Cost | S1: Confidence | T1: Notes
A2: 34 | B2: Monthly F | C2: BI Web Administrator | D2: Core | E2: FALSE | F2: FALSE | G2: 469 | H2: per month | J2: =IF(B2="Monthly F",G2,IF(B2="Monthly V",G2*I2,IF(B2="Annual",G2/12,0))) | K2: =IF(B2="One-Time",G2,J2*12) | L2: =IF(B2="One-Time",0,K2*(1+Metadata!$B$8)) | M2: =IF(B2="One-Time",0,L2*(1+Metadata!$B$8)) | N2: =IF(B2="One-Time",0,M2*(1+Metadata!$B$8)) | O2: =IF(B2="One-Time",0,N2*(1+Metadata!$B$8)) | P2: =IF(B2="One-Time",0,O2*(1+Metadata!$B$8)) | Q2: =IF(B2="One-Time",0,P2*(1+Metadata!$B$8)) | R2: =SUM(K2:Q2)
A3: 1 | B3: Monthly F | C3: Bankway Core Account Processing In-House | D3: Core | E3: FALSE | F3: FALSE | G3: 0 | H3: per month | J3: =IF(B3="Monthly F",G3,IF(B3="Monthly V",G3*I3,IF(B3="Annual",G3/12,0))) | K3: =IF(B3="One-Time",G3,J3*12) | L3: =IF(B3="One-Time",0,K3*(1+Metadata!$B$8)) | M3: =IF(B3="One-Time",0,L3*(1+Metadata!$B$8)) | N3: =IF(B3="One-Time",0,M3*(1+Metadata!$B$8)) | O3: =IF(B3="One-Time",0,N3*(1+Metadata!$B$8)) | P3: =IF(B3="One-Time",0,O3*(1+Metadata!$B$8)) | Q3: =IF(B3="One-Time",0,P3*(1+Metadata!$B$8)) | R3: =SUM(K3:Q3)
A4: 2 | B4: Monthly F | C4: Bankway Standard Third Party Interface Offerings (IH) | D4: Core | E4: FALSE | F4: FALSE | G4: 0 | H4: per month | J4: =IF(B4="Monthly F",G4,IF(B4="Monthly V",G4*I4,IF(B4="Annual",G4/12,0))) | K4: =IF(B4="One-Time",G4,J4*12) | L4: =IF(B4="One-Time",0,K4*(1+Metadata!$B$8)) | M4: =IF(B4="One-Time",0,L4*(1+Metadata!$B$8)) | N4: =IF(B4="One-Time",0,M4*(1+Metadata!$B$8)) | O4: =IF(B4="One-Time",0,N4*(1+Metadata!$B$8)) | P4: =IF(B4="One-Time",0,O4*(1+Metadata!$B$8)) | Q4: =IF(B4="One-Time",0,P4*(1+Metadata!$B$8)) | R4: =SUM(K4:Q4)
A5: 29 | B5: Monthly F | C5: CSi Simplicity Hosting | D5: Core | E5: FALSE | F5: FALSE | G5: 120 | H5: per month | J5: =IF(B5="Monthly F",G5,IF(B5="Monthly V",G5*I5,IF(B5="Annual",G5/12,0))) | K5: =IF(B5="One-Time",G5,J5*12) | L5: =IF(B5="One-Time",0,K5*(1+Metadata!$B$8)) | M5: =IF(B5="One-Time",0,L5*(1+Metadata!$B$8)) | N5: =IF(B5="One-Time",0,M5*(1+Metadata!$B$8)) | O5: =IF(B5="One-Time",0,N5*(1+Metadata!$B$8)) | P5: =IF(B5="One-Time",0,O5*(1+Metadata!$B$8)) | Q5: =IF(B5="One-Time",0,P5*(1+Metadata!$B$8)) | R5: =SUM(K5:Q5)
A6: 32 | B6: Monthly F | C6: HORIZON BI Enterprise License | D6: Core | E6: FALSE | F6: FALSE | G6: 1350 | H6: per month | J6: =IF(B6="Monthly F",G6,IF(B6="Monthly V",G6*I6,IF(B6="Annual",G6/12,0))) | K6: =IF(B6="One-Time",G6,J6*12) | L6: =IF(B6="One-Time",0,K6*(1+Metadata!$B$8)) | M6: =IF(B6="One-Time",0,L6*(1+Metadata!$B$8)) | N6: =IF(B6="One-Time",0,M6*(1+Metadata!$B$8)) | O6: =IF(B6="One-Time",0,N6*(1+Metadata!$B$8)) | P6: =IF(B6="One-Time",0,O6*(1+Metadata!$B$8)) | Q6: =IF(B6="One-Time",0,P6*(1+Metadata!$B$8)) | R6: =SUM(K6:Q6)
A7: 3 | B7: Monthly F | C7: HORIZON Core Account Processing Service Bureau (SB) | D7: Core | E7: FALSE | F7: FALSE | G7: 28854 | H7: per account | I7: 54437 | J7: =IF(B7="Monthly F",G7,IF(B7="Monthly V",G7*I7,IF(B7="Annual",G7/12,0))) | K7: =IF(B7="One-Time",G7,J7*12) | L7: =IF(B7="One-Time",0,K7*(1+Metadata!$B$8)) | M7: =IF(B7="One-Time",0,L7*(1+Metadata!$B$8)) | N7: =IF(B7="One-Time",0,M7*(1+Metadata!$B$8)) | O7: =IF(B7="One-Time",0,N7*(1+Metadata!$B$8)) | P7: =IF(B7="One-Time",0,O7*(1+Metadata!$B$8)) | Q7: =IF(B7="One-Time",0,P7*(1+Metadata!$B$8)) | R7: =SUM(K7:Q7)
A8: 4 | B8: Monthly F | C8: HORIZON Products and Services (SB) | D8: Core | E8: FALSE | F8: FALSE | G8: 6549 | H8: per account | I8: 54437 | J8: =IF(B8="Monthly F",G8,IF(B8="Monthly V",G8*I8,IF(B8="Annual",G8/12,0))) | K8: =IF(B8="One-Time",G8,J8*12) | L8: =IF(B8="One-Time",0,K8*(1+Metadata!$B$8)) | M8: =IF(B8="One-Time",0,L8*(1+Metadata!$B$8)) | N8: =IF(B8="One-Time",0,M8*(1+Metadata!$B$8)) | O8: =IF(B8="One-Time",0,N8*(1+Metadata!$B$8)) | P8: =IF(B8="One-Time",0,O8*(1+Metadata!$B$8)) | Q8: =IF(B8="One-Time",0,P8*(1+Metadata!$B$8)) | R8: =SUM(K8:Q8)
A9: 5 | B9: Monthly F | C9: HORIZON Standard Third Party Interface Offerings (SB) | D9: Core | E9: FALSE | F9: FALSE | G9: 1610 | H9: per month | J9: =IF(B9="Monthly F",G9,IF(B9="Monthly V",G9*I9,IF(B9="Annual",G9/12,0))) | K9: =IF(B9="One-Time",G9,J9*12) | L9: =IF(B9="One-Time",0,K9*(1+Metadata!$B$8)) | M9: =IF(B9="One-Time",0,L9*(1+Metadata!$B$8)) | N9: =IF(B9="One-Time",0,M9*(1+Metadata!$B$8)) | O9: =IF(B9="One-Time",0,N9*(1+Metadata!$B$8)) | P9: =IF(B9="One-Time",0,O9*(1+Metadata!$B$8)) | Q9: =IF(B9="One-Time",0,P9*(1+Metadata!$B$8)) | R9: =SUM(K9:Q9)
A10: 31 | B10: Monthly F | C10: SmartSign | D10: Core | E10: FALSE | F10: FALSE | G10: 1531.2 | H10: per month | J10: =IF(B10="Monthly F",G10,IF(B10="Monthly V",G10*I10,IF(B10="Annual",G10/12,0))) | K10: =IF(B10="One-Time",G10,J10*12) | L10: =IF(B10="One-Time",0,K10*(1+Metadata!$B$8)) | M10: =IF(B10="One-Time",0,L10*(1+Metadata!$B$8)) | N10: =IF(B10="One-Time",0,M10*(1+Metadata!$B$8)) | O10: =IF(B10="One-Time",0,N10*(1+Metadata!$B$8)) | P10: =IF(B10="One-Time",0,O10*(1+Metadata!$B$8)) | Q10: =IF(B10="One-Time",0,P10*(1+Metadata!$B$8)) | R10: =SUM(K10:Q10)
A11: 7 | B11: Monthly F | C11: FIS Payment Manager - Consumer | D11: Digital | E11: FALSE | F11: FALSE | G11: 4089 | H11: per month | J11: =IF(B11="Monthly F",G11,IF(B11="Monthly V",G11*I11,IF(B11="Annual",G11/12,0))) | K11: =IF(B11="One-Time",G11,J11*12) | L11: =IF(B11="One-Time",0,K11*(1+Metadata!$B$8)) | M11: =IF(B11="One-Time",0,L11*(1+Metadata!$B$8)) | N11: =IF(B11="One-Time",0,M11*(1+Metadata!$B$8)) | O11: =IF(B11="One-Time",0,N11*(1+Metadata!$B$8)) | P11: =IF(B11="One-Time",0,O11*(1+Metadata!$B$8)) | Q11: =IF(B11="One-Time",0,P11*(1+Metadata!$B$8)) | R11: =SUM(K11:Q11)
A12: 56 | B12: Monthly F | C12: Monthly Hosting Fee | D12: Digital | E12: FALSE | F12: FALSE | G12: 750 | H12: per month | J12: =IF(B12="Monthly F",G12,IF(B12="Monthly V",G12*I12,IF(B12="Annual",G12/12,0))) | K12: =IF(B12="One-Time",G12,J12*12) | L12: =IF(B12="One-Time",0,K12*(1+Metadata!$B$8)) | M12: =IF(B12="One-Time",0,L12*(1+Metadata!$B$8)) | N12: =IF(B12="One-Time",0,M12*(1+Metadata!$B$8)) | O12: =IF(B12="One-Time",0,N12*(1+Metadata!$B$8)) | P12: =IF(B12="One-Time",0,O12*(1+Metadata!$B$8)) | Q12: =IF(B12="One-Time",0,P12*(1+Metadata!$B$8)) | R12: =SUM(K12:Q12)
A13: 9 | B13: Monthly F | C13: 3D Secure | D13: EFT | E13: FALSE | F13: FALSE | G13: 435 | H13: per month | J13: =IF(B13="Monthly F",G13,IF(B13="Monthly V",G13*I13,IF(B13="Annual",G13/12,0))) | K13: =IF(B13="One-Time",G13,J13*12) | L13: =IF(B13="One-Time",0,K13*(1+Metadata!$B$8)) | M13: =IF(B13="One-Time",0,L13*(1+Metadata!$B$8)) | N13: =IF(B13="One-Time",0,M13*(1+Metadata!$B$8)) | O13: =IF(B13="One-Time",0,N13*(1+Metadata!$B$8)) | P13: =IF(B13="One-Time",0,O13*(1+Metadata!$B$8)) | Q13: =IF(B13="One-Time",0,P13*(1+Metadata!$B$8)) | R13: =SUM(K13:Q13)
A14: 10 | B14: Monthly F | C14: Card Suite | D14: EFT | E14: FALSE | F14: FALSE | G14: 658 | H14: per user | I14: 1110 | J14: =IF(B14="Monthly F",G14,IF(B14="Monthly V",G14*I14,IF(B14="Annual",G14/12,0))) | K14: =IF(B14="One-Time",G14,J14*12) | L14: =IF(B14="One-Time",0,K14*(1+Metadata!$B$8)) | M14: =IF(B14="One-Time",0,L14*(1+Metadata!$B$8)) | N14: =IF(B14="One-Time",0,M14*(1+Metadata!$B$8)) | O14: =IF(B14="One-Time",0,N14*(1+Metadata!$B$8)) | P14: =IF(B14="One-Time",0,O14*(1+Metadata!$B$8)) | Q14: =IF(B14="One-Time",0,P14*(1+Metadata!$B$8)) | R14: =SUM(K14:Q14)
A15: 8 | B15: Monthly F | C15: FIS EFT Processing - PaymentsOne | D15: EFT | E15: FALSE | F15: FALSE | G15: 10955 | H15: per month | J15: =IF(B15="Monthly F",G15,IF(B15="Monthly V",G15*I15,IF(B15="Annual",G15/12,0))) | K15: =IF(B15="One-Time",G15,J15*12) | L15: =IF(B15="One-Time",0,K15*(1+Metadata!$B$8)) | M15: =IF(B15="One-Time",0,L15*(1+Metadata!$B$8)) | N15: =IF(B15="One-Time",0,M15*(1+Metadata!$B$8)) | O15: =IF(B15="One-Time",0,N15*(1+Metadata!$B$8)) | P15: =IF(B15="One-Time",0,O15*(1+Metadata!$B$8)) | Q15: =IF(B15="One-Time",0,P15*(1+Metadata!$B$8)) | R15: =SUM(K15:Q15)
A16: 11 | B16: Monthly F | C16: SecurLOCK™ Processing | D16: EFT | E16: FALSE | F16: FALSE | G16: 13148 | H16: per month | J16: =IF(B16="Monthly F",G16,IF(B16="Monthly V",G16*I16,IF(B16="Annual",G16/12,0))) | K16: =IF(B16="One-Time",G16,J16*12) | L16: =IF(B16="One-Time",0,K16*(1+Metadata!$B$8)) | M16: =IF(B16="One-Time",0,L16*(1+Metadata!$B$8)) | N16: =IF(B16="One-Time",0,M16*(1+Metadata!$B$8)) | O16: =IF(B16="One-Time",0,N16*(1+Metadata!$B$8)) | P16: =IF(B16="One-Time",0,O16*(1+Metadata!$B$8)) | Q16: =IF(B16="One-Time",0,P16*(1+Metadata!$B$8)) | R16: =SUM(K16:Q16)
A17: 17 | B17: Monthly F | C17: Branch Capture Xpress (BCX) | D17: Item Processing | E17: FALSE | F17: FALSE | G17: 1042 | H17: per device | I17: 10 | J17: =IF(B17="Monthly F",G17,IF(B17="Monthly V",G17*I17,IF(B17="Annual",G17/12,0))) | K17: =IF(B17="One-Time",G17,J17*12) | L17: =IF(B17="One-Time",0,K17*(1+Metadata!$B$8)) | M17: =IF(B17="One-Time",0,L17*(1+Metadata!$B$8)) | N17: =IF(B17="One-Time",0,M17*(1+Metadata!$B$8)) | O17: =IF(B17="One-Time",0,N17*(1+Metadata!$B$8)) | P17: =IF(B17="One-Time",0,O17*(1+Metadata!$B$8)) | Q17: =IF(B17="One-Time",0,P17*(1+Metadata!$B$8)) | R17: =SUM(K17:Q17)
A18: 14 | B18: Monthly F | C18: Content Management (new structure) | D18: Item Processing | E18: FALSE | F18: FALSE | G18: 5294 | H18: per account | I18: 23700 | J18: =IF(B18="Monthly F",G18,IF(B18="Monthly V",G18*I18,IF(B18="Annual",G18/12,0))) | K18: =IF(B18="One-Time",G18,J18*12) | L18: =IF(B18="One-Time",0,K18*(1+Metadata!$B$8)) | M18: =IF(B18="One-Time",0,L18*(1+Metadata!$B$8)) | N18: =IF(B18="One-Time",0,M18*(1+Metadata!$B$8)) | O18: =IF(B18="One-Time",0,N18*(1+Metadata!$B$8)) | P18: =IF(B18="One-Time",0,O18*(1+Metadata!$B$8)) | Q18: =IF(B18="One-Time",0,P18*(1+Metadata!$B$8)) | R18: =SUM(K18:Q18)
A19: 13 | B19: Monthly F | C19: Content Management (old structure) | D19: Item Processing | E19: FALSE | F19: FALSE | G19: 0 | H19: per month | J19: =IF(B19="Monthly F",G19,IF(B19="Monthly V",G19*I19,IF(B19="Annual",G19/12,0))) | K19: =IF(B19="One-Time",G19,J19*12) | L19: =IF(B19="One-Time",0,K19*(1+Metadata!$B$8)) | M19: =IF(B19="One-Time",0,L19*(1+Metadata!$B$8)) | N19: =IF(B19="One-Time",0,M19*(1+Metadata!$B$8)) | O19: =IF(B19="One-Time",0,N19*(1+Metadata!$B$8)) | P19: =IF(B19="One-Time",0,O19*(1+Metadata!$B$8)) | Q19: =IF(B19="One-Time",0,P19*(1+Metadata!$B$8)) | R19: =SUM(K19:Q19)
A20: 19 | B20: Monthly F | C20: FIS DirectLink | D20: Item Processing | E20: FALSE | F20: FALSE | G20: 1006 | H20: per month | J20: =IF(B20="Monthly F",G20,IF(B20="Monthly V",G20*I20,IF(B20="Annual",G20/12,0))) | K20: =IF(B20="One-Time",G20,J20*12) | L20: =IF(B20="One-Time",0,K20*(1+Metadata!$B$8)) | M20: =IF(B20="One-Time",0,L20*(1+Metadata!$B$8)) | N20: =IF(B20="One-Time",0,M20*(1+Metadata!$B$8)) | O20: =IF(B20="One-Time",0,N20*(1+Metadata!$B$8)) | P20: =IF(B20="One-Time",0,O20*(1+Metadata!$B$8)) | Q20: =IF(B20="One-Time",0,P20*(1+Metadata!$B$8)) | R20: =SUM(K20:Q20)
A21: 18 | B21: Monthly F | C21: FIS Xpress Deposit (FXD) | D21: Item Processing | E21: FALSE | F21: FALSE | G21: 867 | H21: per deposit | I21: 352 | J21: =IF(B21="Monthly F",G21,IF(B21="Monthly V",G21*I21,IF(B21="Annual",G21/12,0))) | K21: =IF(B21="One-Time",G21,J21*12) | L21: =IF(B21="One-Time",0,K21*(1+Metadata!$B$8)) | M21: =IF(B21="One-Time",0,L21*(1+Metadata!$B$8)) | N21: =IF(B21="One-Time",0,M21*(1+Metadata!$B$8)) | O21: =IF(B21="One-Time",0,N21*(1+Metadata!$B$8)) | P21: =IF(B21="One-Time",0,O21*(1+Metadata!$B$8)) | Q21: =IF(B21="One-Time",0,P21*(1+Metadata!$B$8)) | R21: =SUM(K21:Q21)
A22: 16 | B22: Monthly F | C22: Item Processing Services (new structure) | D22: Item Processing | E22: FALSE | F22: FALSE | G22: 5257 | H22: per account | I22: 23700 | J22: =IF(B22="Monthly F",G22,IF(B22="Monthly V",G22*I22,IF(B22="Annual",G22/12,0))) | K22: =IF(B22="One-Time",G22,J22*12) | L22: =IF(B22="One-Time",0,K22*(1+Metadata!$B$8)) | M22: =IF(B22="One-Time",0,L22*(1+Metadata!$B$8)) | N22: =IF(B22="One-Time",0,M22*(1+Metadata!$B$8)) | O22: =IF(B22="One-Time",0,N22*(1+Metadata!$B$8)) | P22: =IF(B22="One-Time",0,O22*(1+Metadata!$B$8)) | Q22: =IF(B22="One-Time",0,P22*(1+Metadata!$B$8)) | R22: =SUM(K22:Q22)
A23: 15 | B23: Monthly F | C23: Item Processing Services (old structure) | D23: Item Processing | E23: FALSE | F23: FALSE | G23: 0 | H23: per month | J23: =IF(B23="Monthly F",G23,IF(B23="Monthly V",G23*I23,IF(B23="Annual",G23/12,0))) | K23: =IF(B23="One-Time",G23,J23*12) | L23: =IF(B23="One-Time",0,K23*(1+Metadata!$B$8)) | M23: =IF(B23="One-Time",0,L23*(1+Metadata!$B$8)) | N23: =IF(B23="One-Time",0,M23*(1+Metadata!$B$8)) | O23: =IF(B23="One-Time",0,N23*(1+Metadata!$B$8)) | P23: =IF(B23="One-Time",0,O23*(1+Metadata!$B$8)) | Q23: =IF(B23="One-Time",0,P23*(1+Metadata!$B$8)) | R23: =SUM(K23:Q23)
A24: 20 | B24: Monthly F | C24: Sendpoint Merchant Capture | D24: Item Processing | E24: FALSE | F24: FALSE | G24: 0 | H24: per month | J24: =IF(B24="Monthly F",G24,IF(B24="Monthly V",G24*I24,IF(B24="Annual",G24/12,0))) | K24: =IF(B24="One-Time",G24,J24*12) | L24: =IF(B24="One-Time",0,K24*(1+Metadata!$B$8)) | M24: =IF(B24="One-Time",0,L24*(1+Metadata!$B$8)) | N24: =IF(B24="One-Time",0,M24*(1+Metadata!$B$8)) | O24: =IF(B24="One-Time",0,N24*(1+Metadata!$B$8)) | P24: =IF(B24="One-Time",0,O24*(1+Metadata!$B$8)) | Q24: =IF(B24="One-Time",0,P24*(1+Metadata!$B$8)) | R24: =SUM(K24:Q24)
A25: 22 | B25: Monthly F | C25: AvidAscend | D25: Other | E25: FALSE | F25: FALSE | G25: 597 | H25: per month | J25: =IF(B25="Monthly F",G25,IF(B25="Monthly V",G25*I25,IF(B25="Annual",G25/12,0))) | K25: =IF(B25="One-Time",G25,J25*12) | L25: =IF(B25="One-Time",0,K25*(1+Metadata!$B$8)) | M25: =IF(B25="One-Time",0,L25*(1+Metadata!$B$8)) | N25: =IF(B25="One-Time",0,M25*(1+Metadata!$B$8)) | O25: =IF(B25="One-Time",0,N25*(1+Metadata!$B$8)) | P25: =IF(B25="One-Time",0,O25*(1+Metadata!$B$8)) | Q25: =IF(B25="One-Time",0,P25*(1+Metadata!$B$8)) | R25: =SUM(K25:Q25)
A26: 23 | B26: Monthly F | C26: Card Production | D26: Other | E26: FALSE | F26: FALSE | G26: 3958 | H26: per month | J26: =IF(B26="Monthly F",G26,IF(B26="Monthly V",G26*I26,IF(B26="Annual",G26/12,0))) | K26: =IF(B26="One-Time",G26,J26*12) | L26: =IF(B26="One-Time",0,K26*(1+Metadata!$B$8)) | M26: =IF(B26="One-Time",0,L26*(1+Metadata!$B$8)) | N26: =IF(B26="One-Time",0,M26*(1+Metadata!$B$8)) | O26: =IF(B26="One-Time",0,N26*(1+Metadata!$B$8)) | P26: =IF(B26="One-Time",0,O26*(1+Metadata!$B$8)) | Q26: =IF(B26="One-Time",0,P26*(1+Metadata!$B$8)) | R26: =SUM(K26:Q26)
A27: 21 | B27: Monthly F | C27: FIS Telephone Banking Services - On-Call | D27: Other | E27: FALSE | F27: FALSE | G27: 497 | H27: per month | J27: =IF(B27="Monthly F",G27,IF(B27="Monthly V",G27*I27,IF(B27="Annual",G27/12,0))) | K27: =IF(B27="One-Time",G27,J27*12) | L27: =IF(B27="One-Time",0,K27*(1+Metadata!$B$8)) | M27: =IF(B27="One-Time",0,L27*(1+Metadata!$B$8)) | N27: =IF(B27="One-Time",0,M27*(1+Metadata!$B$8)) | O27: =IF(B27="One-Time",0,N27*(1+Metadata!$B$8)) | P27: =IF(B27="One-Time",0,O27*(1+Metadata!$B$8)) | Q27: =IF(B27="One-Time",0,P27*(1+Metadata!$B$8)) | R27: =SUM(K27:Q27)
A28: 26 | B28: Monthly F | C28: NYCE | D28: Other | E28: FALSE | F28: FALSE | G28: 6688 | H28: per month | J28: =IF(B28="Monthly F",G28,IF(B28="Monthly V",G28*I28,IF(B28="Annual",G28/12,0))) | K28: =IF(B28="One-Time",G28,J28*12) | L28: =IF(B28="One-Time",0,K28*(1+Metadata!$B$8)) | M28: =IF(B28="One-Time",0,L28*(1+Metadata!$B$8)) | N28: =IF(B28="One-Time",0,M28*(1+Metadata!$B$8)) | O28: =IF(B28="One-Time",0,N28*(1+Metadata!$B$8)) | P28: =IF(B28="One-Time",0,O28*(1+Metadata!$B$8)) | Q28: =IF(B28="One-Time",0,P28*(1+Metadata!$B$8)) | R28: =SUM(K28:Q28)
A29: 24 | B29: Monthly F | C29: Network Services | D29: Other | E29: FALSE | F29: FALSE | G29: 3334 | H29: per month | J29: =IF(B29="Monthly F",G29,IF(B29="Monthly V",G29*I29,IF(B29="Annual",G29/12,0))) | K29: =IF(B29="One-Time",G29,J29*12) | L29: =IF(B29="One-Time",0,K29*(1+Metadata!$B$8)) | M29: =IF(B29="One-Time",0,L29*(1+Metadata!$B$8)) | N29: =IF(B29="One-Time",0,M29*(1+Metadata!$B$8)) | O29: =IF(B29="One-Time",0,N29*(1+Metadata!$B$8)) | P29: =IF(B29="One-Time",0,O29*(1+Metadata!$B$8)) | Q29: =IF(B29="One-Time",0,P29*(1+Metadata!$B$8)) | R29: =SUM(K29:Q29)
A30: 27 | B30: Monthly F | C30: Recently Signed/Implemented Services | D30: Other | E30: FALSE | F30: FALSE | G30: 1254 | H30: per month | J30: =IF(B30="Monthly F",G30,IF(B30="Monthly V",G30*I30,IF(B30="Annual",G30/12,0))) | K30: =IF(B30="One-Time",G30,J30*12) | L30: =IF(B30="One-Time",0,K30*(1+Metadata!$B$8)) | M30: =IF(B30="One-Time",0,L30*(1+Metadata!$B$8)) | N30: =IF(B30="One-Time",0,M30*(1+Metadata!$B$8)) | O30: =IF(B30="One-Time",0,N30*(1+Metadata!$B$8)) | P30: =IF(B30="One-Time",0,O30*(1+Metadata!$B$8)) | Q30: =IF(B30="One-Time",0,P30*(1+Metadata!$B$8)) | R30: =SUM(K30:Q30)
A31: 12 | B31: Monthly F | C31: Decision Solutions | D31: Risk, Fraud & Compliance | E31: FALSE | F31: FALSE | G31: 1406 | H31: per month | J31: =IF(B31="Monthly F",G31,IF(B31="Monthly V",G31*I31,IF(B31="Annual",G31/12,0))) | K31: =IF(B31="One-Time",G31,J31*12) | L31: =IF(B31="One-Time",0,K31*(1+Metadata!$B$8)) | M31: =IF(B31="One-Time",0,L31*(1+Metadata!$B$8)) | N31: =IF(B31="One-Time",0,M31*(1+Metadata!$B$8)) | O31: =IF(B31="One-Time",0,N31*(1+Metadata!$B$8)) | P31: =IF(B31="One-Time",0,O31*(1+Metadata!$B$8)) | Q31: =IF(B31="One-Time",0,P31*(1+Metadata!$B$8)) | R31: =SUM(K31:Q31)
A32: 28 | B32: Monthly V | C32: ACH Activity | D32: Core | E32: FALSE | F32: FALSE | G32: 53.06 | H32: per transaction | I32: 10611 | J32: =IF(B32="Monthly F",G32,IF(B32="Monthly V",G32*I32,IF(B32="Annual",G32/12,0))) | K32: =IF(B32="One-Time",G32,J32*12) | L32: =IF(B32="One-Time",0,K32*(1+Metadata!$B$8)) | M32: =IF(B32="One-Time",0,L32*(1+Metadata!$B$8)) | N32: =IF(B32="One-Time",0,M32*(1+Metadata!$B$8)) | O32: =IF(B32="One-Time",0,N32*(1+Metadata!$B$8)) | P32: =IF(B32="One-Time",0,O32*(1+Metadata!$B$8)) | Q32: =IF(B32="One-Time",0,P32*(1+Metadata!$B$8)) | R32: =SUM(K32:Q32)
A33: 53 | B33: Monthly V | C33: Active Monthly User Fee | D33: Digital | E33: FALSE | F33: FALSE | G33: 1312.5 | H33: per user | I33: 875 | J33: =IF(B33="Monthly F",G33,IF(B33="Monthly V",G33*I33,IF(B33="Annual",G33/12,0))) | K33: =IF(B33="One-Time",G33,J33*12) | L33: =IF(B33="One-Time",0,K33*(1+Metadata!$B$8)) | M33: =IF(B33="One-Time",0,L33*(1+Metadata!$B$8)) | N33: =IF(B33="One-Time",0,M33*(1+Metadata!$B$8)) | O33: =IF(B33="One-Time",0,N33*(1+Metadata!$B$8)) | P33: =IF(B33="One-Time",0,O33*(1+Metadata!$B$8)) | Q33: =IF(B33="One-Time",0,P33*(1+Metadata!$B$8)) | R33: =SUM(K33:Q33)
A34: 55 | B34: Monthly V | C34: Checks | D34: Digital | E34: FALSE | F34: FALSE | G34: 1585.78 | H34: per check | I34: 1687 | J34: =IF(B34="Monthly F",G34,IF(B34="Monthly V",G34*I34,IF(B34="Annual",G34/12,0))) | K34: =IF(B34="One-Time",G34,J34*12) | L34: =IF(B34="One-Time",0,K34*(1+Metadata!$B$8)) | M34: =IF(B34="One-Time",0,L34*(1+Metadata!$B$8)) | N34: =IF(B34="One-Time",0,M34*(1+Metadata!$B$8)) | O34: =IF(B34="One-Time",0,N34*(1+Metadata!$B$8)) | P34: =IF(B34="One-Time",0,O34*(1+Metadata!$B$8)) | Q34: =IF(B34="One-Time",0,P34*(1+Metadata!$B$8)) | R34: =SUM(K34:Q34)
A35: 54 | B35: Monthly V | C35: Electronic Payment Transaction Volumes | D35: Digital | E35: FALSE | F35: FALSE | G35: 440.39 | H35: per transaction | I35: 937 | J35: =IF(B35="Monthly F",G35,IF(B35="Monthly V",G35*I35,IF(B35="Annual",G35/12,0))) | K35: =IF(B35="One-Time",G35,J35*12) | L35: =IF(B35="One-Time",0,K35*(1+Metadata!$B$8)) | M35: =IF(B35="One-Time",0,L35*(1+Metadata!$B$8)) | N35: =IF(B35="One-Time",0,M35*(1+Metadata!$B$8)) | O35: =IF(B35="One-Time",0,N35*(1+Metadata!$B$8)) | P35: =IF(B35="One-Time",0,O35*(1+Metadata!$B$8)) | Q35: =IF(B35="One-Time",0,P35*(1+Metadata!$B$8)) | R35: =SUM(K35:Q35)
A36: 52 | B36: Monthly V | C36: Fraud Management | D36: Digital | E36: FALSE | F36: FALSE | G36: 0.03925 | H36: per transaction | I36: 1690 | J36: =IF(B36="Monthly F",G36,IF(B36="Monthly V",G36*I36,IF(B36="Annual",G36/12,0))) | K36: =IF(B36="One-Time",G36,J36*12) | L36: =IF(B36="One-Time",0,K36*(1+Metadata!$B$8)) | M36: =IF(B36="One-Time",0,L36*(1+Metadata!$B$8)) | N36: =IF(B36="One-Time",0,M36*(1+Metadata!$B$8)) | O36: =IF(B36="One-Time",0,N36*(1+Metadata!$B$8)) | P36: =IF(B36="One-Time",0,O36*(1+Metadata!$B$8)) | Q36: =IF(B36="One-Time",0,P36*(1+Metadata!$B$8)) | R36: =SUM(K36:Q36)
A37: 42 | B37: Monthly V | C37: ATM Monitoring User Interface | D37: EFT | E37: FALSE | F37: FALSE | G37: 100 | H37: per ATM | I37: 10 | J37: =IF(B37="Monthly F",G37,IF(B37="Monthly V",G37*I37,IF(B37="Annual",G37/12,0))) | K37: =IF(B37="One-Time",G37,J37*12) | L37: =IF(B37="One-Time",0,K37*(1+Metadata!$B$8)) | M37: =IF(B37="One-Time",0,L37*(1+Metadata!$B$8)) | N37: =IF(B37="One-Time",0,M37*(1+Metadata!$B$8)) | O37: =IF(B37="One-Time",0,N37*(1+Metadata!$B$8)) | P37: =IF(B37="One-Time",0,O37*(1+Metadata!$B$8)) | Q37: =IF(B37="One-Time",0,P37*(1+Metadata!$B$8)) | R37: =SUM(K37:Q37)
A38: 43 | B38: Monthly V | C38: ATM Support | D38: EFT | E38: FALSE | F38: FALSE | G38: 431.07 | H38: per ATM | I38: 10 | J38: =IF(B38="Monthly F",G38,IF(B38="Monthly V",G38*I38,IF(B38="Annual",G38/12,0))) | K38: =IF(B38="One-Time",G38,J38*12) | L38: =IF(B38="One-Time",0,K38*(1+Metadata!$B$8)) | M38: =IF(B38="One-Time",0,L38*(1+Metadata!$B$8)) | N38: =IF(B38="One-Time",0,M38*(1+Metadata!$B$8)) | O38: =IF(B38="One-Time",0,N38*(1+Metadata!$B$8)) | P38: =IF(B38="One-Time",0,O38*(1+Metadata!$B$8)) | Q38: =IF(B38="One-Time",0,P38*(1+Metadata!$B$8)) | R38: =SUM(K38:Q38)
A39: 46 | B39: Monthly V | C39: Affiliate Quarterly Report | D39: EFT | E39: FALSE | F39: FALSE | G39: 35.92 | H39: per report | I39: 1 | J39: =IF(B39="Monthly F",G39,IF(B39="Monthly V",G39*I39,IF(B39="Annual",G39/12,0))) | K39: =IF(B39="One-Time",G39,J39*12) | L39: =IF(B39="One-Time",0,K39*(1+Metadata!$B$8)) | M39: =IF(B39="One-Time",0,L39*(1+Metadata!$B$8)) | N39: =IF(B39="One-Time",0,M39*(1+Metadata!$B$8)) | O39: =IF(B39="One-Time",0,N39*(1+Metadata!$B$8)) | P39: =IF(B39="One-Time",0,O39*(1+Metadata!$B$8)) | Q39: =IF(B39="One-Time",0,P39*(1+Metadata!$B$8)) | R39: =SUM(K39:Q39)
A40: 47 | B40: Monthly V | C40: Billing Account Updater - Accounts on File | D40: EFT | E40: FALSE | F40: FALSE | G40: 106.2 | H40: per institution | I40: 18000 | J40: =IF(B40="Monthly F",G40,IF(B40="Monthly V",G40*I40,IF(B40="Annual",G40/12,0))) | K40: =IF(B40="One-Time",G40,J40*12) | L40: =IF(B40="One-Time",0,K40*(1+Metadata!$B$8)) | M40: =IF(B40="One-Time",0,L40*(1+Metadata!$B$8)) | N40: =IF(B40="One-Time",0,M40*(1+Metadata!$B$8)) | O40: =IF(B40="One-Time",0,N40*(1+Metadata!$B$8)) | P40: =IF(B40="One-Time",0,O40*(1+Metadata!$B$8)) | Q40: =IF(B40="One-Time",0,P40*(1+Metadata!$B$8)) | R40: =SUM(K40:Q40)
...

Sheet Years 1-7
A1: Annual Cost Breakdown (7-Year Projection)
A2: Category | B2: Year 1 | C2: Year 2 | D2: Year 3 | E2: Year 4 | F2: Year 5 | G2: Year 6 | H2: Year 7
A3: Required Annual Fees | B3: =SUMIFS('Line Items'!$K:$K,'Line Items'!$F:$F,FALSE) | C3: =SUMIFS('Line Items'!$L:$L,'Line Items'!$F:$F,FALSE) | D3: =SUMIFS('Line Items'!$M:$M,'Line Items'!$F:$F,FALSE) | E3: =SUMIFS('Line Items'!$N:$N,'Line Items'!$F:$F,FALSE) | F3: =SUMIFS('Line Items'!$O:$O,'Line Items'!$F:$F,FALSE) | G3: =SUMIFS('Line Items'!$P:$P,'Line Items'!$F:$F,FALSE) | H3: =SUMIFS('Line Items'!$Q:$Q,'Line Items'!$F:$F,FALSE)
A4: Optional Annual Fees | B4: =SUMIFS('Line Items'!$K:$K,'Line Items'!$F:$F,TRUE) | C4: =SUMIFS('Line Items'!$L:$L,'Line Items'!$F:$F,TRUE) | D4: =SUMIFS('Line Items'!$M:$M,'Line Items'!$F:$F,TRUE) | E4: =SUMIFS('Line Items'!$N:$N,'Line Items'!$F:$F,TRUE) | F4: =SUMIFS('Line Items'!$O:$O,'Line Items'!$F:$F,TRUE) | G4: =SUMIFS('Line Items'!$P:$P,'Line Items'!$F:$F,TRUE) | H4: =SUMIFS('Line Items'!$Q:$Q,'Line Items'!$F:$F,TRUE)
A5: Total Annual Cost | B5: =B3+B4 | C5: =C3+C4 | D5: =D3+D4 | E5: =E3+E4 | F5: =F3+F4 | G5: =G3+G4 | H5: =H3+H4

Sheet Summary
A1: Total Cost of Ownership (TCO) Summary
A2: Vendor: | B2: =Metadata!B2
A4: Category | B4: 7-Year Total | C4: Monthly Average
A5: Core | B5: =SUMIFS('Line Items'!$R:$R,'Line Items'!$D:$D,A5) | C5: =B5/84
A6: Digital | B6: =SUMIFS('Line Items'!$R:$R,'Line Items'!$D:$D,A6) | C6: =B6/84
A7: EFT | B7: =SUMIFS('Line Items'!$R:$R,'Line Items'!$D:$D,A7) | C7: =B7/84
A8: Item Processing | B8: =SUMIFS('Line Items'!$R:$R,'Line Items'!$D:$D,A8) | C8: =B8/84
A9: Other | B9: =SUMIFS('Line Items'!$R:$R,'Line Items'!$D:$D,A9) | C9: =B9/84
A10: Risk, Fraud & Compliance | B10: =SUMIFS('Line Items'!$R:$R,'Line Items'!$D:$D,A10) | C10: =B10/84
A12: Total Required TCO | B12: =SUM(B5:B10) | C12: =B12/84
A14: Grand Total (Required + Optional)

Sheet Metadata
A1: TCO Analysis - Proposal Metadata
A2: Primary Vendor: | B2: FIS
A3: Client Name: | B3: First State Bank
A4: Proposal Type: | B4: N/A
A5: Proposal Date: | B5: 2024-03-21
A6: Contract Term (Years): | B6: 7
A7: Annual Growth Rate: | B7: 0.02
A8: Annual CPI Rate: | B8: 0.02
A10: Data Extraction Date: | B10: 2025-12-18 08:50:22
A12: Source Proposal File: | B12: N/A
