Workbook

Sheet Line Items
A1: Row ID | B1: Fee Type | C1: Solution Name | D1: Category | E1: Third Party | F1: Optional | G1: Per Unit Rate | H1: Unit Description | I1: Avg Monthly Qty | J1: Year 1 Monthly | K1: Year 1 Annual | L1: Year 2 | M1: Year 3 | N1: Year 4 | O1: Year 5 | P1: Year 6 | Q1: Year 7 | R1: Total 7-Year Cost | S1: Confidence | T1: Notes
A2: 8 | B2: Annual | C2: CSI Annual Forms & Statements | D2: Other | E2: FALSE | F2: FALSE | G2: 170.33 | H2: per year | J2: =IF(B2="Monthly F",G2,IF(B2="Monthly V",G2*I2,IF(B2="Annual",G2/12,0))) | K2: =IF(B2="One-Time",G2,J2*12) | L2: =IF(B2="One-Time",0,K2*(1+Metadata!$B$8)) | M2: =IF(B2="One-Time",0,L2*(1+Metadata!$B$8)) | N2: =IF(B2="One-Time",0,M2*(1+Metadata!$B$8)) | O2: =IF(B2="One-Time",0,N2*(1+Metadata!$B$8)) | P2: =IF(B2="One-Time",0,O2*(1+Metadata!$B$8)) | Q2: =IF(B2="One-Time",0,P2*(1+Metadata!$B$8)) | R2: =SUM(K2:Q2) | S2: 0.95 | T2: Annual fee of $2,044 converted to monthly equivalent
A3: 5 | B3: Monthly F | C3: CSI Fees Included in Organic Growth Based Pricing | D3: Core | E3: FALSE | F3: FALSE | G3: 38663 | H3: per month | J3: =IF(B3="Monthly F",G3,IF(B3="Monthly V",G3*I3,IF(B3="Annual",G3/12,0))) | K3: =IF(B3="One-Time",G3,J3*12) | L3: =IF(B3="One-Time",0,K3*(1+Metadata!$B$8)) | M3: =IF(B3="One-Time",0,L3*(1+Metadata!$B$8)) | N3: =IF(B3="One-Time",0,M3*(1+Metadata!$B$8)) | O3: =IF(B3="One-Time",0,N3*(1+Metadata!$B$8)) | P3: =IF(B3="One-Time",0,O3*(1+Metadata!$B$8)) | Q3: =IF(B3="One-Time",0,P3*(1+Metadata!$B$8)) | R3: =SUM(K3:Q3) | S3: 0.95 | T3: Core processing fees under organic growth pricing
A4: 7 | B4: Monthly F | C4: Monthly Equipment Fees | D4: Item Processing | E4: FALSE | F4: FALSE | G4: 250 | H4: per month | J4: =IF(B4="Monthly F",G4,IF(B4="Monthly V",G4*I4,IF(B4="Annual",G4/12,0))) | K4: =IF(B4="One-Time",G4,J4*12) | L4: =IF(B4="One-Time",0,K4*(1+Metadata!$B$8)) | M4: =IF(B4="One-Time",0,L4*(1+Metadata!$B$8)) | N4: =IF(B4="One-Time",0,M4*(1+Metadata!$B$8)) | O4: =IF(B4="One-Time",0,N4*(1+Metadata!$B$8)) | P4: =IF(B4="One-Time",0,O4*(1+Metadata!$B$8)) | Q4: =IF(B4="One-Time",0,P4*(1+Metadata!$B$8)) | R4: =SUM(K4:Q4) | S4: 0.95 | T4: Monthly equipment rental/maintenance
A5: 6 | B5: Monthly F | C5: Other Processing Fees | D5: Other | E5: FALSE | F5: FALSE | G5: 12734 | H5: per month | J5: =IF(B5="Monthly F",G5,IF(B5="Monthly V",G5*I5,IF(B5="Annual",G5/12,0))) | K5: =IF(B5="One-Time",G5,J5*12) | L5: =IF(B5="One-Time",0,K5*(1+Metadata!$B$8)) | M5: =IF(B5="One-Time",0,L5*(1+Metadata!$B$8)) | N5: =IF(B5="One-Time",0,M5*(1+Metadata!$B$8)) | O5: =IF(B5="One-Time",0,N5*(1+Metadata!$B$8)) | P5: =IF(B5="One-Time",0,O5*(1+Metadata!$B$8)) | Q5: =IF(B5="One-Time",0,P5*(1+Metadata!$B$8)) | R5: =SUM(K5:Q5) | S5: 0.95 | T5: Additional processing fees
A6: 2 | B6: One-Time | C6: Equipment Fees - Implementation Fee | D6: Item Processing | E6: FALSE | F6: FALSE | G6: 76933 | H6: one-time | J6: =IF(B6="Monthly F",G6,IF(B6="Monthly V",G6*I6,IF(B6="Annual",G6/12,0))) | K6: =IF(B6="One-Time",G6,J6*12) | L6: =IF(B6="One-Time",0,K6*(1+Metadata!$B$8)) | M6: =IF(B6="One-Time",0,L6*(1+Metadata!$B$8)) | N6: =IF(B6="One-Time",0,M6*(1+Metadata!$B$8)) | O6: =IF(B6="One-Time",0,N6*(1+Metadata!$B$8)) | P6: =IF(B6="One-Time",0,O6*(1+Metadata!$B$8)) | Q6: =IF(B6="One-Time",0,P6*(1+Metadata!$B$8)) | R6: =SUM(K6:Q6) | S6: 0.95 | T6: Hardware and equipment costs
A7: 1 | B7: One-Time | C7: CSI One-Time Fee - Implementation Fee | D7: Other | E7: FALSE | F7: FALSE | G7: 261102 | H7: one-time | J7: =IF(B7="Monthly F",G7,IF(B7="Monthly V",G7*I7,IF(B7="Annual",G7/12,0))) | K7: =IF(B7="One-Time",G7,J7*12) | L7: =IF(B7="One-Time",0,K7*(1+Metadata!$B$8)) | M7: =IF(B7="One-Time",0,L7*(1+Metadata!$B$8)) | N7: =IF(B7="One-Time",0,M7*(1+Metadata!$B$8)) | O7: =IF(B7="One-Time",0,N7*(1+Metadata!$B$8)) | P7: =IF(B7="One-Time",0,O7*(1+Metadata!$B$8)) | Q7: =IF(B7="One-Time",0,P7*(1+Metadata!$B$8)) | R7: =SUM(K7:Q7) | S7: 0.95 | T7: Base implementation fee
A8: 3 | B8: One-Time | C8: Credit for One-Time Fees - Implementation Fee | D8: Other | E8: FALSE | F8: FALSE | G8: -338034 | H8: one-time | J8: =IF(B8="Monthly F",G8,IF(B8="Monthly V",G8*I8,IF(B8="Annual",G8/12,0))) | K8: =IF(B8="One-Time",G8,J8*12) | L8: =IF(B8="One-Time",0,K8*(1+Metadata!$B$8)) | M8: =IF(B8="One-Time",0,L8*(1+Metadata!$B$8)) | N8: =IF(B8="One-Time",0,M8*(1+Metadata!$B$8)) | O8: =IF(B8="One-Time",0,N8*(1+Metadata!$B$8)) | P8: =IF(B8="One-Time",0,O8*(1+Metadata!$B$8)) | Q8: =IF(B8="One-Time",0,P8*(1+Metadata!$B$8)) | R8: =SUM(K8:Q8) | S8: 0.95 | T8: Credit applied to implementation fees
A9: 4 | B9: One-Time | C9: Special Incentive Billing Credit - Implementation Fee | D9: Other | E9: FALSE | F9: FALSE | G9: -375000 | H9: one-time | J9: =IF(B9="Monthly F",G9,IF(B9="Monthly V",G9*I9,IF(B9="Annual",G9/12,0))) | K9: =IF(B9="One-Time",G9,J9*12) | L9: =IF(B9="One-Time",0,K9*(1+Metadata!$B$8)) | M9: =IF(B9="One-Time",0,L9*(1+Metadata!$B$8)) | N9: =IF(B9="One-Time",0,M9*(1+Metadata!$B$8)) | O9: =IF(B9="One-Time",0,N9*(1+Metadata!$B$8)) | P9: =IF(B9="One-Time",0,O9*(1+Metadata!$B$8)) | Q9: =IF(B9="One-Time",0,P9*(1+Metadata!$B$8)) | R9: =SUM(K9:Q9) | S9: 0.95 | T9: Special incentive credit
A10: 17 | B10: Monthly F | C10: PLUS Network Sponsorship | D10: Network | E10: FALSE | F10: TRUE | G10: 50 | H10: per month | J10: =IF(B10="Monthly F",G10,IF(B10="Monthly V",G10*I10,IF(B10="Annual",G10/12,0))) | K10: =IF(B10="One-Time",G10,J10*12) | L10: =IF(B10="One-Time",0,K10*(1+Metadata!$B$8)) | M10: =IF(B10="One-Time",0,L10*(1+Metadata!$B$8)) | N10: =IF(B10="One-Time",0,M10*(1+Metadata!$B$8)) | O10: =IF(B10="One-Time",0,N10*(1+Metadata!$B$8)) | P10: =IF(B10="One-Time",0,O10*(1+Metadata!$B$8)) | Q10: =IF(B10="One-Time",0,P10*(1+Metadata!$B$8)) | R10: =SUM(K10:Q10) | S10: 0.95 | T10: Fixed monthly network sponsorship fee
A11: 27 | B11: Monthly F | C11: Call Report File Download (SmartCall) | D11: Other | E11: FALSE | F11: TRUE | G11: 100 | H11: per month | J11: =IF(B11="Monthly F",G11,IF(B11="Monthly V",G11*I11,IF(B11="Annual",G11/12,0))) | K11: =IF(B11="One-Time",G11,J11*12) | L11: =IF(B11="One-Time",0,K11*(1+Metadata!$B$8)) | M11: =IF(B11="One-Time",0,L11*(1+Metadata!$B$8)) | N11: =IF(B11="One-Time",0,M11*(1+Metadata!$B$8)) | O11: =IF(B11="One-Time",0,N11*(1+Metadata!$B$8)) | P11: =IF(B11="One-Time",0,O11*(1+Metadata!$B$8)) | Q11: =IF(B11="One-Time",0,P11*(1+Metadata!$B$8)) | R11: =SUM(K11:Q11) | S11: 0.95 | T11: Fixed monthly fee for call report downloads
A12: 31 | B12: Monthly F | C12: WatchDog CIP License | D12: Risk, Fraud & Compliance | E12: FALSE | F12: TRUE | G12: 250 | H12: per month | J12: =IF(B12="Monthly F",G12,IF(B12="Monthly V",G12*I12,IF(B12="Annual",G12/12,0))) | K12: =IF(B12="One-Time",G12,J12*12) | L12: =IF(B12="One-Time",0,K12*(1+Metadata!$B$8)) | M12: =IF(B12="One-Time",0,L12*(1+Metadata!$B$8)) | N12: =IF(B12="One-Time",0,M12*(1+Metadata!$B$8)) | O12: =IF(B12="One-Time",0,N12*(1+Metadata!$B$8)) | P12: =IF(B12="One-Time",0,O12*(1+Metadata!$B$8)) | Q12: =IF(B12="One-Time",0,P12*(1+Metadata!$B$8)) | R12: =SUM(K12:Q12) | S12: 0.9 | T12: Annual license fee of $249.58 shown as monthly equivalent
A13: 25 | B13: Monthly V | C13: Mobile Banking Push Notifications | D13: Digital | E13: FALSE | F13: TRUE | G13: 220 | H13: per notification | I13: 1 | J13: =IF(B13="Monthly F",G13,IF(B13="Monthly V",G13*I13,IF(B13="Annual",G13/12,0))) | K13: =IF(B13="One-Time",G13,J13*12) | L13: =IF(B13="One-Time",0,K13*(1+Metadata!$B$8)) | M13: =IF(B13="One-Time",0,L13*(1+Metadata!$B$8)) | N13: =IF(B13="One-Time",0,M13*(1+Metadata!$B$8)) | O13: =IF(B13="One-Time",0,N13*(1+Metadata!$B$8)) | P13: =IF(B13="One-Time",0,O13*(1+Metadata!$B$8)) | Q13: =IF(B13="One-Time",0,P13*(1+Metadata!$B$8)) | R13: =SUM(K13:Q13) | S13: 0.9 | T13: 600 notifications at $0.20 each ($100 base fee included)
A14: 24 | B14: Monthly V | C14: Mobile Deposit | D14: Digital | E14: FALSE | F14: TRUE | G14: 583 | H14: per deposit | I14: 1 | J14: =IF(B14="Monthly F",G14,IF(B14="Monthly V",G14*I14,IF(B14="Annual",G14/12,0))) | K14: =IF(B14="One-Time",G14,J14*12) | L14: =IF(B14="One-Time",0,K14*(1+Metadata!$B$8)) | M14: =IF(B14="One-Time",0,L14*(1+Metadata!$B$8)) | N14: =IF(B14="One-Time",0,M14*(1+Metadata!$B$8)) | O14: =IF(B14="One-Time",0,N14*(1+Metadata!$B$8)) | P14: =IF(B14="One-Time",0,O14*(1+Metadata!$B$8)) | Q14: =IF(B14="One-Time",0,P14*(1+Metadata!$B$8)) | R14: =SUM(K14:Q14) | S14: 0.9 | T14: 1,416 deposits at $0.55 per deposit ($525 base fee included)
A15: 23 | B15: Monthly V | C15: Out of Band Authentication (OOBA) | D15: Digital | E15: FALSE | F15: TRUE | G15: 401 | H15: per authentication | I15: 1 | J15: =IF(B15="Monthly F",G15,IF(B15="Monthly V",G15*I15,IF(B15="Annual",G15/12,0))) | K15: =IF(B15="One-Time",G15,J15*12) | L15: =IF(B15="One-Time",0,K15*(1+Metadata!$B$8)) | M15: =IF(B15="One-Time",0,L15*(1+Metadata!$B$8)) | N15: =IF(B15="One-Time",0,M15*(1+Metadata!$B$8)) | O15: =IF(B15="One-Time",0,N15*(1+Metadata!$B$8)) | P15: =IF(B15="One-Time",0,O15*(1+Metadata!$B$8)) | Q15: =IF(B15="One-Time",0,P15*(1+Metadata!$B$8)) | R15: =SUM(K15:Q15) | S15: 0.85 | T15: 2,027 + 10,730 + 51 + 3,223 authentications at $0.05 each ($300 base fee included)
A16: 13 | B16: Monthly V | C16: Card Production - Instant Issue | D16: EFT | E16: FALSE | F16: TRUE | G16: 81 | H16: per card | I16: 1 | J16: =IF(B16="Monthly F",G16,IF(B16="Monthly V",G16*I16,IF(B16="Annual",G16/12,0))) | K16: =IF(B16="One-Time",G16,J16*12) | L16: =IF(B16="One-Time",0,K16*(1+Metadata!$B$8)) | M16: =IF(B16="One-Time",0,L16*(1+Metadata!$B$8)) | N16: =IF(B16="One-Time",0,M16*(1+Metadata!$B$8)) | O16: =IF(B16="One-Time",0,N16*(1+Metadata!$B$8)) | P16: =IF(B16="One-Time",0,O16*(1+Metadata!$B$8)) | Q16: =IF(B16="One-Time",0,P16*(1+Metadata!$B$8)) | R16: =SUM(K16:Q16) | S16: 0.9 | T16: 108 cards at $0.75 per card
A17: 16 | B17: Monthly V | C17: Contactless EMV Card Production Fee | D17: EFT | E17: FALSE | F17: TRUE | G17: 68 | H17: per card | I17: 1 | J17: =IF(B17="Monthly F",G17,IF(B17="Monthly V",G17*I17,IF(B17="Annual",G17/12,0))) | K17: =IF(B17="One-Time",G17,J17*12) | L17: =IF(B17="One-Time",0,K17*(1+Metadata!$B$8)) | M17: =IF(B17="One-Time",0,L17*(1+Metadata!$B$8)) | N17: =IF(B17="One-Time",0,M17*(1+Metadata!$B$8)) | O17: =IF(B17="One-Time",0,N17*(1+Metadata!$B$8)) | P17: =IF(B17="One-Time",0,O17*(1+Metadata!$B$8)) | Q17: =IF(B17="One-Time",0,P17*(1+Metadata!$B$8)) | R17: =SUM(K17:Q17) | S17: 0.85 | T17: 22,710 cards at $0.003 per card (calculated from $68 monthly)
A18: 15 | B18: Monthly V | C18: EFT Processing Fees - Primary Network | D18: EFT | E18: FALSE | F18: TRUE | G18: 514 | H18: per transaction | I18: 1 | J18: =IF(B18="Monthly F",G18,IF(B18="Monthly V",G18*I18,IF(B18="Annual",G18/12,0))) | K18: =IF(B18="One-Time",G18,J18*12) | L18: =IF(B18="One-Time",0,K18*(1+Metadata!$B$8)) | M18: =IF(B18="One-Time",0,L18*(1+Metadata!$B$8)) | N18: =IF(B18="One-Time",0,M18*(1+Metadata!$B$8)) | O18: =IF(B18="One-Time",0,N18*(1+Metadata!$B$8)) | P18: =IF(B18="One-Time",0,O18*(1+Metadata!$B$8)) | Q18: =IF(B18="One-Time",0,P18*(1+Metadata!$B$8)) | R18: =SUM(K18:Q18) | S18: 0.9 | T18: 41,101 transactions at $0.01 per transaction
A19: 14 | B19: Monthly V | C19: EMV Card Production Fee | D19: EFT | E19: FALSE | F19: TRUE | G19: 73 | H19: per card | I19: 1 | J19: =IF(B19="Monthly F",G19,IF(B19="Monthly V",G19*I19,IF(B19="Annual",G19/12,0))) | K19: =IF(B19="One-Time",G19,J19*12) | L19: =IF(B19="One-Time",0,K19*(1+Metadata!$B$8)) | M19: =IF(B19="One-Time",0,L19*(1+Metadata!$B$8)) | N19: =IF(B19="One-Time",0,M19*(1+Metadata!$B$8)) | O19: =IF(B19="One-Time",0,N19*(1+Metadata!$B$8)) | P19: =IF(B19="One-Time",0,O19*(1+Metadata!$B$8)) | Q19: =IF(B19="One-Time",0,P19*(1+Metadata!$B$8)) | R19: =SUM(K19:Q19) | S19: 0.9 | T19: 3,672 cards at $0.02 per card
A20: 12 | B20: Monthly V | C20: PIN Change | D20: EFT | E20: FALSE | F20: TRUE | G20: 85 | H20: per change | I20: 1 | J20: =IF(B20="Monthly F",G20,IF(B20="Monthly V",G20*I20,IF(B20="Annual",G20/12,0))) | K20: =IF(B20="One-Time",G20,J20*12) | L20: =IF(B20="One-Time",0,K20*(1+Metadata!$B$8)) | M20: =IF(B20="One-Time",0,L20*(1+Metadata!$B$8)) | N20: =IF(B20="One-Time",0,M20*(1+Metadata!$B$8)) | O20: =IF(B20="One-Time",0,N20*(1+Metadata!$B$8)) | P20: =IF(B20="One-Time",0,O20*(1+Metadata!$B$8)) | Q20: =IF(B20="One-Time",0,P20*(1+Metadata!$B$8)) | R20: =SUM(K20:Q20) | S20: 0.9 | T20: 85 changes at $1.00 per change
A21: 10 | B21: Monthly V | C21: A2iA CAR/LAR | D21: Image Solutions | E21: FALSE | F21: TRUE | G21: 767 | H21: per item | I21: 1 | J21: =IF(B21="Monthly F",G21,IF(B21="Monthly V",G21*I21,IF(B21="Annual",G21/12,0))) | K21: =IF(B21="One-Time",G21,J21*12) | L21: =IF(B21="One-Time",0,K21*(1+Metadata!$B$8)) | M21: =IF(B21="One-Time",0,L21*(1+Metadata!$B$8)) | N21: =IF(B21="One-Time",0,M21*(1+Metadata!$B$8)) | O21: =IF(B21="One-Time",0,N21*(1+Metadata!$B$8)) | P21: =IF(B21="One-Time",0,O21*(1+Metadata!$B$8)) | Q21: =IF(B21="One-Time",0,P21*(1+Metadata!$B$8)) | R21: =SUM(K21:Q21) | S21: 0.9 | T21: 5,897 items at $0.13 per item
A22: 9 | B22: Monthly V | C22: Image Capture Processing Fees | D22: Image Solutions | E22: FALSE | F22: TRUE | G22: 186 | H22: per item | I22: 1 | J22: =IF(B22="Monthly F",G22,IF(B22="Monthly V",G22*I22,IF(B22="Annual",G22/12,0))) | K22: =IF(B22="One-Time",G22,J22*12) | L22: =IF(B22="One-Time",0,K22*(1+Metadata!$B$8)) | M22: =IF(B22="One-Time",0,L22*(1+Metadata!$B$8)) | N22: =IF(B22="One-Time",0,M22*(1+Metadata!$B$8)) | O22: =IF(B22="One-Time",0,N22*(1+Metadata!$B$8)) | P22: =IF(B22="One-Time",0,O22*(1+Metadata!$B$8)) | Q22: =IF(B22="One-Time",0,P22*(1+Metadata!$B$8)) | R22: =SUM(K22:Q22) | S22: 0.9 | T22: 23,248 items at $0.008 per item
A23: 34 | B23: Monthly V | C23: CSI Wire | D23: Other | E23: FALSE | F23: TRUE | G23: 3577 | H23: per wire | I23: 1 | J23: =IF(B23="Monthly F",G23,IF(B23="Monthly V",G23*I23,IF(B23="Annual",G23/12,0))) | K23: =IF(B23="One-Time",G23,J23*12) | L23: =IF(B23="One-Time",0,K23*(1+Metadata!$B$8)) | M23: =IF(B23="One-Time",0,L23*(1+Metadata!$B$8)) | N23: =IF(B23="One-Time",0,M23*(1+Metadata!$B$8)) | O23: =IF(B23="One-Time",0,N23*(1+Metadata!$B$8)) | P23: =IF(B23="One-Time",0,O23*(1+Metadata!$B$8)) | Q23: =IF(B23="One-Time",0,P23*(1+Metadata!$B$8)) | R23: =SUM(K23:Q23) | S23: 0.85 | T23: 1,022 wires at $3.50 per wire plus $300 base fee
A24: 29 | B24: Monthly V | C24: FMS Margin Performer | D24: Other | E24: FALSE | F24: TRUE | G24: 326 | H24: per record | I24: 1 | J24: =IF(B24="Monthly F",G24,IF(B24="Monthly V",G24*I24,IF(B24="Annual",G24/12,0))) | K24: =IF(B24="One-Time",G24,J24*12) | L24: =IF(B24="One-Time",0,K24*(1+Metadata!$B$8)) | M24: =IF(B24="One-Time",0,L24*(1+Metadata!$B$8)) | N24: =IF(B24="One-Time",0,M24*(1+Metadata!$B$8)) | O24: =IF(B24="One-Time",0,N24*(1+Metadata!$B$8)) | P24: =IF(B24="One-Time",0,O24*(1+Metadata!$B$8)) | Q24: =IF(B24="One-Time",0,P24*(1+Metadata!$B$8)) | R24: =SUM(K24:Q24) | S24: 0.85 | T24: 10,874 records at $0.03 per record ($250 minimum)
... A29: 33 | B29: Monthly V | C29: Out of Wallet Transactions | D29: Risk, Fraud & Compliance | E29: FALSE | F29: TRUE | G29: 98 | H29: per transaction | I29: 1 | J29: =IF(B29="Monthly F",G29,IF(B29="Monthly V",G29*I29,IF(B29="Annual",G29/12,0))) | K29: =IF(B29="One-Time",G29,J29*12) | L29: =IF(B29="One-Time",0,K29*(1+Metadata!$B$8)) | M29: =IF(B29="One-Time",0,L29*(1+Metadata!$B$8)) | N29: =IF(B29="One-Time",0,M29*(1+Metadata!$B$8)) | O29: =IF(B29="One-Time",0,N29*(1+Metadata!$B$8)) | P29: =IF(B29="One-Time",0,O29*(1+Metadata!$B$8)) | Q29: =IF(B29="One-Time",0,P29*(1+Metadata!$B$8)) | R29: =SUM(K29:Q29) | S29: 0.9 | T29: 39 transactions at $2.50 per transaction
A30: 26 | B30: Monthly F | C30: Digital Chat - LinkLive | D30: Digital | E30: TRUE | F30: TRUE | G30: 102 | H30: per month | J30: =IF(B30="Monthly F",G30,IF(B30="Monthly V",G30*I30,IF(B30="Annual",G30/12,0))) | K30: =IF(B30="One-Time",G30,J30*12) | L30: =IF(B30="One-Time",0,K30*(1+Metadata!$B$8)) | M30: =IF(B30="One-Time",0,L30*(1+Metadata!$B$8)) | N30: =IF(B30="One-Time",0,M30*(1+Metadata!$B$8)) | O30: =IF(B30="One-Time",0,N30*(1+Metadata!$B$8)) | P30: =IF(B30="One-Time",0,O30*(1+Metadata!$B$8)) | Q30: =IF(B30="One-Time",0,P30*(1+Metadata!$B$8)) | R30: =SUM(K30:Q30) | S30: 0.9 | T30: Fixed monthly fee for embedded chat package
A31: 22 | B31: Monthly F | C31: Quicken & QuickBooks Direct Connect | D31: Digital | E31: TRUE | F31: TRUE | G31: 737 | H31: per month | J31: =IF(B31="Monthly F",G31,IF(B31="Monthly V",G31*I31,IF(B31="Annual",G31/12,0))) | K31: =IF(B31="One-Time",G31,J31*12) | L31: =IF(B31="One-Time",0,K31*(1+Metadata!$B$8)) | M31: =IF(B31="One-Time",0,L31*(1+Metadata!$B$8)) | N31: =IF(B31="One-Time",0,M31*(1+Metadata!$B$8)) | O31: =IF(B31="One-Time",0,N31*(1+Metadata!$B$8)) | P31: =IF(B31="One-Time",0,O31*(1+Metadata!$B$8)) | Q31: =IF(B31="One-Time",0,P31*(1+Metadata!$B$8)) | R31: =SUM(K31:Q31) | S31: 0.9 | T31: Fixed monthly fee of $736.67
A32: 20 | B32: Monthly V | C32: Integrated PFM | D32: Digital | E32: TRUE | F32: TRUE | G32: 353 | H32: per user | I32: 1 | J32: =IF(B32="Monthly F",G32,IF(B32="Monthly V",G32*I32,IF(B32="Annual",G32/12,0))) | K32: =IF(B32="One-Time",G32,J32*12) | L32: =IF(B32="One-Time",0,K32*(1+Metadata!$B$8)) | M32: =IF(B32="One-Time",0,L32*(1+Metadata!$B$8)) | N32: =IF(B32="One-Time",0,M32*(1+Metadata!$B$8)) | O32: =IF(B32="One-Time",0,N32*(1+Metadata!$B$8)) | P32: =IF(B32="One-Time",0,O32*(1+Metadata!$B$8)) | Q32: =IF(B32="One-Time",0,P32*(1+Metadata!$B$8)) | R32: =SUM(K32:Q32) | S32: 0.9 | T32: 470 users at $0.75 per user
A33: 21 | B33: Monthly V | C33: Integrated PFM + Aggregation | D33: Digital | E33: TRUE | F33: TRUE | G33: 94 | H33: per user | I33: 1 | J33: =IF(B33="Monthly F",G33,IF(B33="Monthly V",G33*I33,IF(B33="Annual",G33/12,0))) | K33: =IF(B33="One-Time",G33,J33*12) | L33: =IF(B33="One-Time",0,K33*(1+Metadata!$B$8)) | M33: =IF(B33="One-Time",0,L33*(1+Metadata!$B$8)) | N33: =IF(B33="One-Time",0,M33*(1+Metadata!$B$8)) | O33: =IF(B33="One-Time",0,N33*(1+Metadata!$B$8)) | P33: =IF(B33="One-Time",0,O33*(1+Metadata!$B$8)) | Q33: =IF(B33="One-Time",0,P33*(1+Metadata!$B$8)) | R33: =SUM(K33:Q33) | S33: 0.9 | T33: 94 users at $1.00 per user
A34: 19 | B34: Monthly V | C34: iPay Business Bill Pay Program | D34: Digital | E34: TRUE | F34: TRUE | G34: 738 | H34: per user + per payment | I34: 1 | J34: =IF(B34="Monthly F",G34,IF(B34="Monthly V",G34*I34,IF(B34="Annual",G34/12,0))) | K34: =IF(B34="One-Time",G34,J34*12) | L34: =IF(B34="One-Time",0,K34*(1+Metadata!$B$8)) | M34: =IF(B34="One-Time",0,L34*(1+Metadata!$B$8)) | N34: =IF(B34="One-Time",0,M34*(1+Metadata!$B$8)) | O34: =IF(B34="One-Time",0,N34*(1+Metadata!$B$8)) | P34: =IF(B34="One-Time",0,O34*(1+Metadata!$B$8)) | Q34: =IF(B34="One-Time",0,P34*(1+Metadata!$B$8)) | R34: =SUM(K34:Q34) | S34: 0.85 | T34: 102 users at $5.95 + 290 payments at $0.45 ($300 minimum)
A35: 18 | B35: Monthly V | C35: iPay Online Bill Pay | D35: Digital | E35: TRUE | F35: TRUE | G35: 1328 | H35: per user | I35: 1 | J35: =IF(B35="Monthly F",G35,IF(B35="Monthly V",G35*I35,IF(B35="Annual",G35/12,0))) | K35: =IF(B35="One-Time",G35,J35*12) | L35: =IF(B35="One-Time",0,K35*(1+Metadata!$B$8)) | M35: =IF(B35="One-Time",0,L35*(1+Metadata!$B$8)) | N35: =IF(B35="One-Time",0,M35*(1+Metadata!$B$8)) | O35: =IF(B35="One-Time",0,N35*(1+Metadata!$B$8)) | P35: =IF(B35="One-Time",0,O35*(1+Metadata!$B$8)) | Q35: =IF(B35="One-Time",0,P35*(1+Metadata!$B$8)) | R35: =SUM(K35:Q35) | S35: 0.9 | T35: 1,398 users at $0.95 per user

Sheet Years 1-7
A1: Annual Cost Breakdown (7-Year Projection)
A2: Category | B2: Year 1 | C2: Year 2 | D2: Year 3 | E2: Year 4 | F2: Year 5 | G2: Year 6 | H2: Year 7
A3: Required Annual Fees | B3: =SUMIFS('Line Items'!$K:$K,'Line Items'!$F:$F,FALSE) | C3: =SUMIFS('Line Items'!$L:$L,'Line Items'!$F:$F,FALSE) | D3: =SUMIFS('Line Items'!$M:$M,'Line Items'!$F:$F,FALSE) | E3: =SUMIFS('Line Items'!$N:$N,'Line Items'!$F:$F,FALSE) | F3: =SUMIFS('Line Items'!$O:$O,'Line Items'!$F:$F,FALSE) | G3: =SUMIFS('Line Items'!$P:$P,'Line Items'!$F:$F,FALSE) | H3: =SUMIFS('Line Items'!$Q:$Q,'Line Items'!$F:$F,FALSE)
A4: Optional Annual Fees | B4: =SUMIFS('Line Items'!$K:$K,'Line Items'!$F:$F,TRUE) | C4: =SUMIFS('Line Items'!$L:$L,'Line Items'!$F:$F,TRUE) | D4: =SUMIFS('Line Items'!$M:$M,'Line Items'!$F:$F,TRUE) | E4: =SUMIFS('Line Items'!$N:$N,'Line Items'!$F:$F,TRUE) | F4: =SUMIFS('Line Items'!$O:$O,'Line Items'!$F:$F,TRUE) | G4: =SUMIFS('Line Items'!$P:$P,'Line Items'!$F:$F,TRUE) | H4: =SUMIFS('Line Items'!$Q:$Q,'Line Items'!$F:$F,TRUE)
A5: Total Annual Cost | B5: =B3+B4 | C5: =C3+C4 | D5: =D3+D4 | E5: =E3+E4 | F5: =F3+F4 | G5: =G3+G4 | H5: =H3+H4

Sheet Summary
A1: Total Cost of Ownership (TCO) Summary
A2: Vendor: | B2: =Metadata!B2
A4: Category | B4: 7-Year Total | C4: Monthly Average
A5: Core | B5: =SUMIFS('Line Items'!$R:$R,'Line Items'!$D:$D,A5) | C5: =B5/84
A6: Digital | B6: =SUMIFS('Line Items'!$R:$R,'Line Items'!$D:$D,A6) | C6: =B6/84
A7: EFT | B7: =SUMIFS('Line Items'!$R:$R,'Line Items'!$D:$D,A7) | C7: =B7/84
A8: Image Solutions | B8: =SUMIFS('Line Items'!$R:$R,'Line Items'!$D:$D,A8) | C8: =B8/84
A9: Item Processing | B9: =SUMIFS('Line Items'!$R:$R,'Line Items'!$D:$D,A9) | C9: =B9/84
A10: Network | B10: =SUMIFS('Line Items'!$R:$R,'Line Items'!$D:$D,A10) | C10: =B10/84
A11: Other | B11: =SUMIFS('Line Items'!$R:$R,'Line Items'!$D:$D,A11) | C11: =B11/84
A12: Risk, Fraud & Compliance | B12: =SUMIFS('Line Items'!$R:$R,'Line Items'!$D:$D,A12) | C12: =B12/84
A14: Total Required TCO | B14: =SUM(B5:B12) | C14: =B14/84
A16: Optional Items Total | B16: =SUMIFS('Line Items'!$R:$R,'Line Items'!$F:$F,TRUE) | C16: =B16/84

Sheet Metadata
A1: TCO Analysis - Proposal Metadata
A2: Primary Vendor: | B2: LIBERTY_CAPITAL_BANK_CSI
A3: Client Name: | B3: Liberty Capital & Texas Heritage (COMBINED)
A4: Proposal Type: | B4: CSI Pricing Proposal (Organic Growth 7-yr)
A5: Proposal Date: | B5: 2024-12-16
A6: Contract Term (Years): | B6: 7
A7: Annual Growth Rate: | B7: 0.02
A8: Annual CPI Rate: | B8: 0.02
A10: Data Extraction Date: | B10: 2026-01-15 15:00:42
A12: Source Proposal File: | B12: N/A

Sheet Normalized Comparison
A1: VENDOR COMPARISON: LIBERTY CAPITAL BANK
A2: Normalized Cost Analysis | Generated: January 15, 2026
A4: EXECUTIVE SUMMARY
A5: Vendors Compared: | B5: CSI vs FIS
A6: CSI Total 7-Year TCO: | B6: 5410852.1
A7: FIS Total 7-Year TCO: | B7: 13244335
A8: Cost Difference: | B8: 7833483.3
A9: Savings Percentage: | B9: 0.59145915
A10: Recommended Vendor: | B10: CSI
A12: 7-YEAR TCO BY COST CATEGORY
A13: Cost Category | B13: CSI | C13: FIS | D13: Difference | E13: Savings % | F13: Lower Cost
A14: Setup/Implementation | B14: -374999 | C14: -3218234.1 | D14: 2843235.1 | E14: 0 | F14: FIS
A15: Licensing/Subscription | B15: 4273097.2 | C15: 6534838.6 | D15: -2261741.5 | E15: 0.34610517 | F15: CSI
A16: Transaction/Usage | B16: 1415195.5 | C16: 0 | D16: 1415195.5 | E16: 1 | F16: FIS
A17: Training/Enablement | B17: 6620.3673 | C17: 0 | D17: 6620.3673 | E17: 1 | F17: FIS
A18: Support/Maintenance | B18: 23079.336 | C18: 0 | D18: 23079.336 | E18: 1 | F18: FIS
A19: Professional Services | B19: 67858.765 | C19: 3305563.2 | D19: -3237704.4 | E19: 0.97947135 | F19: CSI
A20: TOTAL 7-YEAR TCO | B20: 5410852.1 | C20: 13244335 | D20: -7833483.3 | E20: 0.59145915 | F20: CSI
A22: RECOMMENDATION
A23: CSI offers a savings of $7,833,483 (59.1%) over FIS across the 7-year contract term.
A25: DETAILED LINE ITEM COMPARISON
A26: Line items organized by cost category for detailed analysis
A28: Setup/Implementation
A29: CSI Solution | B29: CSI Cost | C29: FIS Solution | D29: FIS Cost
A30: CSI One-Time Fee | B30: 261102 | C30: Monthly Relationship Credit | D30: -3218234.1 | E30: Monthly Relationship Credit | F30: -3218234.1
A31: Equipment Fees | B31: 76933
A32: Credit for One-Time Fees | B32: -338034
A33: Special Incentive Billing Credit | B33: -375000
A34: Subtotal | B34: -374999 | C34: Subtotal | D34: -3218234.1 | E34: Subtotal | F34: -3218234.1
A36: Licensing/Subscription
A37: CSI Solution | B37: CSI Cost | C37: FIS Solution | D37: FIS Cost
A38: CSI Fees Included in Organic Growth Based Pricing | B38: 3555045.3 | C38: Item Processing: FCM, IP, Branch Capture, CCX, FXD, DLRR | D38: 1779499.6 | E38: Item Processing: FCM, IP, Branch Capture, CCX, FXD, DLRR | F38: 1779499.6
A39: CSI Wire | B39: 328903.53 | C39: Core: HORIZON | D39: 1544016.8 | E39: Core: HORIZON | F39: 1544016.8
A40: iPay Online Bill Pay | B40: 122109 | C40: EFT: EFT Norcross, 3D Secure, Tokenization, SecurLOCK | D40: 613763.22 | E40: EFT: EFT Norcross, 3D Secure, Tokenization, SecurLOCK | F40: 613763.22
A41: Quicken & QuickBooks Direct Connect | B41: 67766.816 | C41: Image Solutions: FedNOW (Send and Receive) D1B | D41: 326420.89 | E41: Image Solutions: FedNOW (Send and Receive) D1B | F41: 326420.89
A42: Mobile Deposit | B42: 53606.585 | C42: IP: DirectLink Merchant (via RDC) | D42: 312825.23 | E42: IP: DirectLink Merchant (via RDC) | F42: 312825.23
A43: Out of Band Authentication (OOBA) | B43: 36871.768 | C43: Treasury: eWire (Business) | D43: 219023.82 | E43: Treasury: eWire (Business) | F43: 219023.82
A44: Integrated PFM | B44: 32458.19 | C44: Network: Network Connectivity Services | D44: 200082.21 | E44: Network: Network Connectivity Services | F44: 200082.21
A45: WatchDog CIP License | B45: 22987.387 | C45: FOS: eDelivery, Print/Render, Forms & Envelopes | D45: 199346.62 | E45: FOS: eDelivery, Print/Render, Forms & Envelopes | F45: 199346.62
A46: Mobile Banking Push Notifications | B46: 20228.9 | C46: Digital: WebConnect/DirectConnect & Quickbooks | D46: 191163.11 | E46: Digital: WebConnect/DirectConnect & Quickbooks | F46: 191163.11
...
