Workbook
Name HighlightActiveRow: 23

Sheet (INTERNAL) Basic Entry 
B2: INTERNAL USE ONLY
B4: Arriba Advisors Data Entry Required in Blue Fields
E6: Additional Boxes for Custom Cell Linking:
B7: Client's Name | C7: First State Bank of Waynesboro | E7: Current Contract Effective Date
B9: Project Type (ex: Digital, CORE, etc.) | C9: CORE & DIGITAL | E9: (Custom Entry)
B11: Current Contract End Date | E11: Early Term Savings (# of Months)
B13: What is our baseline?
A14: A) | B14: Baseline from Current Invoices
B17: Incumbent Vendor's Name | C17: Current (FIS Bankway)
B19: Prospective Vendor #1's Name | C19: FIS Horizon with D1 Flex | E19: Vendor #1 Proposal Date or Round | F19: Proposal Dated 12/13/2023
B21: Prospective Vendor #2's Name | C21: FIS Horizon WITHOUT D1 Flex | E21: Vendor #2 Proposal Date or Round | F21: Proposal Dated 12/13/2023
B23: Prospective Vendor #3's Name | C23: Vendor #3 | E23: Vendor #3 Proposal Date or Round | F23: Month Year

Sheet CORE Recurring Items
C3: CORE: Monthly & Annual Fees | H3: QTY YOY Growth % | J3: CPI Rates
C4: ='(INTERNAL) Basic Entry '!$C$7 -> First State Bank of Waynesboro | J4: Current | K4: Vendor #1 Proposed | L4: Vendor #2 Proposed | M4: Vendor #3 Proposed | N4: ='(INTERNAL) Basic Entry '!$C$17 -> Current (FIS Bankway) | X4: ='(INTERNAL) Basic Entry '!$C$19 -> FIS Horizon with D1 Flex | AI4: ='(INTERNAL) Basic Entry '!C21 -> FIS Horizon WITHOUT D1 Flex | AT4: ='(INTERNAL) Basic Entry '!C23 -> Vendor #3
C5: ='(INTERNAL) Basic Entry '!$C$9&" Pricing Analysis" -> CORE & DIGITAL Pricing Analysis | H5: 0.05 | J5: 0.0467 | K5: 0.0467 | L5: 0.0467 | M5: 0 | N5: ='(INTERNAL) Basic Entry '!$B$14 -> Baseline from Current Invoices | X5: ='(INTERNAL) Basic Entry '!F19 -> Proposal Dated 12/13/2023 | AI5: ='(INTERNAL) Basic Entry '!F21 -> Proposal Dated 12/13/2023 | AT5: ='(INTERNAL) Basic Entry '!F23 -> Month Year
B6: Billing Category | C6: MONTHLY PROCESSING ITEMS | D6: Invoice #1 (Sep/2023) | E6: Invoice #2 (Aug/2023) | F6: Invoice #3 (Jul/2023) | G6: Invoice #4 (Jun/2023) | H6: Average Monthly QTY | I6: Year 1 Quantity | J6: Year 2 Quantity | K6: Year 3 Quantity | L6: Year 4 Quantity | M6: Year 5 Quantity | N6: Item Name | O6: Per Unit Rate | Q6: Year 1 Cost | R6: Year 2 Cost | S6: Year 3 Cost | T6: Year 4 Cost | U6: Year 5 Cost | V6: Total Term Cost | W6: Line Item Note | X6: Product Name | Y6: Per Unit Rate | AA6: Year 1 Cost (7/31/2025) | AB6: Year 2 Cost | AC6: Year 3 Cost | AD6: Year 4 Cost | AE6: Year 5 Cost (7/31/2030) | AF6: Term Total Cost | AG6: P/S Fee (if any) | AH6: Line Item Note | AI6: Product Name | AJ6: Per Unit Rate | AK6: Year 1 by Month | AL6: Year 1 Cost | AM6: Year 2 Cost | AN6: Year 3 Cost | AO6: Year 4 Cost | AP6: Year 5 Cost | AQ6: Term Total Cost | AR6: P/S Fee (if any) | AS6: Line Item Note | AT6: Product Name | AU6: Per Unit Rate | AV6: Year 1 Cost | AW6: Year 2 Cost | AX6: Year 3 Cost | AY6: Year 4 Cost | AZ6: Year 5 Cost | BA6: Term Total Cost | BB6: Line Item Note
B8: =C8 -> Core Banking Service: | C8: Core Banking Service: | N8: =C8 -> Core Banking Service: | X8: =C8 -> Core Banking Service: | AI8: =C8 -> Core Banking Service: | AT8: =C8 -> Core Banking Service:
C9: Bankway Core Banking System (Enterprise License) | D9: 1 | E9: 1 | F9: 1 | G9: 1 | H9: =IFERROR(AVERAGE(D9:G9),0) -> 1 | I9: =H9*12 -> 12 | J9: =((I9)*$H$5)+I9 -> 12.6 | K9: =((J9)*$H$5)+J9 -> 13.23 | L9: =((K9)*$H$5)+K9 -> 13.8915 | M9: =((L9)*$H$5)+L9 -> 14.586075 | N9: =IF(C9="","",C9) -> Bankway Core Banking System (Enterprise License) | O9: 25697.928 | P9: =Q9/12 -> 25697.928 | Q9: =IF(O9>0,PRODUCT(I9,$O9),0) -> 308375.14 | R9: =IF(Q9>0,PRODUCT(J9,$O9),0) -> 323793.9 | S9: =IF(R9>0,PRODUCT(K9,$O9),0) -> 339983.59 | T9: =IF(S9>0,PRODUCT(L9,$O9),0) -> 356982.77 | U9: =IF(T9>0,PRODUCT(M9,$O9),0) -> 374831.91 | V9: =SUM(Q9:U9) -> 1703967.3 | W9: Cost Based on Asset Size increasing 5% Annually | Z9: =AA9/12 -> 0 | AA9: =IF(Y9>0,PRODUCT(I9,$Y9),0) -> 0 | AB9: =IF(AA9>0,PRODUCT(J9,$Y9),0) -> 0 | AC9: =IF(AB9>0,PRODUCT(K9,$Y9),0) -> 0 | AD9: =IF(AC9>0,PRODUCT(L9,$Y9),0) -> 0 | AE9: =IF(AD9>0,PRODUCT(M9,$Y9),0) -> 0 | AF9: =SUM(AA9:AE9) -> 0 | AK9: =AL9/12 -> 0 | AL9: {=_xlfn.IFS(AJ9="NO CHARGE",0,AJ9=0,0,AJ9>0,PRODUCT(I9,$AJ9))} -> 0 | AM9: {=_xlfn.IFS(AK9="NO CHARGE",0,AK9=0,0,AK9>0,PRODUCT(J9,$AJ9))} -> 0 | AN9: {=_xlfn.IFS(AL9="NO CHARGE",0,AL9=0,0,AL9>0,PRODUCT(K9,$AJ9))} -> 0 | AO9: {=_xlfn.IFS(AM9="NO CHARGE",0,AM9=0,0,AM9>0,PRODUCT(L9,$AJ9))} -> 0 | AP9: {=_xlfn.IFS(AN9="NO CHARGE",0,AN9=0,0,AN9>0,PRODUCT(M9,$AJ9))} -> 0 | AQ9: =SUM(AL9:AP9) -> 0 | AV9: =IF(AU9>0,PRODUCT(I9,$AU9),0) -> 0 | AW9: =IF(AV9>0,PRODUCT(J9,$AU9),0) -> 0 | AX9: =IF(AW9>0,PRODUCT(K9,$AU9),0) -> 0 | AY9: =IF(AX9>0,PRODUCT(L9,$AU9),0) -> 0 | AZ9: =IF(AY9>0,PRODUCT(M9,$AU9),0) -> 0 | BA9: =SUM(AV9:AZ9) -> 0
C10: Bankway Core Banking System New Account Desk | D10: 1 | E10: 1 | F10: 1 | G10: 1 | H10: =IFERROR(AVERAGE(D10:G10),0) -> 1 | I10: =H10*12 -> 12 | J10: =IF(I10>12,(((I10)*$H$5)+I10),(I10*1)) -> 12 | K10: =IF(J10>12,(((J10)*$H$5)+J10),(J10*1)) -> 12 | L10: =IF(K10>12,(((K10)*$H$5)+K10),(K10*1)) -> 12 | M10: =IF(L10>12,(((L10)*$H$5)+L10),(L10*1)) -> 12 | N10: =IF(C10="","",C10) -> Bankway Core Banking System New Account Desk | O10: 817.53583 | P10: =Q10/12 -> 817.53583 | Q10: =IF(O10>0,PRODUCT(I10,$O10),0) -> 9810.43 | R10: =IF(Q10>0,PRODUCT(J10,$O10),0) -> 9810.43 | S10: =IF(R10>0,PRODUCT(K10,$O10),0) -> 9810.43 | T10: =IF(S10>0,PRODUCT(L10,$O10),0) -> 9810.43 | U10: =IF(T10>0,PRODUCT(M10,$O10),0) -> 9810.43 | V10: =SUM(Q10:U10) -> 49052.15 | Z10: =AA10/12 -> 0 | AA10: =IF(Y10>0,PRODUCT(I10,$Y10),0) -> 0 | AB10: =IF(AA10>0,PRODUCT(J10,$Y10),0) -> 0 | AC10: =IF(AB10>0,PRODUCT(K10,$Y10),0) -> 0 | AD10: =IF(AC10>0,PRODUCT(L10,$Y10),0) -> 0 | AE10: =IF(AD10>0,PRODUCT(M10,$Y10),0) -> 0 | AF10: =SUM(AA10:AE10) -> 0 | AK10: =AL10/12 -> 0 | AL10: {=_xlfn.IFS(AJ10="NO CHARGE",0,AJ10=0,0,AJ10>0,PRODUCT(I10,$AJ10))} -> 0 | AM10: {=_xlfn.IFS(AK10="NO CHARGE",0,AK10=0,0,AK10>0,PRODUCT(J10,$AJ10))} -> 0 | AN10: {=_xlfn.IFS(AL10="NO CHARGE",0,AL10=0,0,AL10>0,PRODUCT(K10,$AJ10))} -> 0 | AO10: {=_xlfn.IFS(AM10="NO CHARGE",0,AM10=0,0,AM10>0,PRODUCT(L10,$AJ10))} -> 0 | AP10: {=_xlfn.IFS(AN10="NO CHARGE",0,AN10=0,0,AN10>0,PRODUCT(M10,$AJ10))} -> 0 | AQ10: =SUM(AL10:AP10) -> 0 | AV10: =IF(AU10>0,PRODUCT(I10,$AU10),0) -> 0 | AW10: =IF(AV10>0,PRODUCT(J10,$AU10),0) -> 0 | AX10: =IF(AW10>0,PRODUCT(K10,$AU10),0) -> 0 | AY10: =IF(AX10>0,PRODUCT(L10,$AU10),0) -> 0 | AZ10: =IF(AY10>0,PRODUCT(M10,$AU10),0) -> 0 | BA10: =SUM(AV10:AZ10) -> 0
C11: EFT Card Management | D11: 1 | E11: 1 | F11: 1 | G11: 1 | H11: =IFERROR(AVERAGE(D11:G11),0) -> 1 | I11: =H11*12 -> 12 | J11: =IF(I11>12,(((I11)*$H$5)+I11),(I11*1)) -> 12 | K11: =IF(J11>12,(((J11)*$H$5)+J11),(J11*1)) -> 12 | L11: =IF(K11>12,(((K11)*$H$5)+K11),(K11*1)) -> 12 | M11: =IF(L11>12,(((L11)*$H$5)+L11),(L11*1)) -> 12 | N11: =IF(C11="","",C11) -> EFT Card Management | O11: 1502.9425 | P11: =Q11/12 -> 1502.9425 | Q11: =IF(O11>0,PRODUCT(I11,$O11),0) -> 18035.31 | R11: =IF(Q11>0,PRODUCT(J11,$O11),0) -> 18035.31 | S11: =IF(R11>0,PRODUCT(K11,$O11),0) -> 18035.31 | T11: =IF(S11>0,PRODUCT(L11,$O11),0) -> 18035.31 | U11: =IF(T11>0,PRODUCT(M11,$O11),0) -> 18035.31 | V11: =SUM(Q11:U11) -> 90176.55 | Z11: =AA11/12 -> 0 | AA11: =IF(Y11>0,PRODUCT(I11,$Y11),0) -> 0 | AB11: =IF(AA11>0,PRODUCT(J11,$Y11),0) -> 0 | AC11: =IF(AB11>0,PRODUCT(K11,$Y11),0) -> 0 | AD11: =IF(AC11>0,PRODUCT(L11,$Y11),0) -> 0 | AE11: =IF(AD11>0,PRODUCT(M11,$Y11),0) -> 0 | AF11: =SUM(AA11:AE11) -> 0 | AK11: =AL11/12 -> 0 | AL11: {=_xlfn.IFS(AJ11="NO CHARGE",0,AJ11=0,0,AJ11>0,PRODUCT(I11,$AJ11))} -> 0 | AM11: {=_xlfn.IFS(AK11="NO CHARGE",0,AK11=0,0,AK11>0,PRODUCT(J11,$AJ11))} -> 0 | AN11: {=_xlfn.IFS(AL11="NO CHARGE",0,AL11=0,0,AL11>0,PRODUCT(K11,$AJ11))} -> 0 | AO11: {=_xlfn.IFS(AM11="NO CHARGE",0,AM11=0,0,AM11>0,PRODUCT(L11,$AJ11))} -> 0 | AP11: {=_xlfn.IFS(AN11="NO CHARGE",0,AN11=0,0,AN11>0,PRODUCT(M11,$AJ11))} -> 0 | AQ11: =SUM(AL11:AP11) -> 0 | AV11: =IF(AU11>0,PRODUCT(I11,$AU11),0) -> 0 | AW11: =IF(AV11>0,PRODUCT(J11,$AU11),0) -> 0 | AX11: =IF(AW11>0,PRODUCT(K11,$AU11),0) -> 0 | AY11: =IF(AX11>0,PRODUCT(L11,$AU11),0) -> 0 | AZ11: =IF(AY11>0,PRODUCT(M11,$AU11),0) -> 0 | BA11: =SUM(AV11:AZ11) -> 0
B12: Horizon Core Account Processing | C12: =B12&" [QTY CALCULATIONS YOY]" -> Horizon Core Account Processing [QTY CALCULATIONS YOY] | H12: 54437 | I12: =H12*12 -> 653244 | J12: =IF(I12>12,(((I12)*$H$5)+I12),(I12*1)) -> 685906.2 | K12: =IF(J12>12,(((J12)*$H$5)+J12),(J12*1)) -> 720201.51 | L12: =IF(K12>12,(((K12)*$H$5)+K12),(K12*1)) -> 756211.59 | M12: =IF(L12>12,(((L12)*$H$5)+L12),(L12*1)) -> 794022.16 | P12: =Q12/12 -> 0 | Q12: =IF(O12>0,PRODUCT(I12,$O12),0) -> 0 | R12: =IF(Q12>0,PRODUCT(J12,$O12),0) -> 0 | S12: =IF(R12>0,PRODUCT(K12,$O12),0) -> 0 | T12: =IF(S12>0,PRODUCT(L12,$O12),0) -> 0 | U12: =IF(T12>0,PRODUCT(M12,$O12),0) -> 0 | V12: =SUM(Q12:U12) -> 0 | X12: =B12&" [TIERED]" -> Horizon Core Account Processing [TIERED] | Z12: =AA12/12 -> 0 | AA12: =IF(Y12>0,PRODUCT(I12,$Y12),0) -> 0 | AB12: =IF(AA12>0,PRODUCT(J12,$Y12),0) -> 0 | AC12: =IF(AB12>0,PRODUCT(K12,$Y12),0) -> 0 | AD12: =IF(AC12>0,PRODUCT(L12,$Y12),0) -> 0 | AE12: =IF(AD12>0,PRODUCT(M12,$Y12),0) -> 0 | AF12: =SUM(AA12:AE12) -> 0 | AI12: =X12 -> Horizon Core Account Processing [TIERED] | AK12: =AL12/12 -> 0 | AL12: {=_xlfn.IFS(AJ12="NO CHARGE",0,AJ12=0,0,AJ12>0,PRODUCT(I12,$AJ12))} -> 0 | AM12: {=_xlfn.IFS(AK12="NO CHARGE",0,AK12=0,0,AK12>0,PRODUCT(J12,$AJ12))} -> 0 | AN12: {=_xlfn.IFS(AL12="NO CHARGE",0,AL12=0,0,AL12>0,PRODUCT(K12,$AJ12))} -> 0 | AO12: {=_xlfn.IFS(AM12="NO CHARGE",0,AM12=0,0,AM12>0,PRODUCT(L12,$AJ12))} -> 0 | AP12: {=_xlfn.IFS(AN12="NO CHARGE",0,AN12=0,0,AN12>0,PRODUCT(M12,$AJ12))} -> 0 | AQ12: =SUM(AL12:AP12) -> 0 | AV12: =IF(AU12>0,PRODUCT(I12,$AU12),0) -> 0 | AW12: =IF(AV12>0,PRODUCT(J12,$AU12),0) -> 0 | AX12: =IF(AW12>0,PRODUCT(K12,$AU12),0) -> 0 | AY12: =IF(AX12>0,PRODUCT(L12,$AU12),0) -> 0 | AZ12: =IF(AY12>0,PRODUCT(M12,$AU12),0) -> 0 | BA12: =SUM(AV12:AZ12) -> 0
B13: Horizon Core Account Processing | C13: [Tiered] Base Monthly Processing 0 - 54,437 Accounts | H13: 54437 | I13: =IF(I12>($H13*12),$H13*12,I12) -> 653244 | J13: =IF(J12>($H13*12),$H13*12,J12) -> 653244 | K13: =IF(K12>($H13*12),$H13*12,K12) -> 653244 | L13: =IF(L12>($H13*12),$H13*12,L12) -> 653244 | M13: =IF(M12>($H13*12),$H13*12,M12) -> 653244 | P13: =Q13/12 -> 0 | Q13: =IF(O13>0,PRODUCT(I13,$O13),0) -> 0 | R13: =IF(Q13>0,PRODUCT(J13,$O13),0) -> 0 | S13: =IF(R13>0,PRODUCT(K13,$O13),0) -> 0 | T13: =IF(S13>0,PRODUCT(L13,$O13),0) -> 0 | U13: =IF(T13>0,PRODUCT(M13,$O13),0) -> 0 | V13: =SUM(Q13:U13) -> 0 | X13: =C13 -> [Tiered] Base Monthly Processing 0 - 54,437 Accounts | Y13: =28853.62/54437 -> 0.53003692 | Z13: =AA13/12 -> 28853.62 | AA13: =IF(Y13>0,PRODUCT(I13,$Y13),0) -> 346243.44 | AB13: =IF(AA13>0,PRODUCT(J13,$Y13),0) -> 346243.44 | AC13: =IF(AB13>0,PRODUCT(K13,$Y13),0) -> 346243.44 | AD13: =IF(AC13>0,PRODUCT(L13,$Y13),0) -> 346243.44 | AE13: =IF(AD13>0,PRODUCT(M13,$Y13),0) -> 346243.44 | AF13: =SUM(AA13:AE13) -> 1731217.2 | AG13: WAIVED | AH13: FIS PROPOSAL MISSING PER UNIT RATE | AI13: =C13 -> [Tiered] Base Monthly Processing 0 - 54,437 Accounts | AJ13: =28853.62/54437 -> 0.53003692 | AK13: =AL13/12 -> 28853.62 | AL13: {=_xlfn.IFS($AJ13="NO CHARGE",0,$AJ13=0,0,$AJ13>0,PRODUCT(I13,$AJ13))} -> 346243.44 | AM13: {=_xlfn.IFS($AJ13="NO CHARGE",0,$AJ13=0,0,$AJ13>0,PRODUCT(J13,$AJ13))} -> 346243.44 | AN13: {=_xlfn.IFS($AJ13="NO CHARGE",0,$AJ13=0,0,$AJ13>0,PRODUCT(K13,$AJ13))} -> 346243.44 | AO13: {=_xlfn.IFS($AJ13="NO CHARGE",0,$AJ13=0,0,$AJ13>0,PRODUCT(L13,$AJ13))} -> 346243.44 | AP13: {=_xlfn.IFS($AJ13="NO CHARGE",0,$AJ13=0,0,$AJ13>0,PRODUCT(M13,$AJ13))} -> 346243.44 | AQ13: =SUM(AL13:AP13) -> 1731217.2 | AR13: Waived | AS13: FIS PROPOSAL MISSING PER UNIT RATE | AV13: =IF(AU13>0,PRODUCT(I13,$AU13),0) -> 0 | AW13: =IF(AV13>0,PRODUCT(J13,$AU13),0) -> 0 | AX13: =IF(AW13>0,PRODUCT(K13,$AU13),0) -> 0 | AY13: =IF(AX13>0,PRODUCT(L13,$AU13),0) -> 0 | AZ13: =IF(AY13>0,PRODUCT(M13,$AU13),0) -> 0 | BA13: =SUM(AV13:AZ13) -> 0
B14: Horizon Core Account Processing | C14: [Tiered] Base Monthly Processing 54,438 - 100k Accounts | H14: =100000-54438 -> 45562 | I14: {=_xlfn.IFS(I12>(($H13*12)+($H14*12)),$H14*12, I12<(($H13*12)+($H14*12)),I12-I13, I12=(($H13*12)+($H14*12)),I12-I13)} -> 0 | J14: {=_xlfn.IFS(J12>(($H13*12)+($H14*12)),$H14*12, J12<(($H13*12)+($H14*12)),J12-J13, J12=(($H13*12)+($H14*12)),J12-J13)} -> 32662.2 | K14: {=_xlfn.IFS(K12>(($H13*12)+($H14*12)),$H14*12, K12<(($H13*12)+($H14*12)),K12-K13, K12=(($H13*12)+($H14*12)),K12-K13)} -> 66957.51 | L14: {=_xlfn.IFS(L12>(($H13*12)+($H14*12)),$H14*12, L12<(($H13*12)+($H14*12)),L12-L13, L12=(($H13*12)+($H14*12)),L12-L13)} -> 102967.59 | M14: {=_xlfn.IFS(M12>(($H13*12)+($H14*12)),$H14*12, M12<(($H13*12)+($H14*12)),M12-M13, M12=(($H13*12)+($H14*12)),M12-M13)} -> 140778.16 | P14: =Q14/12 -> 0 | Q14: =IF(O14>0,PRODUCT(I14,$O14),0) -> 0 | R14: =IF(Q14>0,PRODUCT(J14,$O14),0) -> 0 | S14: =IF(R14>0,PRODUCT(K14,$O14),0) -> 0 | T14: =IF(S14>0,PRODUCT(L14,$O14),0) -> 0 | U14: =IF(T14>0,PRODUCT(M14,$O14),0) -> 0 | V14: =SUM(Q14:U14) -> 0 | X14: =C14 -> [Tiered] Base Monthly Processing 54,438 - 100k Accounts | Y14: 0.5 | Z14: =AA14/12 -> 0 | AA14: =IF(Y14>0,PRODUCT(I14,$Y14),0) -> 0 | AB14: {=_xlfn.IFS($AJ14="NO CHARGE",0,$AJ14=0,0,$AJ14>0,PRODUCT(J14,$AJ14))} -> 16331.1 | AC14: =IF(AB14>0,PRODUCT(K14,$Y14),0) -> 33478.755 | AD14: =IF(AC14>0,PRODUCT(L14,$Y14),0) -> 51483.793 | AE14: =IF(AD14>0,PRODUCT(M14,$Y14),0) -> 70389.082 | AF14: =SUM(AA14:AE14) -> 171682.73 | AI14: =C14 -> [Tiered] Base Monthly Processing 54,438 - 100k Accounts | AJ14: 0.5 | AK14: =AL14/12 -> 0 | AL14: {=_xlfn.IFS($AJ14="NO CHARGE",0,$AJ14=0,0,$AJ14>0,PRODUCT(I14,$AJ14))} -> 0 | AM14: {=_xlfn.IFS($AJ14="NO CHARGE",0,$AJ14=0,0,$AJ14>0,PRODUCT(J14,$AJ14))} -> 16331.1 | AN14: {=_xlfn.IFS($AJ14="NO CHARGE",0,$AJ14=0,0,$AJ14>0,PRODUCT(K14,$AJ14))} -> 33478.755 | AO14: {=_xlfn.IFS($AJ14="NO CHARGE",0,$AJ14=0,0,$AJ14>0,PRODUCT(L14,$AJ14))} -> 51483.793 | AP14: {=_xlfn.IFS($AJ14="NO CHARGE",0,$AJ14=0,0,$AJ14>0,PRODUCT(M14,$AJ14))} -> 70389.082 | AQ14: =SUM(AL14:AP14) -> 171682.73 | AV14: =IF(AU14>0,PRODUCT(I14,$AU14),0) -> 0 | AW14: =IF(AV14>0,PRODUCT(J14,$AU14),0) -> 0 | AX14: =IF(AW14>0,PRODUCT(K14,$AU14),0) -> 0 | AY14: =IF(AX14>0,PRODUCT(L14,$AU14),0) -> 0 | AZ14: =IF(AY14>0,PRODUCT(M14,$AU14),0) -> 0 | BA14: =SUM(AV14:AZ14) -> 0
B15: Horizon Core Account Processing | C15: [Tiered] Base Monthly Processing beyond 100k Accounts | I15: {=_xlfn.IFS(I12>(($H13+$H14)*12),I12-I13-I14, I12<(($H13+$H14)*12),0, I12=(($H13+$H14)*12),0)} -> 0 | J15: {=_xlfn.IFS(J12>(($H13+$H14)*12),J12-J13-J14, J12<(($H13+$H14)*12),0, J12=(($H13+$H14)*12),0)} -> 0 | K15: {=_xlfn.IFS(K12>(($H13+$H14)*12),K12-K13-K14, K12<(($H13+$H14)*12),0, K12=(($H13+$H14)*12),0)} -> 0 | L15: {=_xlfn.IFS(L12>(($H13+$H14)*12),L12-L13-L14, L12<(($H13+$H14)*12),0, L12=(($H13+$H14)*12),0)} -> 0 | M15: {=_xlfn.IFS(M12>(($H13+$H14)*12),M12-M13-M14, M12<(($H13+$H14)*12),0, M12=(($H13+$H14)*12),0)} -> 0 | P15: =Q15/12 -> 0 | Q15: =IF(O15>0,PRODUCT(I15,$O15),0) -> 0 | R15: =IF(Q15>0,PRODUCT(J15,$O15),0) -> 0 | S15: =IF(R15>0,PRODUCT(K15,$O15),0) -> 0 | T15: =IF(S15>0,PRODUCT(L15,$O15),0) -> 0 | U15: =IF(T15>0,PRODUCT(M15,$O15),0) -> 0 | V15: =SUM(Q15:U15) -> 0 | X15: =C15 -> [Tiered] Base Monthly Processing beyond 100k Accounts | Y15: 0.48 | Z15: =AA15/12 -> 0 | AA15: =IF(Y15>0,PRODUCT(I15,$Y15),0) -> 0 | AB15: =IF(AA15>0,PRODUCT(J15,$Y15),0) -> 0 | AC15: =IF(AB15>0,PRODUCT(K15,$Y15),0) -> 0 | AD15: =IF(AC15>0,PRODUCT(L15,$Y15),0) -> 0 | AE15: =IF(AD15>0,PRODUCT(M15,$Y15),0) -> 0 | AF15: =SUM(AA15:AE15) -> 0 | AI15: =C15 -> [Tiered] Base Monthly Processing beyond 100k Accounts | AJ15: 0.48 | AK15: =AL15/12 -> 0 | AL15: {=_xlfn.IFS($AJ15="NO CHARGE",0,$AJ15=0,0,$AJ15>0,PRODUCT(I15,$AJ15))} -> 0 | AM15: {=_xlfn.IFS($AJ15="NO CHARGE",0,$AJ15=0,0,$AJ15>0,PRODUCT(J15,$AJ15))} -> 0 | AN15: {=_xlfn.IFS($AJ15="NO CHARGE",0,$AJ15=0,0,$AJ15>0,PRODUCT(K15,$AJ15))} -> 0 | AO15: {=_xlfn.IFS($AJ15="NO CHARGE",0,$AJ15=0,0,$AJ15>0,PRODUCT(L15,$AJ15))} -> 0 | AP15: {=_xlfn.IFS($AJ15="NO CHARGE",0,$AJ15=0,0,$AJ15>0,PRODUCT(M15,$AJ15))} -> 0 | AQ15: =SUM(AL15:AP15) -> 0 | AV15: =IF(AU15>0,PRODUCT(I15,$AU15),0) -> 0 | AW15: =IF(AV15>0,PRODUCT(J15,$AU15),0) -> 0 | AX15: =IF(AW15>0,PRODUCT(K15,$AU15),0) -> 0 | AY15: =IF(AX15>0,PRODUCT(L15,$AU15),0) -> 0 | AZ15: =IF(AY15>0,PRODUCT(M15,$AU15),0) -> 0 | BA15: =SUM(AV15:AZ15) -> 0
B16: Horizon Core Account Processing | C16: =B16&" Monthly Minimum" -> Horizon Core Account Processing Monthly Minimum | H16: 0 | I16: =H16*12 -> 0 | J16: =IF(I16>12,(((I16)*$H$5)+I16),(I16*1)) -> 0 | K16: =IF(J16>12,(((J16)*$H$5)+J16),(J16*1)) -> 0 | L16: =IF(K16>12,(((K16)*$H$5)+K16),(K16*1)) -> 0 | M16: =IF(L16>12,(((L16)*$H$5)+L16),(L16*1)) -> 0 | P16: =Q16/12 -> 0 | Q16: =IF(O16>0,PRODUCT(I16,$O16),0) -> 0 | R16: =IF(Q16>0,PRODUCT(J16,$O16),0) -> 0 | S16: =IF(R16>0,PRODUCT(K16,$O16),0) -> 0 | T16: =IF(S16>0,PRODUCT(L16,$O16),0) -> 0 | U16: =IF(T16>0,PRODUCT(M16,$O16),0) -> 0 | V16: =SUM(Q16:U16) -> 0 | X16: =C16 -> Horizon Core Account Processing Monthly Minimum | Y16: 26000 | Z16: =AA16/12 -> 0 | AA16: =IF(Y16>0,PRODUCT(I16,$Y16),0) -> 0 | AB16: =IF(AA16>0,PRODUCT(J16,$Y16),0) -> 0 | AC16: =IF(AB16>0,PRODUCT(K16,$Y16),0) -> 0 | AD16: =IF(AC16>0,PRODUCT(L16,$Y16),0) -> 0 | AE16: =IF(AD16>0,PRODUCT(M16,$Y16),0) -> 0 | AF16: =SUM(AA16:AE16) -> 0 | AH16: Monthly Minimum Item | AI16: =C16 -> Horizon Core Account Processing Monthly Minimum | AJ16: 26000 | AK16: =AL16/12 -> 0 | AL16: {=_xlfn.IFS($AJ16="NO CHARGE",0,$AJ16=0,0,$AJ16>0,PRODUCT(I16,$AJ16))} -> 0 | AM16: {=_xlfn.IFS($AJ16="NO CHARGE",0,$AJ16=0,0,$AJ16>0,PRODUCT(J16,$AJ16))} -> 0 | AN16: {=_xlfn.IFS($AJ16="NO CHARGE",0,$AJ16=0,0,$AJ16>0,PRODUCT(K16,$AJ16))} -> 0 | AO16: {=_xlfn.IFS($AJ16="NO CHARGE",0,$AJ16=0,0,$AJ16>0,PRODUCT(L16,$AJ16))} -> 0 | AP16: {=_xlfn.IFS($AJ16="NO CHARGE",0,$AJ16=0,0,$AJ16>0,PRODUCT(M16,$AJ16))} -> 0 | AQ16: =SUM(AL16:AP16) -> 0 | AS16: Monthly Minimum Item | AV16: =IF(AU16>0,PRODUCT(I16,$AU16),0) -> 0 | AW16: =IF(AV16>0,PRODUCT(J16,$AU16),0) -> 0 | AX16: =IF(AW16>0,PRODUCT(K16,$AU16),0) -> 0 | AY16: =IF(AX16>0,PRODUCT(L16,$AU16),0) -> 0 | AZ16: =IF(AY16>0,PRODUCT(M16,$AU16),0) -> 0 | BA16: =SUM(AV16:AZ16) -> 0
H17: =IFERROR(AVERAGE(D17:G17),0) -> 0 | I17: =H17*12 -> 0 | J17: =IF(I17>12,(((I17)*$H$5)+I17),(I17*1)) -> 0 | K17: =IF(J17>12,(((J17)*$H$5)+J17),(J17*1)) -> 0 | L17: =IF(K17>12,(((K17)*$H$5)+K17),(K17*1)) -> 0 | M17: =IF(L17>12,(((L17)*$H$5)+L17),(L17*1)) -> 0 | N17: =IF(C17="","",C17) | P17: =Q17/12 -> 0 | Q17: =IF(O17>0,PRODUCT(I17,$O17),0) -> 0 | R17: =IF(Q17>0,PRODUCT(J17,$O17),0) -> 0 | S17: =IF(R17>0,PRODUCT(K17,$O17),0) -> 0 | T17: =IF(S17>0,PRODUCT(L17,$O17),0) -> 0 | U17: =IF(T17>0,PRODUCT(M17,$O17),0) -> 0 | V17: =SUM(Q17:U17) -> 0 | Z17: =AA17/12 -> 0 | AA17: =IF(Y17>0,PRODUCT(I17,$Y17),0) -> 0 | AB17: =IF(AA17>0,PRODUCT(J17,$Y17),0) -> 0 | AC17: =IF(AB17>0,PRODUCT(K17,$Y17),0) -> 0 | AD17: =IF(AC17>0,PRODUCT(L17,$Y17),0) -> 0 | AE17: =IF(AD17>0,PRODUCT(M17,$Y17),0) -> 0 | AF17: =SUM(AA17:AE17) -> 0 | AK17: =AL17/12 -> 0 | AL17: {=_xlfn.IFS($AJ17="NO CHARGE",0,$AJ17=0,0,$AJ17>0,PRODUCT(I17,$AJ17))} -> 0 | AM17: {=_xlfn.IFS($AJ17="NO CHARGE",0,$AJ17=0,0,$AJ17>0,PRODUCT(J17,$AJ17))} -> 0 | AN17: {=_xlfn.IFS($AJ17="NO CHARGE",0,$AJ17=0,0,$AJ17>0,PRODUCT(K17,$AJ17))} -> 0 | AO17: {=_xlfn.IFS($AJ17="NO CHARGE",0,$AJ17=0,0,$AJ17>0,PRODUCT(L17,$AJ17))} -> 0 | AP17: {=_xlfn.IFS($AJ17="NO CHARGE",0,$AJ17=0,0,$AJ17>0,PRODUCT(M17,$AJ17))} -> 0 | AQ17: =SUM(AL17:AP17) -> 0 | AV17: =IF(AU17>0,PRODUCT(I17,$AU17),0) -> 0 | AW17: =IF(AV17>0,PRODUCT(J17,$AU17),0) -> 0 | AX17: =IF(AW17>0,PRODUCT(K17,$AU17),0) -> 0 | AY17: =IF(AX17>0,PRODUCT(L17,$AU17),0) -> 0 | AZ17: =IF(AY17>0,PRODUCT(M17,$AU17),0) -> 0 | BA17: =SUM(AV17:AZ17) -> 0
C18: Core Module Per Account Fee Inclusions: | H18: =IFERROR(AVERAGE(D18:G18),0) -> 0 | I18: =H18*12 -> 0 | J18: =IF(I18>12,(((I18)*$H$5)+I18),(I18*1)) -> 0 | K18: =IF(J18>12,(((J18)*$H$5)+J18),(J18*1)) -> 0 | L18: =IF(K18>12,(((K18)*$H$5)+K18),(K18*1)) -> 0 | M18: =IF(L18>12,(((L18)*$H$5)+L18),(L18*1)) -> 0 | P18: =Q18/12 -> 0 | Q18: =IF(O18>0,PRODUCT(I18,$O18),0) -> 0 | R18: =IF(Q18>0,PRODUCT(J18,$O18),0) -> 0 | S18: =IF(R18>0,PRODUCT(K18,$O18),0) -> 0 | T18: =IF(S18>0,PRODUCT(L18,$O18),0) -> 0 | U18: =IF(T18>0,PRODUCT(M18,$O18),0) -> 0 | V18: =SUM(Q18:U18) -> 0 | X18: =C18 -> Core Module Per Account Fee Inclusions: | Z18: =AA18/12 -> 0 | AA18: =IF(Y18>0,PRODUCT(I18,$Y18),0) -> 0 | AB18: =IF(AA18>0,PRODUCT(J18,$Y18),0) -> 0 | AC18: =IF(AB18>0,PRODUCT(K18,$Y18),0) -> 0 | AD18: =IF(AC18>0,PRODUCT(L18,$Y18),0) -> 0 | AE18: =IF(AD18>0,PRODUCT(M18,$Y18),0) -> 0 | AF18: =SUM(AA18:AE18) -> 0 | AI18: Core Module Per Account Fee Inclusions: | AK18: =AL18/12 -> 0 | AL18: {=_xlfn.IFS($AJ18="NO CHARGE",0,$AJ18=0,0,$AJ18>0,PRODUCT(I18,$AJ18))} -> 0 | AM18: {=_xlfn.IFS($AJ18="NO CHARGE",0,$AJ18=0,0,$AJ18>0,PRODUCT(J18,$AJ18))} -> 0 | AN18: {=_xlfn.IFS($AJ18="NO CHARGE",0,$AJ18=0,0,$AJ18>0,PRODUCT(K18,$AJ18))} -> 0 | AO18: {=_xlfn.IFS($AJ18="NO CHARGE",0,$AJ18=0,0,$AJ18>0,PRODUCT(L18,$AJ18))} -> 0 | AP18: {=_xlfn.IFS($AJ18="NO CHARGE",0,$AJ18=0,0,$AJ18>0,PRODUCT(M18,$AJ18))} -> 0 | AQ18: =SUM(AL18:AP18) -> 0 | AV18: =IF(AU18>0,PRODUCT(I18,$AU18),0) -> 0 | AW18: =IF(AV18>0,PRODUCT(J18,$AU18),0) -> 0 | AX18: =IF(AW18>0,PRODUCT(K18,$AU18),0) -> 0 | AY18: =IF(AX18>0,PRODUCT(L18,$AU18),0) -> 0 | AZ18: =IF(AY18>0,PRODUCT(M18,$AU18),0) -> 0 | BA18: =SUM(AV18:AZ18) -> 0
C19: Archived Accounts | H19: =IFERROR(AVERAGE(D19:G19),0) -> 0 | I19: =H19*12 -> 0 | J19: =IF(I19>12,(((I19)*$H$5)+I19),(I19*1)) -> 0 | K19: =IF(J19>12,(((J19)*$H$5)+J19),(J19*1)) -> 0 | L19: =IF(K19>12,(((K19)*$H$5)+K19),(K19*1)) -> 0 | M19: =IF(L19>12,(((L19)*$H$5)+L19),(L19*1)) -> 0 | P19: =Q19/12 -> 0 | Q19: =IF(O19>0,PRODUCT(I19,$O19),0) -> 0 | R19: =IF(Q19>0,PRODUCT(J19,$O19),0) -> 0 | S19: =IF(R19>0,PRODUCT(K19,$O19),0) -> 0 | T19: =IF(S19>0,PRODUCT(L19,$O19),0) -> 0 | U19: =IF(T19>0,PRODUCT(M19,$O19),0) -> 0 | V19: =SUM(Q19:U19) -> 0 | X19: =C19 -> Archived Accounts | Y19: INCLUDED | Z19: =AA19/12 -> 0 | AA19: =IF(Y19>0,PRODUCT(I19,$Y19),0) -> 0 | AB19: =IF(AA19>0,PRODUCT(J19,$Y19),0) -> 0 | AC19: =IF(AB19>0,PRODUCT(K19,$Y19),0) -> 0 | AD19: =IF(AC19>0,PRODUCT(L19,$Y19),0) -> 0 | AE19: =IF(AD19>0,PRODUCT(M19,$Y19),0) -> 0 | AF19: =SUM(AA19:AE19) -> 0 | AI19: Archived Accounts | AK19: =AL19/12 -> 0 | AL19: {=_xlfn.IFS($AJ19="NO CHARGE",0,$AJ19=0,0,$AJ19>0,PRODUCT(I19,$AJ19))} -> 0 | AM19: {=_xlfn.IFS($AJ19="NO CHARGE",0,$AJ19=0,0,$AJ19>0,PRODUCT(J19,$AJ19))} -> 0 | AN19: {=_xlfn.IFS($AJ19="NO CHARGE",0,$AJ19=0,0,$AJ19>0,PRODUCT(K19,$AJ19))} -> 0 | AO19: {=_xlfn.IFS($AJ19="NO CHARGE",0,$AJ19=0,0,$AJ19>0,PRODUCT(L19,$AJ19))} -> 0 | AP19: {=_xlfn.IFS($AJ19="NO CHARGE",0,$AJ19=0,0,$AJ19>0,PRODUCT(M19,$AJ19))} -> 0 | AQ19: =SUM(AL19:AP19) -> 0 | AV19: =IF(AU19>0,PRODUCT(I19,$AU19),0) -> 0 | AW19: =IF(AV19>0,PRODUCT(J19,$AU19),0) -> 0 | AX19: =IF(AW19>0,PRODUCT(K19,$AU19),0) -> 0 | AY19: =IF(AX19>0,PRODUCT(L19,$AU19),0) -> 0 | AZ19: =IF(AY19>0,PRODUCT(M19,$AU19),0) -> 0 | BA19: =SUM(AV19:AZ19) -> 0
C20: Credit Bureau Reporting (3 included) | H20: =IFERROR(AVERAGE(D20:G20),0) -> 0 | I20: =H20*12 -> 0 | J20: =IF(I20>12,(((I20)*$H$5)+I20),(I20*1)) -> 0 | K20: =IF(J20>12,(((J20)*$H$5)+J20),(J20*1)) -> 0 | L20: =IF(K20>12,(((K20)*$H$5)+K20),(K20*1)) -> 0 | M20: =IF(L20>12,(((L20)*$H$5)+L20),(L20*1)) -> 0 | P20: =Q20/12 -> 0 | Q20: =IF(O20>0,PRODUCT(I20,$O20),0) -> 0 | R20: =IF(Q20>0,PRODUCT(J20,$O20),0) -> 0 | S20: =IF(R20>0,PRODUCT(K20,$O20),0) -> 0 | T20: =IF(S20>0,PRODUCT(L20,$O20),0) -> 0 | U20: =IF(T20>0,PRODUCT(M20,$O20),0) -> 0 | V20: =SUM(Q20:U20) -> 0 | X20: =C20 -> Credit Bureau Reporting (3 included) | Y20: INCLUDED | Z20: =AA20/12 -> 0 | AA20: =IF(Y20>0,PRODUCT(I20,$Y20),0) -> 0 | AB20: =IF(AA20>0,PRODUCT(J20,$Y20),0) -> 0 | AC20: =IF(AB20>0,PRODUCT(K20,$Y20),0) -> 0 | AD20: =IF(AC20>0,PRODUCT(L20,$Y20),0) -> 0 | AE20: =IF(AD20>0,PRODUCT(M20,$Y20),0) -> 0 | AF20: =SUM(AA20:AE20) -> 0 | AI20: Credit Bureau Reporting (3 included) | AK20: =AL20/12 -> 0 | AL20: {=_xlfn.IFS($AJ20="NO CHARGE",0,$AJ20=0,0,$AJ20>0,PRODUCT(I20,$AJ20))} -> 0 | AM20: {=_xlfn.IFS($AJ20="NO CHARGE",0,$AJ20=0,0,$AJ20>0,PRODUCT(J20,$AJ20))} -> 0 | AN20: {=_xlfn.IFS($AJ20="NO CHARGE",0,$AJ20=0,0,$AJ20>0,PRODUCT(K20,$AJ20))} -> 0 | AO20: {=_xlfn.IFS($AJ20="NO CHARGE",0,$AJ20=0,0,$AJ20>0,PRODUCT(L20,$AJ20))} -> 0 | AP20: {=_xlfn.IFS($AJ20="NO CHARGE",0,$AJ20=0,0,$AJ20>0,PRODUCT(M20,$AJ20))} -> 0 | AQ20: =SUM(AL20:AP20) -> 0 | AV20: =IF(AU20>0,PRODUCT(I20,$AU20),0) -> 0 | AW20: =IF(AV20>0,PRODUCT(J20,$AU20),0) -> 0 | AX20: =IF(AW20>0,PRODUCT(K20,$AU20),0) -> 0 | AY20: =IF(AX20>0,PRODUCT(L20,$AU20),0) -> 0 | AZ20: =IF(AY20>0,PRODUCT(M20,$AU20),0) -> 0 | BA20: =SUM(AV20:AZ20) -> 0
C21: DDA/Savings History Retention | H21: =IFERROR(AVERAGE(D21:G21),0) -> 0 | I21: =H21*12 -> 0 | J21: =IF(I21>12,(((I21)*$H$5)+I21),(I21*1)) -> 0 | K21: =IF(J21>12,(((J21)*$H$5)+J21),(J21*1)) -> 0 | L21: =IF(K21>12,(((K21)*$H$5)+K21),(K21*1)) -> 0 | M21: =IF(L21>12,(((L21)*$H$5)+L21),(L21*1)) -> 0 | P21: =Q21/12 -> 0 | Q21: =IF(O21>0,PRODUCT(I21,$O21),0) -> 0 | R21: =IF(Q21>0,PRODUCT(J21,$O21),0) -> 0 | S21: =IF(R21>0,PRODUCT(K21,$O21),0) -> 0 | T21: =IF(S21>0,PRODUCT(L21,$O21),0) -> 0 | U21: =IF(T21>0,PRODUCT(M21,$O21),0) -> 0 | V21: =SUM(Q21:U21) -> 0 | X21: =C21 -> DDA/Savings History Retention | Y21: INCLUDED | Z21: =AA21/12 -> 0 | AA21: =IF(Y21>0,PRODUCT(I21,$Y21),0) -> 0 | AB21: =IF(AA21>0,PRODUCT(J21,$Y21),0) -> 0 | AC21: =IF(AB21>0,PRODUCT(K21,$Y21),0) -> 0 | AD21: =IF(AC21>0,PRODUCT(L21,$Y21),0) -> 0 | AE21: =IF(AD21>0,PRODUCT(M21,$Y21),0) -> 0 | AF21: =SUM(AA21:AE21) -> 0 | AI21: DDA/Savings History Retention | AK21: =AL21/12 -> 0 | AL21: {=_xlfn.IFS($AJ21="NO CHARGE",0,$AJ21=0,0,$AJ21>0,PRODUCT(I21,$AJ21))} -> 0 | AM21: {=_xlfn.IFS($AJ21="NO CHARGE",0,$AJ21=0,0,$AJ21>0,PRODUCT(J21,$AJ21))} -> 0 | AN21: {=_xlfn.IFS($AJ21="NO CHARGE",0,$AJ21=0,0,$AJ21>0,PRODUCT(K21,$AJ21))} -> 0 | AO21: {=_xlfn.IFS($AJ21="NO CHARGE",0,$AJ21=0,0,$AJ21>0,PRODUCT(L21,$AJ21))} -> 0 | AP21: {=_xlfn.IFS($AJ21="NO CHARGE",0,$AJ21=0,0,$AJ21>0,PRODUCT(M21,$AJ21))} -> 0 | AQ21: =SUM(AL21:AP21) -> 0 | AV21: =IF(AU21>0,PRODUCT(I21,$AU21),0) -> 0 | AW21: =IF(AV21>0,PRODUCT(J21,$AU21),0) -> 0 | AX21: =IF(AW21>0,PRODUCT(K21,$AU21),0) -> 0 | AY21: =IF(AX21>0,PRODUCT(L21,$AU21),0) -> 0 | AZ21: =IF(AY21>0,PRODUCT(M21,$AU21),0) -> 0 | BA21: =SUM(AV21:AZ21) -> 0
C22: Deposit Origination (DO) | H22: =IFERROR(AVERAGE(D22:G22),0) -> 0 | I22: =H22*12 -> 0 | J22: =IF(I22>12,(((I22)*$H$5)+I22),(I22*1)) -> 0 | K22: =IF(J22>12,(((J22)*$H$5)+J22),(J22*1)) -> 0 | L22: =IF(K22>12,(((K22)*$H$5)+K22),(K22*1)) -> 0 | M22: =IF(L22>12,(((L22)*$H$5)+L22),(L22*1)) -> 0 | P22: =Q22/12 -> 0 | Q22: =IF(O22>0,PRODUCT(I22,$O22),0) -> 0 | R22: =IF(Q22>0,PRODUCT(J22,$O22),0) -> 0 | S22: =IF(R22>0,PRODUCT(K22,$O22),0) -> 0 | T22: =IF(S22>0,PRODUCT(L22,$O22),0) -> 0 | U22: =IF(T22>0,PRODUCT(M22,$O22),0) -> 0 | V22: =SUM(Q22:U22) -> 0 | X22: =C22 -> Deposit Origination (DO) | Y22: INCLUDED | Z22: =AA22/12 -> 0 | AA22: =IF(Y22>0,PRODUCT(I22,$Y22),0) -> 0 | AB22: =IF(AA22>0,PRODUCT(J22,$Y22),0) -> 0 | AC22: =IF(AB22>0,PRODUCT(K22,$Y22),0) -> 0 | AD22: =IF(AC22>0,PRODUCT(L22,$Y22),0) -> 0 | AE22: =IF(AD22>0,PRODUCT(M22,$Y22),0) -> 0 | AF22: =SUM(AA22:AE22) -> 0 | AI22: Deposit Origination (DO) | AK22: =AL22/12 -> 0 | AL22: {=_xlfn.IFS($AJ22="NO CHARGE",0,$AJ22=0,0,$AJ22>0,PRODUCT(I22,$AJ22))} -> 0 | AM22: {=_xlfn.IFS($AJ22="NO CHARGE",0,$AJ22=0,0,$AJ22>0,PRODUCT(J22,$AJ22))} -> 0 | AN22: {=_xlfn.IFS($AJ22="NO CHARGE",0,$AJ22=0,0,$AJ22>0,PRODUCT(K22,$AJ22))} -> 0 | AO22: {=_xlfn.IFS($AJ22="NO CHARGE",0,$AJ22=0,0,$AJ22>0,PRODUCT(L22,$AJ22))} -> 0 | AP22: {=_xlfn.IFS($AJ22="NO CHARGE",0,$AJ22=0,0,$AJ22>0,PRODUCT(M22,$AJ22))} -> 0 | AQ22: =SUM(AL22:AP22) -> 0 | AV22: =IF(AU22>0,PRODUCT(I22,$AU22),0) -> 0 | AW22: =IF(AV22>0,PRODUCT(J22,$AU22),0) -> 0 | AX22: =IF(AW22>0,PRODUCT(K22,$AU22),0) -> 0 | AY22: =IF(AX22>0,PRODUCT(L22,$AU22),0) -> 0 | AZ22: =IF(AY22>0,PRODUCT(M22,$AU22),0) -> 0 | BA22: =SUM(AV22:AZ22) -> 0
C23: eSignature for Teller Capture | H23: =IFERROR(AVERAGE(D23:G23),0) -> 0 | I23: =H23*12 -> 0 | J23: =IF(I23>12,(((I23)*$H$5)+I23),(I23*1)) -> 0 | K23: =IF(J23>12,(((J23)*$H$5)+J23),(J23*1)) -> 0 | L23: =IF(K23>12,(((K23)*$H$5)+K23),(K23*1)) -> 0 | M23: =IF(L23>12,(((L23)*$H$5)+L23),(L23*1)) -> 0 | P23: =Q23/12 -> 0 | Q23: =IF(O23>0,PRODUCT(I23,$O23),0) -> 0 | R23: =IF(Q23>0,PRODUCT(J23,$O23),0) -> 0 | S23: =IF(R23>0,PRODUCT(K23,$O23),0) -> 0 | T23: =IF(S23>0,PRODUCT(L23,$O23),0) -> 0 | U23: =IF(T23>0,PRODUCT(M23,$O23),0) -> 0 | V23: =SUM(Q23:U23) -> 0 | X23: =C23 -> eSignature for Teller Capture | Y23: INCLUDED | Z23: =AA23/12 -> 0 | AA23: =IF(Y23>0,PRODUCT(I23,$Y23),0) -> 0 | AB23: =IF(AA23>0,PRODUCT(J23,$Y23),0) -> 0 | AC23: =IF(AB23>0,PRODUCT(K23,$Y23),0) -> 0 | AD23: =IF(AC23>0,PRODUCT(L23,$Y23),0) -> 0 | AE23: =IF(AD23>0,PRODUCT(M23,$Y23),0) -> 0 | AF23: =SUM(AA23:AE23) -> 0 | AI23: eSignature for Teller Capture | AK23: =AL23/12 -> 0 | AL23: {=_xlfn.IFS($AJ23="NO CHARGE",0,$AJ23=0,0,$AJ23>0,PRODUCT(I23,$AJ23))} -> 0 | AM23: {=_xlfn.IFS($AJ23="NO CHARGE",0,$AJ23=0,0,$AJ23>0,PRODUCT(J23,$AJ23))} -> 0 | AN23: {=_xlfn.IFS($AJ23="NO CHARGE",0,$AJ23=0,0,$AJ23>0,PRODUCT(K23,$AJ23))} -> 0 | AO23: {=_xlfn.IFS($AJ23="NO CHARGE",0,$AJ23=0,0,$AJ23>0,PRODUCT(L23,$AJ23))} -> 0 | AP23: {=_xlfn.IFS($AJ23="NO CHARGE",0,$AJ23=0,0,$AJ23>0,PRODUCT(M23,$AJ23))} -> 0 | AQ23: =SUM(AL23:AP23) -> 0 | AV23: =IF(AU23>0,PRODUCT(I23,$AU23),0) -> 0 | AW23: =IF(AV23>0,PRODUCT(J23,$AU23),0) -> 0 | AX23: =IF(AW23>0,PRODUCT(K23,$AU23),0) -> 0 | AY23: =IF(AX23>0,PRODUCT(L23,$AU23),0) -> 0 | AZ23: =IF(AY23>0,PRODUCT(M23,$AU23),0) -> 0 | BA23: =SUM(AV23:AZ23) -> 0
C24: General Ledger History Retention | H24: =IFERROR(AVERAGE(D24:G24),0) -> 0 | I24: =H24*12 -> 0 | J24: =IF(I24>12,(((I24)*$H$5)+I24),(I24*1)) -> 0 | K24: =IF(J24>12,(((J24)*$H$5)+J24),(J24*1)) -> 0 | L24: =IF(K24>12,(((K24)*$H$5)+K24),(K24*1)) -> 0 | M24: =IF(L24>12,(((L24)*$H$5)+L24),(L24*1)) -> 0 | P24: =Q24/12 -> 0 | Q24: =IF(O24>0,PRODUCT(I24,$O24),0) -> 0 | R24: =IF(Q24>0,PRODUCT(J24,$O24),0) -> 0 | S24: =IF(R24>0,PRODUCT(K24,$O24),0) -> 0 | T24: =IF(S24>0,PRODUCT(L24,$O24),0) -> 0 | U24: =IF(T24>0,PRODUCT(M24,$O24),0) -> 0 | V24: =SUM(Q24:U24) -> 0 | X24: =C24 -> General Ledger History Retention | Y24: INCLUDED | Z24: =AA24/12 -> 0 | AA24: =IF(Y24>0,PRODUCT(I24,$Y24),0) -> 0 | AB24: =IF(AA24>0,PRODUCT(J24,$Y24),0) -> 0 | AC24: =IF(AB24>0,PRODUCT(K24,$Y24),0) -> 0 | AD24: =IF(AC24>0,PRODUCT(L24,$Y24),0) -> 0 | AE24: =IF(AD24>0,PRODUCT(M24,$Y24),0) -> 0 | AF24: =SUM(AA24:AE24) -> 0 | AI24: General Ledger History Retention | AK24: =AL24/12 -> 0 | AL24: {=_xlfn.IFS($AJ24="NO CHARGE",0,$AJ24=0,0,$AJ24>0,PRODUCT(I24,$AJ24))} -> 0 | AM24: {=_xlfn.IFS($AJ24="NO CHARGE",0,$AJ24=0,0,$AJ24>0,PRODUCT(J24,$AJ24))} -> 0 | AN24: {=_xlfn.IFS($AJ24="NO CHARGE",0,$AJ24=0,0,$AJ24>0,PRODUCT(K24,$AJ24))} -> 0 | AO24: {=_xlfn.IFS($AJ24="NO CHARGE",0,$AJ24=0,0,$AJ24>0,PRODUCT(L24,$AJ24))} -> 0 | AP24: {=_xlfn.IFS($AJ24="NO CHARGE",0,$AJ24=0,0,$AJ24>0,PRODUCT(M24,$AJ24))} -> 0 | AQ24: =SUM(AL24:AP24) -> 0 | AV24: =IF(AU24>0,PRODUCT(I24,$AU24),0) -> 0 | AW24: =IF(AV24>0,PRODUCT(J24,$AU24),0) -> 0 | AX24: =IF(AW24>0,PRODUCT(K24,$AU24),0) -> 0 | AY24: =IF(AX24>0,PRODUCT(L24,$AU24),0) -> 0 | AZ24: =IF(AY24>0,PRODUCT(M24,$AU24),0) -> 0 | BA24: =SUM(AV24:AZ24) -> 0
C25: GL Posting Account/Branch/Center Processing | H25: =IFERROR(AVERAGE(D25:G25),0) -> 0 | I25: =H25*12 -> 0 | J25: =IF(I25>12,(((I25)*$H$5)+I25),(I25*1)) -> 0 | K25: =IF(J25>12,(((J25)*$H$5)+J25),(J25*1)) -> 0 | L25: =IF(K25>12,(((K25)*$H$5)+K25),(K25*1)) -> 0 | M25: =IF(L25>12,(((L25)*$H$5)+L25),(L25*1)) -> 0 | P25: =Q25/12 -> 0 | Q25: =IF(O25>0,PRODUCT(I25,$O25),0) -> 0 | R25: =IF(Q25>0,PRODUCT(J25,$O25),0) -> 0 | S25: =IF(R25>0,PRODUCT(K25,$O25),0) -> 0 | T25: =IF(S25>0,PRODUCT(L25,$O25),0) -> 0 | U25: =IF(T25>0,PRODUCT(M25,$O25),0) -> 0 | V25: =SUM(Q25:U25) -> 0 | X25: =C25 -> GL Posting Account/Branch/Center Processing | Y25: INCLUDED | Z25: =AA25/12 -> 0 | AA25: =IF(Y25>0,PRODUCT(I25,$Y25),0) -> 0 | AB25: =IF(AA25>0,PRODUCT(J25,$Y25),0) -> 0 | AC25: =IF(AB25>0,PRODUCT(K25,$Y25),0) -> 0 | AD25: =IF(AC25>0,PRODUCT(L25,$Y25),0) -> 0 | AE25: =IF(AD25>0,PRODUCT(M25,$Y25),0) -> 0 | AF25: =SUM(AA25:AE25) -> 0 | AI25: GL Posting Account/Branch/Center Processing | AK25: =AL25/12 -> 0 | AL25: {=_xlfn.IFS($AJ25="NO CHARGE",0,$AJ25=0,0,$AJ25>0,PRODUCT(I25,$AJ25))} -> 0 | AM25: {=_xlfn.IFS($AJ25="NO CHARGE",0,$AJ25=0,0,$AJ25>0,PRODUCT(J25,$AJ25))} -> 0 | AN25: {=_xlfn.IFS($AJ25="NO CHARGE",0,$AJ25=0,0,$AJ25>0,PRODUCT(K25,$AJ25))} -> 0 | AO25: {=_xlfn.IFS($AJ25="NO CHARGE",0,$AJ25=0,0,$AJ25>0,PRODUCT(L25,$AJ25))} -> 0 | AP25: {=_xlfn.IFS($AJ25="NO CHARGE",0,$AJ25=0,0,$AJ25>0,PRODUCT(M25,$AJ25))} -> 0 | AQ25: =SUM(AL25:AP25) -> 0 | AV25: =IF(AU25>0,PRODUCT(I25,$AU25),0) -> 0 | AW25: =IF(AV25>0,PRODUCT(J25,$AU25),0) -> 0 | AX25: =IF(AW25>0,PRODUCT(K25,$AU25),0) -> 0 | AY25: =IF(AX25>0,PRODUCT(L25,$AU25),0) -> 0 | AZ25: =IF(AY25>0,PRODUCT(M25,$AU25),0) -> 0 | BA25: =SUM(AV25:AZ25) -> 0
C26: HORIZON eAlert (email only) | H26: =IFERROR(AVERAGE(D26:G26),0) -> 0 | I26: =H26*12 -> 0 | J26: =IF(I26>12,(((I26)*$H$5)+I26),(I26*1)) -> 0 | K26: =IF(J26>12,(((J26)*$H$5)+J26),(J26*1)) -> 0 | L26: =IF(K26>12,(((K26)*$H$5)+K26),(K26*1)) -> 0 | M26: =IF(L26>12,(((L26)*$H$5)+L26),(L26*1)) -> 0 | P26: =Q26/12 -> 0 | Q26: =IF(O26>0,PRODUCT(I26,$O26),0) -> 0 | R26: =IF(Q26>0,PRODUCT(J26,$O26),0) -> 0 | S26: =IF(R26>0,PRODUCT(K26,$O26),0) -> 0 | T26: =IF(S26>0,PRODUCT(L26,$O26),0) -> 0 | U26: =IF(T26>0,PRODUCT(M26,$O26),0) -> 0 | V26: =SUM(Q26:U26) -> 0 | X26: =C26 -> HORIZON eAlert (email only) | Y26: INCLUDED | Z26: =AA26/12 -> 0 | AA26: =IF(Y26>0,PRODUCT(I26,$Y26),0) -> 0 | AB26: =IF(AA26>0,PRODUCT(J26,$Y26),0) -> 0 | AC26: =IF(AB26>0,PRODUCT(K26,$Y26),0) -> 0 | AD26: =IF(AC26>0,PRODUCT(L26,$Y26),0) -> 0 | AE26: =IF(AD26>0,PRODUCT(M26,$Y26),0) -> 0 | AF26: =SUM(AA26:AE26) -> 0 | AI26: HORIZON eAlert (email only) | AK26: =AL26/12 -> 0 | AL26: {=_xlfn.IFS($AJ26="NO CHARGE",0,$AJ26=0,0,$AJ26>0,PRODUCT(I26,$AJ26))} -> 0 | AM26: {=_xlfn.IFS($AJ26="NO CHARGE",0,$AJ26=0,0,$AJ26>0,PRODUCT(J26,$AJ26))} -> 0 | AN26: {=_xlfn.IFS($AJ26="NO CHARGE",0,$AJ26=0,0,$AJ26>0,PRODUCT(K26,$AJ26))} -> 0 | AO26: {=_xlfn.IFS($AJ26="NO CHARGE",0,$AJ26=0,0,$AJ26>0,PRODUCT(L26,$AJ26))} -> 0 | AP26: {=_xlfn.IFS($AJ26="NO CHARGE",0,$AJ26=0,0,$AJ26>0,PRODUCT(M26,$AJ26))} -> 0 | AQ26: =SUM(AL26:AP26) -> 0 | AV26: =IF(AU26>0,PRODUCT(I26,$AU26),0) -> 0 | AW26: =IF(AV26>0,PRODUCT(J26,$AU26),0) -> 0 | AX26: =IF(AW26>0,PRODUCT(K26,$AU26),0) -> 0 | AY26: =IF(AX26>0,PRODUCT(L26,$AU26),0) -> 0 | AZ26: =IF(AY26>0,PRODUCT(M26,$AU26),0) -> 0 | BA26: =SUM(AV26:AZ26) -> 0
C27: HORIZON Teller | H27: =IFERROR(AVERAGE(D27:G27),0) -> 0 | I27: =H27*12 -> 0 | J27: =IF(I27>12,(((I27)*$H$5)+I27),(I27*1)) -> 0 | K27: =IF(J27>12,(((J27)*$H$5)+J27),(J27*1)) -> 0 | L27: =IF(K27>12,(((K27)*$H$5)+K27),(K27*1)) -> 0 | M27: =IF(L27>12,(((L27)*$H$5)+L27),(L27*1)) -> 0 | P27: =Q27/12 -> 0 | Q27: =IF(O27>0,PRODUCT(I27,$O27),0) -> 0 | R27: =IF(Q27>0,PRODUCT(J27,$O27),0) -> 0 | S27: =IF(R27>0,PRODUCT(K27,$O27),0) -> 0 | T27: =IF(S27>0,PRODUCT(L27,$O27),0) -> 0 | U27: =IF(T27>0,PRODUCT(M27,$O27),0) -> 0 | V27: =SUM(Q27:U27) -> 0 | X27: =C27 -> HORIZON Teller | Y27: INCLUDED | Z27: =AA27/12 -> 0 | AA27: =IF(Y27>0,PRODUCT(I27,$Y27),0) -> 0 | AB27: =IF(AA27>0,PRODUCT(J27,$Y27),0) -> 0 | AC27: =IF(AB27>0,PRODUCT(K27,$Y27),0) -> 0 | AD27: =IF(AC27>0,PRODUCT(L27,$Y27),0) -> 0 | AE27: =IF(AD27>0,PRODUCT(M27,$Y27),0) -> 0 | AF27: =SUM(AA27:AE27) -> 0 | AI27: HORIZON Teller | AK27: =AL27/12 -> 0 | AL27: {=_xlfn.IFS($AJ27="NO CHARGE",0,$AJ27=0,0,$AJ27>0,PRODUCT(I27,$AJ27))} -> 0 | AM27: {=_xlfn.IFS($AJ27="NO CHARGE",0,$AJ27=0,0,$AJ27>0,PRODUCT(J27,$AJ27))} -> 0 | AN27: {=_xlfn.IFS($AJ27="NO CHARGE",0,$AJ27=0,0,$AJ27>0,PRODUCT(K27,$AJ27))} -> 0 | AO27: {=_xlfn.IFS($AJ27="NO CHARGE",0,$AJ27=0,0,$AJ27>0,PRODUCT(L27,$AJ27))} -> 0 | AP27: {=_xlfn.IFS($AJ27="NO CHARGE",0,$AJ27=0,0,$AJ27>0,PRODUCT(M27,$AJ27))} -> 0 | AQ27: =SUM(AL27:AP27) -> 0 | AV27: =IF(AU27>0,PRODUCT(I27,$AU27),0) -> 0 | AW27: =IF(AV27>0,PRODUCT(J27,$AU27),0) -> 0 | AX27: =IF(AW27>0,PRODUCT(K27,$AU27),0) -> 0 | AY27: =IF(AX27>0,PRODUCT(L27,$AU27),0) -> 0 | AZ27: =IF(AY27>0,PRODUCT(M27,$AU27),0) -> 0 | BA27: =SUM(AV27:AZ27) -> 0
C28: Multi-Tabbing | H28: =IFERROR(AVERAGE(D28:G28),0) -> 0 | I28: =H28*12 -> 0 | J28: =IF(I28>12,(((I28)*$H$5)+I28),(I28*1)) -> 0 | K28: =IF(J28>12,(((J28)*$H$5)+J28),(J28*1)) -> 0 | L28: =IF(K28>12,(((K28)*$H$5)+K28),(K28*1)) -> 0 | M28: =IF(L28>12,(((L28)*$H$5)+L28),(L28*1)) -> 0 | P28: =Q28/12 -> 0 | Q28: =IF(O28>0,PRODUCT(I28,$O28),0) -> 0 | R28: =IF(Q28>0,PRODUCT(J28,$O28),0) -> 0 | S28: =IF(R28>0,PRODUCT(K28,$O28),0) -> 0 | T28: =IF(S28>0,PRODUCT(L28,$O28),0) -> 0 | U28: =IF(T28>0,PRODUCT(M28,$O28),0) -> 0 | V28: =SUM(Q28:U28) -> 0 | X28: =C28 -> Multi-Tabbing | Y28: INCLUDED | Z28: =AA28/12 -> 0 | AA28: =IF(Y28>0,PRODUCT(I28,$Y28),0) -> 0 | AB28: =IF(AA28>0,PRODUCT(J28,$Y28),0) -> 0 | AC28: =IF(AB28>0,PRODUCT(K28,$Y28),0) -> 0 | AD28: =IF(AC28>0,PRODUCT(L28,$Y28),0) -> 0 | AE28: =IF(AD28>0,PRODUCT(M28,$Y28),0) -> 0 | AF28: =SUM(AA28:AE28) -> 0 | AI28: Multi-Tabbing | AK28: =AL28/12 -> 0 | AL28: {=_xlfn.IFS($AJ28="NO CHARGE",0,$AJ28=0,0,$AJ28>0,PRODUCT(I28,$AJ28))} -> 0 | AM28: {=_xlfn.IFS($AJ28="NO CHARGE",0,$AJ28=0,0,$AJ28>0,PRODUCT(J28,$AJ28))} -> 0 | AN28: {=_xlfn.IFS($AJ28="NO CHARGE",0,$AJ28=0,0,$AJ28>0,PRODUCT(K28,$AJ28))} -> 0 | AO28: {=_xlfn.IFS($AJ28="NO CHARGE",0,$AJ28=0,0,$AJ28>0,PRODUCT(L28,$AJ28))} -> 0 | AP28: {=_xlfn.IFS($AJ28="NO CHARGE",0,$AJ28=0,0,$AJ28>0,PRODUCT(M28,$AJ28))} -> 0 | AQ28: =SUM(AL28:AP28) -> 0 | AV28: =IF(AU28>0,PRODUCT(I28,$AU28),0) -> 0 | AW28: =IF(AV28>0,PRODUCT(J28,$AU28),0) -> 0 | AX28: =IF(AW28>0,PRODUCT(K28,$AU28),0) -> 0 | AY28: =IF(AX28>0,PRODUCT(L28,$AU28),0) -> 0 | AZ28: =IF(AY28>0,PRODUCT(M28,$AU28),0) -> 0 | BA28: =SUM(AV28:AZ28) -> 0
C29: Origination eSignature | H29: =IFERROR(AVERAGE(D29:G29),0) -> 0 | I29: =H29*12 -> 0 | J29: =IF(I29>12,(((I29)*$H$5)+I29),(I29*1)) -> 0 | K29: =IF(J29>12,(((J29)*$H$5)+J29),(J29*1)) -> 0 | L29: =IF(K29>12,(((K29)*$H$5)+K29),(K29*1)) -> 0 | M29: =IF(L29>12,(((L29)*$H$5)+L29),(L29*1)) -> 0 | P29: =Q29/12 -> 0 | Q29: =IF(O29>0,PRODUCT(I29,$O29),0) -> 0 | R29: =IF(Q29>0,PRODUCT(J29,$O29),0) -> 0 | S29: =IF(R29>0,PRODUCT(K29,$O29),0) -> 0 | T29: =IF(S29>0,PRODUCT(L29,$O29),0) -> 0 | U29: =IF(T29>0,PRODUCT(M29,$O29),0) -> 0 | V29: =SUM(Q29:U29) -> 0 | X29: =C29 -> Origination eSignature | Y29: INCLUDED | Z29: =AA29/12 -> 0 | AA29: =IF(Y29>0,PRODUCT(I29,$Y29),0) -> 0 | AB29: =IF(AA29>0,PRODUCT(J29,$Y29),0) -> 0 | AC29: =IF(AB29>0,PRODUCT(K29,$Y29),0) -> 0 | AD29: =IF(AC29>0,PRODUCT(L29,$Y29),0) -> 0 | AE29: =IF(AD29>0,PRODUCT(M29,$Y29),0) -> 0 | AF29: =SUM(AA29:AE29) -> 0 | AI29: Origination eSignature | AK29: =AL29/12 -> 0 | AL29: {=_xlfn.IFS($AJ29="NO CHARGE",0,$AJ29=0,0,$AJ29>0,PRODUCT(I29,$AJ29))} -> 0 | AM29: {=_xlfn.IFS($AJ29="NO CHARGE",0,$AJ29=0,0,$AJ29>0,PRODUCT(J29,$AJ29))} -> 0 | AN29: {=_xlfn.IFS($AJ29="NO CHARGE",0,$AJ29=0,0,$AJ29>0,PRODUCT(K29,$AJ29))} -> 0 | AO29: {=_xlfn.IFS($AJ29="NO CHARGE",0,$AJ29=0,0,$AJ29>0,PRODUCT(L29,$AJ29))} -> 0 | AP29: {=_xlfn.IFS($AJ29="NO CHARGE",0,$AJ29=0,0,$AJ29>0,PRODUCT(M29,$AJ29))} -> 0 | AQ29: =SUM(AL29:AP29) -> 0 | AV29: =IF(AU29>0,PRODUCT(I29,$AU29),0) -> 0 | AW29: =IF(AV29>0,PRODUCT(J29,$AU29),0) -> 0 | AX29: =IF(AW29>0,PRODUCT(K29,$AU29),0) -> 0 | AY29: =IF(AX29>0,PRODUCT(L29,$AU29),0) -> 0 | AZ29: =IF(AY29>0,PRODUCT(M29,$AU29),0) -> 0 | BA29: =SUM(AV29:AZ29) -> 0
C30: Relationship Management Accounts | H30: =IFERROR(AVERAGE(D30:G30),0) -> 0 | I30: =H30*12 -> 0 | J30: =IF(I30>12,(((I30)*$H$5)+I30),(I30*1)) -> 0 | K30: =IF(J30>12,(((J30)*$H$5)+J30),(J30*1)) -> 0 | L30: =IF(K30>12,(((K30)*$H$5)+K30),(K30*1)) -> 0 | M30: =IF(L30>12,(((L30)*$H$5)+L30),(L30*1)) -> 0 | P30: =Q30/12 -> 0 | Q30: =IF(O30>0,PRODUCT(I30,$O30),0) -> 0 | R30: =IF(Q30>0,PRODUCT(J30,$O30),0) -> 0 | S30: =IF(R30>0,PRODUCT(K30,$O30),0) -> 0 | T30: =IF(S30>0,PRODUCT(L30,$O30),0) -> 0 | U30: =IF(T30>0,PRODUCT(M30,$O30),0) -> 0 | V30: =SUM(Q30:U30) -> 0 | X30: =C30 -> Relationship Management Accounts | Y30: INCLUDED | Z30: =AA30/12 -> 0 | AA30: =IF(Y30>0,PRODUCT(I30,$Y30),0) -> 0 | AB30: =IF(AA30>0,PRODUCT(J30,$Y30),0) -> 0 | AC30: =IF(AB30>0,PRODUCT(K30,$Y30),0) -> 0 | AD30: =IF(AC30>0,PRODUCT(L30,$Y30),0) -> 0 | AE30: =IF(AD30>0,PRODUCT(M30,$Y30),0) -> 0 | AF30: =SUM(AA30:AE30) -> 0 | AI30: Relationship Management Accounts | AK30: =AL30/12 -> 0 | AL30: {=_xlfn.IFS($AJ30="NO CHARGE",0,$AJ30=0,0,$AJ30>0,PRODUCT(I30,$AJ30))} -> 0 | AM30: {=_xlfn.IFS($AJ30="NO CHARGE",0,$AJ30=0,0,$AJ30>0,PRODUCT(J30,$AJ30))} -> 0 | AN30: {=_xlfn.IFS($AJ30="NO CHARGE",0,$AJ30=0,0,$AJ30>0,PRODUCT(K30,$AJ30))} -> 0 | AO30: {=_xlfn.IFS($AJ30="NO CHARGE",0,$AJ30=0,0,$AJ30>0,PRODUCT(L30,$AJ30))} -> 0 | AP30: {=_xlfn.IFS($AJ30="NO CHARGE",0,$AJ30=0,0,$AJ30>0,PRODUCT(M30,$AJ30))} -> 0 | AQ30: =SUM(AL30:AP30) -> 0 | AV30: =IF(AU30>0,PRODUCT(I30,$AU30),0) -> 0 | AW30: =IF(AV30>0,PRODUCT(J30,$AU30),0) -> 0 | AX30: =IF(AW30>0,PRODUCT(K30,$AU30),0) -> 0 | AY30: =IF(AX30>0,PRODUCT(L30,$AU30),0) -> 0 | AZ30: =IF(AY30>0,PRODUCT(M30,$AU30),0) -> 0 | BA30: =SUM(AV30:AZ30) -> 0
... C33: XChange Messaging Middleware Base Fee | H33: =IFERROR(AVERAGE(D33:G33),0) -> 0 | I33: =H33*12 -> 0 | J33: =IF(I33>12,(((I33)*$H$5)+I33),(I33*1)) -> 0 | K33: =IF(J33>12,(((J33)*$H$5)+J33),(J33*1)) -> 0 | L33: =IF(K33>12,(((K33)*$H$5)+K33),(K33*1)) -> 0 | M33: =IF(L33>12,(((L33)*$H$5)+L33),(L33*1)) -> 0 | P33: =Q33/12 -> 0 | Q33: =IF(O33>0,PRODUCT(I33,$O33),0) -> 0 | R33: =IF(Q33>0,PRODUCT(J33,$O33),0) -> 0 | S33: =IF(R33>0,PRODUCT(K33,$O33),0) -> 0 | T33: =IF(S33>0,PRODUCT(L33,$O33),0) -> 0 | U33: =IF(T33>0,PRODUCT(M33,$O33),0) -> 0 | V33: =SUM(Q33:U33) -> 0 | X33: =C33 -> XChange Messaging Middleware Base Fee | Y33: INCLUDED | Z33: =AA33/12 -> 0 | AA33: =IF(Y33>0,PRODUCT(I33,$Y33),0) -> 0 | AB33: =IF(AA33>0,PRODUCT(J33,$Y33),0) -> 0 | AC33: =IF(AB33>0,PRODUCT(K33,$Y33),0) -> 0 | AD33: =IF(AC33>0,PRODUCT(L33,$Y33),0) -> 0 | AE33: =IF(AD33>0,PRODUCT(M33,$Y33),0) -> 0 | AF33: =SUM(AA33:AE33) -> 0 | AI33: XChange Messaging Middleware Base Fee | AK33: =AL33/12 -> 0 | AL33: {=_xlfn.IFS($AJ33="NO CHARGE",0,$AJ33=0,0,$AJ33>0,PRODUCT(I33,$AJ33))} -> 0 | AM33: {=_xlfn.IFS($AJ33="NO CHARGE",0,$AJ33=0,0,$AJ33>0,PRODUCT(J33,$AJ33))} -> 0 | AN33: {=_xlfn.IFS($AJ33="NO CHARGE",0,$AJ33=0,0,$AJ33>0,PRODUCT(K33,$AJ33))} -> 0 | AO33: {=_xlfn.IFS($AJ33="NO CHARGE",0,$AJ33=0,0,$AJ33>0,PRODUCT(L33,$AJ33))} -> 0 | AP33: {=_xlfn.IFS($AJ33="NO CHARGE",0,$AJ33=0,0,$AJ33>0,PRODUCT(M33,$AJ33))} -> 0 | AQ33: =SUM(AL33:AP33) -> 0 | AV33: =IF(AU33>0,PRODUCT(I33,$AU33),0) -> 0 | AW33: =IF(AV33>0,PRODUCT(J33,$AU33),0) -> 0 | AX33: =IF(AW33>0,PRODUCT(K33,$AU33),0) -> 0 | AY33: =IF(AX33>0,PRODUCT(L33,$AU33),0) -> 0 | AZ33: =IF(AY33>0,PRODUCT(M33,$AU33),0) -> 0 | BA33: =SUM(AV33:AZ33) -> 0
H34: =IFERROR(AVERAGE(D34:G34),0) -> 0 | I34: =H34*12 -> 0 | J34: =IF(I34>12,(((I34)*$H$5)+I34),(I34*1)) -> 0 | K34: =IF(J34>12,(((J34)*$H$5)+J34),(J34*1)) -> 0 | L34: =IF(K34>12,(((K34)*$H$5)+K34),(K34*1)) -> 0 | M34: =IF(L34>12,(((L34)*$H$5)+L34),(L34*1)) -> 0 | N34: =IF(C34="","",C34) | P34: =Q34/12 -> 0 | Q34: =IF(O34>0,PRODUCT(I34,$O34),0) -> 0 | R34: =IF(Q34>0,PRODUCT(J34,$O34),0) -> 0 | S34: =IF(R34>0,PRODUCT(K34,$O34),0) -> 0 | T34: =IF(S34>0,PRODUCT(L34,$O34),0) -> 0 | U34: =IF(T34>0,PRODUCT(M34,$O34),0) -> 0 | V34: =SUM(Q34:U34) -> 0 | Z34: =AA34/12 -> 0 | AA34: =IF(Y34>0,PRODUCT(I34,$Y34),0) -> 0 | AB34: =IF(AA34>0,PRODUCT(J34,$Y34),0) -> 0 | AC34: =IF(AB34>0,PRODUCT(K34,$Y34),0) -> 0 | AD34: =IF(AC34>0,PRODUCT(L34,$Y34),0) -> 0 | AE34: =IF(AD34>0,PRODUCT(M34,$Y34),0) -> 0 | AF34: =SUM(AA34:AE34) -> 0 | AK34: =AL34/12 -> 0 | AL34: {=_xlfn.IFS($AJ34="NO CHARGE",0,$AJ34=0,0,$AJ34>0,PRODUCT(I34,$AJ34))} -> 0 | AM34: {=_xlfn.IFS($AJ34="NO CHARGE",0,$AJ34=0,0,$AJ34>0,PRODUCT(J34,$AJ34))} -> 0 | AN34: {=_xlfn.IFS($AJ34="NO CHARGE",0,$AJ34=0,0,$AJ34>0,PRODUCT(K34,$AJ34))} -> 0 | AO34: {=_xlfn.IFS($AJ34="NO CHARGE",0,$AJ34=0,0,$AJ34>0,PRODUCT(L34,$AJ34))} -> 0 | AP34: {=_xlfn.IFS($AJ34="NO CHARGE",0,$AJ34=0,0,$AJ34>0,PRODUCT(M34,$AJ34))} -> 0 | AQ34: =SUM(AL34:AP34) -> 0 | AV34: =IF(AU34>0,PRODUCT(I34,$AU34),0) -> 0 | AW34: =IF(AV34>0,PRODUCT(J34,$AU34),0) -> 0 | AX34: =IF(AW34>0,PRODUCT(K34,$AU34),0) -> 0 | AY34: =IF(AX34>0,PRODUCT(L34,$AU34),0) -> 0 | AZ34: =IF(AY34>0,PRODUCT(M34,$AU34),0) -> 0 | BA34: =SUM(AV34:AZ34) -> 0
B35: Horizon Aggregated Products and Services | C35: =B35&" [QTY CALCULATIONS YOY]" -> Horizon Aggregated Products and Services [QTY CALCULATIONS YOY] | H35: 54437 | I35: =H35*12 -> 653244 | J35: =IF(I35>12,(((I35)*$H$5)+I35),(I35*1)) -> 685906.2 | K35: =IF(J35>12,(((J35)*$H$5)+J35),(J35*1)) -> 720201.51 | L35: =IF(K35>12,(((K35)*$H$5)+K35),(K35*1)) -> 756211.59 | M35: =IF(L35>12,(((L35)*$H$5)+L35),(L35*1)) -> 794022.16 | P35: =Q35/12 -> 0 | Q35: =IF(O35>0,PRODUCT(I35,$O35),0) -> 0 | R35: =IF(Q35>0,PRODUCT(J35,$O35),0) -> 0 | S35: =IF(R35>0,PRODUCT(K35,$O35),0) -> 0 | T35: =IF(S35>0,PRODUCT(L35,$O35),0) -> 0 | U35: =IF(T35>0,PRODUCT(M35,$O35),0) -> 0 | V35: =SUM(Q35:U35) -> 0 | X35: =B35&" [TIERED]" -> Horizon Aggregated Products and Services [TIERED] | Z35: =AA35/12 -> 0 | AA35: =IF(Y35>0,PRODUCT(I35,$Y35),0) -> 0 | AB35: =IF(AA35>0,PRODUCT(J35,$Y35),0) -> 0 | AC35: =IF(AB35>0,PRODUCT(K35,$Y35),0) -> 0 | AD35: =IF(AC35>0,PRODUCT(L35,$Y35),0) -> 0 | AE35: =IF(AD35>0,PRODUCT(M35,$Y35),0) -> 0 | AF35: =SUM(AA35:AE35) -> 0 | AI35: =X35 -> Horizon Aggregated Products and Services [TIERED] | AK35: =AL35/12 -> 0 | AL35: {=_xlfn.IFS($AJ35="NO CHARGE",0,$AJ35=0,0,$AJ35>0,PRODUCT(I35,$AJ35))} -> 0 | AM35: {=_xlfn.IFS($AJ35="NO CHARGE",0,$AJ35=0,0,$AJ35>0,PRODUCT(J35,$AJ35))} -> 0 | AN35: {=_xlfn.IFS($AJ35="NO CHARGE",0,$AJ35=0,0,$AJ35>0,PRODUCT(K35,$AJ35))} -> 0 | AO35: {=_xlfn.IFS($AJ35="NO CHARGE",0,$AJ35=0,0,$AJ35>0,PRODUCT(L35,$AJ35))} -> 0 | AP35: {=_xlfn.IFS($AJ35="NO CHARGE",0,$AJ35=0,0,$AJ35>0,PRODUCT(M35,$AJ35))} -> 0 | AQ35: =SUM(AL35:AP35) -> 0 | AV35: =IF(AU35>0,PRODUCT(I35,$AU35),0) -> 0 | AW35: =IF(AV35>0,PRODUCT(J35,$AU35),0) -> 0 | AX35: =IF(AW35>0,PRODUCT(K35,$AU35),0) -> 0 | AY35: =IF(AX35>0,PRODUCT(L35,$AU35),0) -> 0 | AZ35: =IF(AY35>0,PRODUCT(M35,$AU35),0) -> 0 | BA35: =SUM(AV35:AZ35) -> 0
B36: Horizon Aggregated Products and Services | C36: [Tiered] Base Monthly Processing 0 - 54,437 Accounts | H36: 54437 | I36: =IF(I35>($H36*12),$H36*12,I35) -> 653244 | J36: =IF(J35>($H36*12),$H36*12,J35) -> 653244 | K36: =IF(K35>($H36*12),$H36*12,K35) -> 653244 | L36: =IF(L35>($H36*12),$H36*12,L35) -> 653244 | M36: =IF(M35>($H36*12),$H36*12,M35) -> 653244 | P36: =Q36/12 -> 0 | Q36: =IF(O36>0,PRODUCT(I36,$O36),0) -> 0 | R36: =IF(Q36>0,PRODUCT(J36,$O36),0) -> 0 | S36: =IF(R36>0,PRODUCT(K36,$O36),0) -> 0 | T36: =IF(S36>0,PRODUCT(L36,$O36),0) -> 0 | U36: =IF(T36>0,PRODUCT(M36,$O36),0) -> 0 | V36: =SUM(Q36:U36) -> 0 | X36: =C36 -> [Tiered] Base Monthly Processing 0 - 54,437 Accounts | Y36: =2775.26/54437 -> 0.050981134 | Z36: =AA36/12 -> 2775.26 | AA36: =IF(Y36>0,PRODUCT(I36,$Y36),0) -> 33303.12 | AB36: =IF(AA36>0,PRODUCT(J36,$Y36),0) -> 33303.12 | AC36: =IF(AB36>0,PRODUCT(K36,$Y36),0) -> 33303.12 | AD36: =IF(AC36>0,PRODUCT(L36,$Y36),0) -> 33303.12 | AE36: =IF(AD36>0,PRODUCT(M36,$Y36),0) -> 33303.12 | AF36: =SUM(AA36:AE36) -> 166515.6 | AG36: WAIVED | AH36: FIS PROPOSAL MISSING PER UNIT RATE | AI36: =C36 -> [Tiered] Base Monthly Processing 0 - 54,437 Accounts | AJ36: =2775.26/54437 -> 0.050981134 | AK36: =AL36/12 -> 2775.26 | AL36: {=_xlfn.IFS($AJ36="NO CHARGE",0,$AJ36=0,0,$AJ36>0,PRODUCT(I36,$AJ36))} -> 33303.12 | AM36: {=_xlfn.IFS($AJ36="NO CHARGE",0,$AJ36=0,0,$AJ36>0,PRODUCT(J36,$AJ36))} -> 33303.12 | AN36: {=_xlfn.IFS($AJ36="NO CHARGE",0,$AJ36=0,0,$AJ36>0,PRODUCT(K36,$AJ36))} -> 33303.12 | AO36: {=_xlfn.IFS($AJ36="NO CHARGE",0,$AJ36=0,0,$AJ36>0,PRODUCT(L36,$AJ36))} -> 33303.12 | AP36: {=_xlfn.IFS($AJ36="NO CHARGE",0,$AJ36=0,0,$AJ36>0,PRODUCT(M36,$AJ36))} -> 33303.12 | AQ36: =SUM(AL36:AP36) -> 166515.6 | AR36: Waived | AS36: FIS PROPOSAL MISSING PER UNIT RATE | AV36: =IF(AU36>0,PRODUCT(I36,$AU36),0) -> 0 | AW36: =IF(AV36>0,PRODUCT(J36,$AU36),0) -> 0 | AX36: =IF(AW36>0,PRODUCT(K36,$AU36),0) -> 0 | AY36: =IF(AX36>0,PRODUCT(L36,$AU36),0) -> 0 | AZ36: =IF(AY36>0,PRODUCT(M36,$AU36),0) -> 0 | BA36: =SUM(AV36:AZ36) -> 0
B37: Horizon Aggregated Products and Services | C37: [Tiered] Base Monthly Processing 54,438 - 100k Accounts | H37: =100000-54438 -> 45562 | I37: {=_xlfn.IFS(I35>(($H36*12)+($H37*12)),$H37*12, I35<(($H36*12)+($H37*12)),I35-I36, I35=(($H36*12)+($H37*12)),I35-I36)} -> 0 | J37: {=_xlfn.IFS(J35>(($H36*12)+($H37*12)),$H37*12, J35<(($H36*12)+($H37*12)),J35-J36, J35=(($H36*12)+($H37*12)),J35-J36)} -> 32662.2 | K37: {=_xlfn.IFS(K35>(($H36*12)+($H37*12)),$H37*12, K35<(($H36*12)+($H37*12)),K35-K36, K35=(($H36*12)+($H37*12)),K35-K36)} -> 66957.51 | L37: {=_xlfn.IFS(L35>(($H36*12)+($H37*12)),$H37*12, L35<(($H36*12)+($H37*12)),L35-L36, L35=(($H36*12)+($H37*12)),L35-L36)} -> 102967.59 | M37: {=_xlfn.IFS(M35>(($H36*12)+($H37*12)),$H37*12, M35<(($H36*12)+($H37*12)),M35-M36, M35=(($H36*12)+($H37*12)),M35-M36)} -> 140778.16 | P37: =Q37/12 -> 0 | Q37: =IF(O37>0,PRODUCT(I37,$O37),0) -> 0 | R37: =IF(Q37>0,PRODUCT(J37,$O37),0) -> 0 | S37: =IF(R37>0,PRODUCT(K37,$O37),0) -> 0 | T37: =IF(S37>0,PRODUCT(L37,$O37),0) -> 0 | U37: =IF(T37>0,PRODUCT(M37,$O37),0) -> 0 | V37: =SUM(Q37:U37) -> 0 | X37: =C37 -> [Tiered] Base Monthly Processing 54,438 - 100k Accounts | Y37: 0.048 | Z37: =AA37/12 -> 0 | AA37: =IF(Y37>0,PRODUCT(I37,$Y37),0) -> 0 | AB37: {=_xlfn.IFS($AJ37="NO CHARGE",0,$AJ37=0,0,$AJ37>0,PRODUCT(J37,$AJ37))} -> 1567.7856 | AC37: =IF(AB37>0,PRODUCT(K37,$Y37),0) -> 3213.9605 | AD37: =IF(AC37>0,PRODUCT(L37,$Y37),0) -> 4942.4441 | AE37: =IF(AD37>0,PRODUCT(M37,$Y37),0) -> 6757.3519 | AF37: =SUM(AA37:AE37) -> 16481.542 | AI37: =C37 -> [Tiered] Base Monthly Processing 54,438 - 100k Accounts | AJ37: 0.048 | AK37: =AL37/12 -> 0 | AL37: {=_xlfn.IFS($AJ37="NO CHARGE",0,$AJ37=0,0,$AJ37>0,PRODUCT(I37,$AJ37))} -> 0 | AM37: {=_xlfn.IFS($AJ37="NO CHARGE",0,$AJ37=0,0,$AJ37>0,PRODUCT(J37,$AJ37))} -> 1567.7856 | AN37: {=_xlfn.IFS($AJ37="NO CHARGE",0,$AJ37=0,0,$AJ37>0,PRODUCT(K37,$AJ37))} -> 3213.9605 | AO37: {=_xlfn.IFS($AJ37="NO CHARGE",0,$AJ37=0,0,$AJ37>0,PRODUCT(L37,$AJ37))} -> 4942.4441 | AP37: {=_xlfn.IFS($AJ37="NO CHARGE",0,$AJ37=0,0,$AJ37>0,PRODUCT(M37,$AJ37))} -> 6757.3519 | AQ37: =SUM(AL37:AP37) -> 16481.542 | AV37: =IF(AU37>0,PRODUCT(I37,$AU37),0) -> 0 | AW37: =IF(AV37>0,PRODUCT(J37,$AU37),0) -> 0 | AX37: =IF(AW37>0,PRODUCT(K37,$AU37),0) -> 0 | AY37: =IF(AX37>0,PRODUCT(L37,$AU37),0) -> 0 | AZ37: =IF(AY37>0,PRODUCT(M37,$AU37),0) -> 0 | BA37: =SUM(AV37:AZ37) -> 0
B38: Horizon Aggregated Products and Services | C38: [Tiered] Base Monthly Processing beyond 100k Accounts | I38: {=_xlfn.IFS(I35>(($H36+$H37)*12),I35-I36-I37, I35<(($H36+$H37)*12),0, I35=(($H36+$H37)*12),0)} -> 0 | J38: {=_xlfn.IFS(J35>(($H36+$H37)*12),J35-J36-J37, J35<(($H36+$H37)*12),0, J35=(($H36+$H37)*12),0)} -> 0 | K38: {=_xlfn.IFS(K35>(($H36+$H37)*12),K35-K36-K37, K35<(($H36+$H37)*12),0, K35=(($H36+$H37)*12),0)} -> 0 | L38: {=_xlfn.IFS(L35>(($H36+$H37)*12),L35-L36-L37, L35<(($H36+$H37)*12),0, L35=(($H36+$H37)*12),0)} -> 0 | M38: {=_xlfn.IFS(M35>(($H36+$H37)*12),M35-M36-M37, M35<(($H36+$H37)*12),0, M35=(($H36+$H37)*12),0)} -> 0 | P38: =Q38/12 -> 0 | Q38: =IF(O38>0,PRODUCT(I38,$O38),0) -> 0 | R38: =IF(Q38>0,PRODUCT(J38,$O38),0) -> 0 | S38: =IF(R38>0,PRODUCT(K38,$O38),0) -> 0 | T38: =IF(S38>0,PRODUCT(L38,$O38),0) -> 0 | U38: =IF(T38>0,PRODUCT(M38,$O38),0) -> 0 | V38: =SUM(Q38:U38) -> 0 | X38: =C38 -> [Tiered] Base Monthly Processing beyond 100k Accounts | Y38: 0.046 | Z38: =AA38/12 -> 0 | AA38: =IF(Y38>0,PRODUCT(I38,$Y38),0) -> 0 | AB38: =IF(AA38>0,PRODUCT(J38,$Y38),0) -> 0 | AC38: =IF(AB38>0,PRODUCT(K38,$Y38),0) -> 0 | AD38: =IF(AC38>0,PRODUCT(L38,$Y38),0) -> 0 | AE38: =IF(AD38>0,PRODUCT(M38,$Y38),0) -> 0 | AF38: =SUM(AA38:AE38) -> 0 | AI38: =C38 -> [Tiered] Base Monthly Processing beyond 100k Accounts | AJ38: 0.046 | AK38: =AL38/12 -> 0 | AL38: {=_xlfn.IFS($AJ38="NO CHARGE",0,$AJ38=0,0,$AJ38>0,PRODUCT(I38,$AJ38))} -> 0 | AM38: {=_xlfn.IFS($AJ38="NO CHARGE",0,$AJ38=0,0,$AJ38>0,PRODUCT(J38,$AJ38))} -> 0 | AN38: {=_xlfn.IFS($AJ38="NO CHARGE",0,$AJ38=0,0,$AJ38>0,PRODUCT(K38,$AJ38))} -> 0 | AO38: {=_xlfn.IFS($AJ38="NO CHARGE",0,$AJ38=0,0,$AJ38>0,PRODUCT(L38,$AJ38))} -> 0 | AP38: {=_xlfn.IFS($AJ38="NO CHARGE",0,$AJ38=0,0,$AJ38>0,PRODUCT(M38,$AJ38))} -> 0 | AQ38: =SUM(AL38:AP38) -> 0 | AV38: =IF(AU38>0,PRODUCT(I38,$AU38),0) -> 0 | AW38: =IF(AV38>0,PRODUCT(J38,$AU38),0) -> 0 | AX38: =IF(AW38>0,PRODUCT(K38,$AU38),0) -> 0 | AY38: =IF(AX38>0,PRODUCT(L38,$AU38),0) -> 0 | AZ38: =IF(AY38>0,PRODUCT(M38,$AU38),0) -> 0 | BA38: =SUM(AV38:AZ38) -> 0
H39: =IFERROR(AVERAGE(D39:G39),0) -> 0 | I39: =H39*12 -> 0 | J39: =IF(I39>12,(((I39)*$H$5)+I39),(I39*1)) -> 0 | K39: =IF(J39>12,(((J39)*$H$5)+J39),(J39*1)) -> 0 | L39: =IF(K39>12,(((K39)*$H$5)+K39),(K39*1)) -> 0 | M39: =IF(L39>12,(((L39)*$H$5)+L39),(L39*1)) -> 0 | P39: =Q39/12 -> 0 | Q39: =IF(O39>0,PRODUCT(I39,$O39),0) -> 0 | R39: =IF(Q39>0,PRODUCT(J39,$O39),0) -> 0 | S39: =IF(R39>0,PRODUCT(K39,$O39),0) -> 0 | T39: =IF(S39>0,PRODUCT(L39,$O39),0) -> 0 | U39: =IF(T39>0,PRODUCT(M39,$O39),0) -> 0 | V39: =SUM(Q39:U39) -> 0 | Z39: =AA39/12 -> 0 | AA39: =IF(Y39>0,PRODUCT(I39,$Y39),0) -> 0 | AB39: =IF(AA39>0,PRODUCT(J39,$Y39),0) -> 0 | AC39: =IF(AB39>0,PRODUCT(K39,$Y39),0) -> 0 | AD39: =IF(AC39>0,PRODUCT(L39,$Y39),0) -> 0 | AE39: =IF(AD39>0,PRODUCT(M39,$Y39),0) -> 0 | AF39: =SUM(AA39:AE39) -> 0 | AK39: =AL39/12 -> 0 | AL39: {=_xlfn.IFS($AJ39="NO CHARGE",0,$AJ39=0,0,$AJ39>0,PRODUCT(I39,$AJ39))} -> 0 | AM39: {=_xlfn.IFS($AJ39="NO CHARGE",0,$AJ39=0,0,$AJ39>0,PRODUCT(J39,$AJ39))} -> 0 | AN39: {=_xlfn.IFS($AJ39="NO CHARGE",0,$AJ39=0,0,$AJ39>0,PRODUCT(K39,$AJ39))} -> 0 | AO39: {=_xlfn.IFS($AJ39="NO CHARGE",0,$AJ39=0,0,$AJ39>0,PRODUCT(L39,$AJ39))} -> 0 | AP39: {=_xlfn.IFS($AJ39="NO CHARGE",0,$AJ39=0,0,$AJ39>0,PRODUCT(M39,$AJ39))} -> 0 | AQ39: =SUM(AL39:AP39) -> 0 | AV39: =IF(AU39>0,PRODUCT(I39,$AU39),0) -> 0 | AW39: =IF(AV39>0,PRODUCT(J39,$AU39),0) -> 0 | AX39: =IF(AW39>0,PRODUCT(K39,$AU39),0) -> 0 | AY39: =IF(AX39>0,PRODUCT(L39,$AU39),0) -> 0 | AZ39: =IF(AY39>0,PRODUCT(M39,$AU39),0) -> 0 | BA39: =SUM(AV39:AZ39) -> 0
B40: Horizon Aggregated Products and Services | C40: ACH Activity | H40: 10611 | I40: =H40*12 -> 127332 | J40: =IF(I40>12,(((I40)*$H$5)+I40),(I40*1)) -> 133698.6 | K40: =IF(J40>12,(((J40)*$H$5)+J40),(J40*1)) -> 140383.53 | L40: =IF(K40>12,(((K40)*$H$5)+K40),(K40*1)) -> 147402.71 | M40: =IF(L40>12,(((L40)*$H$5)+L40),(L40*1)) -> 154772.84 | P40: =Q40/12 -> 0 | Q40: =IF(O40>0,PRODUCT(I40,$O40),0) -> 0 | R40: =IF(Q40>0,PRODUCT(J40,$O40),0) -> 0 | S40: =IF(R40>0,PRODUCT(K40,$O40),0) -> 0 | T40: =IF(S40>0,PRODUCT(L40,$O40),0) -> 0 | U40: =IF(T40>0,PRODUCT(M40,$O40),0) -> 0 | V40: =SUM(Q40:U40) -> 0 | X40: =C40 -> ACH Activity | Y40: 0.005 | Z40: =AA40/12 -> 53.055 | AA40: =IF(Y40>0,PRODUCT(I40,$Y40),0) -> 636.66 | AB40: =IF(AA40>0,PRODUCT(J40,$Y40),0) -> 668.493 | AC40: =IF(AB40>0,PRODUCT(K40,$Y40),0) -> 701.91765 | AD40: =IF(AC40>0,PRODUCT(L40,$Y40),0) -> 737.01353 | AE40: =IF(AD40>0,PRODUCT(M40,$Y40),0) -> 773.86421 | AF40: =SUM(AA40:AE40) -> 3517.9484 | AI40: =C40 -> ACH Activity | AJ40: 0.005 | AK40: =AL40/12 -> 53.055 | AL40: {=_xlfn.IFS($AJ40="NO CHARGE",0,$AJ40=0,0,$AJ40>0,PRODUCT(I40,$AJ40))} -> 636.66 | AM40: {=_xlfn.IFS($AJ40="NO CHARGE",0,$AJ40=0,0,$AJ40>0,PRODUCT(J40,$AJ40))} -> 668.493 | AN40: {=_xlfn.IFS($AJ40="NO CHARGE",0,$AJ40=0,0,$AJ40>0,PRODUCT(K40,$AJ40))} -> 701.91765 | AO40: {=_xlfn.IFS($AJ40="NO CHARGE",0,$AJ40=0,0,$AJ40>0,PRODUCT(L40,$AJ40))} -> 737.01353 | AP40: {=_xlfn.IFS($AJ40="NO CHARGE",0,$AJ40=0,0,$AJ40>0,PRODUCT(M40,$AJ40))} -> 773.86421 | AQ40: =SUM(AL40:AP40) -> 3517.9484 | AV40: =IF(AU40>0,PRODUCT(I40,$AU40),0) -> 0 | AW40: =IF(AV40>0,PRODUCT(J40,$AU40),0) -> 0 | AX40: =IF(AW40>0,PRODUCT(K40,$AU40),0) -> 0 | AY40: =IF(AX40>0,PRODUCT(L40,$AU40),0) -> 0 | AZ40: =IF(AY40>0,PRODUCT(M40,$AU40),0) -> 0 | BA40: =SUM(AV40:AZ40) -> 0
B41: Horizon Aggregated Products and Services | C41: Same Day ACH Settlement | H41: 1 | I41: =H41*12 -> 12 | J41: =IF(I41>12,(((I41)*$H$5)+I41),(I41*1)) -> 12 | K41: =IF(J41>12,(((J41)*$H$5)+J41),(J41*1)) -> 12 | L41: =IF(K41>12,(((K41)*$H$5)+K41),(K41*1)) -> 12 | M41: =IF(L41>12,(((L41)*$H$5)+L41),(L41*1)) -> 12 | P41: =Q41/12 -> 0 | Q41: =IF(O41>0,PRODUCT(I41,$O41),0) -> 0 | R41: =IF(Q41>0,PRODUCT(J41,$O41),0) -> 0 | S41: =IF(R41>0,PRODUCT(K41,$O41),0) -> 0 | T41: =IF(S41>0,PRODUCT(L41,$O41),0) -> 0 | U41: =IF(T41>0,PRODUCT(M41,$O41),0) -> 0 | V41: =SUM(Q41:U41) -> 0 | X41: =C41 -> Same Day ACH Settlement | Y41: 0.01 | Z41: =AA41/12 -> 0.01 | AA41: =IF(Y41>0,PRODUCT(I41,$Y41),0) -> 0.12 | AB41: =IF(AA41>0,PRODUCT(J41,$Y41),0) -> 0.12 | AC41: =IF(AB41>0,PRODUCT(K41,$Y41),0) -> 0.12 | AD41: =IF(AC41>0,PRODUCT(L41,$Y41),0) -> 0.12 | AE41: =IF(AD41>0,PRODUCT(M41,$Y41),0) -> 0.12 | AF41: =IF((SUM(AA41:AE41))<(Y42*60),0,(SUM(AA41:AE41))) -> 0 | AG41: WAIVED | AI41: =C41 -> Same Day ACH Settlement | AJ41: 0.01 | AK41: =AL41/12 -> 0.01 | AL41: {=_xlfn.IFS($AJ41="NO CHARGE",0,$AJ41=0,0,$AJ41>0,PRODUCT(I41,$AJ41))} -> 0.12 | AM41: {=_xlfn.IFS($AJ41="NO CHARGE",0,$AJ41=0,0,$AJ41>0,PRODUCT(J41,$AJ41))} -> 0.12 | AN41: {=_xlfn.IFS($AJ41="NO CHARGE",0,$AJ41=0,0,$AJ41>0,PRODUCT(K41,$AJ41))} -> 0.12 | AO41: {=_xlfn.IFS($AJ41="NO CHARGE",0,$AJ41=0,0,$AJ41>0,PRODUCT(L41,$AJ41))} -> 0.12 | AP41: {=_xlfn.IFS($AJ41="NO CHARGE",0,$AJ41=0,0,$AJ41>0,PRODUCT(M41,$AJ41))} -> 0.12 | AQ41: =IF((SUM(AL41:AP41))<(AJ42*60),0,(SUM(AL41:AP41))) -> 0 | AR41: Waived | AV41: =IF(AU41>0,PRODUCT(I41,$AU41),0) -> 0 | AW41: =IF(AV41>0,PRODUCT(J41,$AU41),0) -> 0 | AX41: =IF(AW41>0,PRODUCT(K41,$AU41),0) -> 0 | AY41: =IF(AX41>0,PRODUCT(L41,$AU41),0) -> 0 | AZ41: =IF(AY41>0,PRODUCT(M41,$AU41),0) -> 0 | BA41: =SUM(AV41:AZ41) -> 0
